Workbook

Sheet Parejas
A1: Coliseo Arena Gamer · CS2 Wingman 2v2
A2: Editá los nombres en amarillo. El ID no se cambia: los partidos usan el ID.
A4: ID | B4: Pareja (nombre corto) | C4: Jugador 1 | D4: Jugador 2
A5: 1 | B5: Cardozo / Cardozo | C5: José Cardozo | D5: Maximiliano Cardozo
A6: 2 | B6: Blas / Agustin | C6: Blas Machado Susseret | D6: Agustin Chioraia
A7: 3 | B7: Diego / (a confirmar) | C7: Diego Villan | D7: (a confirmar)
A8: 4 | B8: Luciano / Gonzalo | C8: Luciano | D8: Gonzalo
A9: 5 | B9: Francisco / Marcos | C9: Francisco | D9: Marcos
A10: 6 | B10: Luciano / Lautaro | C10: Luciano Pua | D10: Lautaro Montes
A11: 7 | B11: Simon / Joaquin | C11: Simon Cerra | D11: Joaquín Mucci
A12: 8 | B12: Rodrigo / Nazareno | C12: Rodrigo Antonino | D12: Nazareno Acosta
A13: 9 | B13: Bautista / Luciano | C13: Bautista Barrera | D13: Luciano Barrera
A14: 10 | B14: Lucas / Martin | C14: Lucas Tissera | D14: Martín Rodríguez
A15: 11 | B15: Agustin / Rodrigo | C15: Agustin Caceres | D15: Rodrigo Dimare
A16: 12 | B16: Enzo / Gonza | C16: Enzo | D16: Gonza

Sheet Suizo
A1: Fase suiza · 3 rondas · BO1
A2: Completá en amarillo: ID de cada pareja, rounds ganados y mapa. Wingman: gana quien llega a 9 rounds. No muevas las columnas.
A4: Partido | B4: Ronda | C4: ID A | D4: Pareja A | E4: Rounds A | F4: Rounds B | G4: Pareja B | H4: ID B | I4: Mapa | J4: Ganador | K4: id_ganador | L4: victorias_rival_A | M4: victorias_rival_B
A5: 1 | B5: R1 | C5: 1 | D5: {=IF(C5="","",INDEX(Parejas!$B$5:$B$16,C5))} -> Cardozo / Cardozo | E5: 9 | F5: 4 | G5: {=IF(H5="","",INDEX(Parejas!$B$5:$B$16,H5))} -> Simon / Joaquin | H5: 7 | I5: Inferno | J5: {=IF(K5="",IF(AND(E5<>"",F5<>"",E5=F5),"EMPATE: jugar OT",""),INDEX(Parejas!$B$5:$B$16,K5))} -> Cardozo / Cardozo | K5: =IF(OR(C5="",H5="",E5="",F5=""),"",IF(E5>F5,C5,IF(F5>E5,H5,""))) -> 1 | L5: {=IF(K5="","",INDEX(Calculo!$D$2:$D$13,H5))} -> 1 | M5: {=IF(K5="","",INDEX(Calculo!$D$2:$D$13,C5))} -> 3
A6: 2 | B6: R1 | C6: 3 | D6: {=IF(C6="","",INDEX(Parejas!$B$5:$B$16,C6))} -> Diego / (a confirmar) | E6: 7 | F6: 9 | G6: {=IF(H6="","",INDEX(Parejas!$B$5:$B$16,H6))} -> Luciano / Gonzalo | H6: 4 | I6: Inferno | J6: {=IF(K6="",IF(AND(E6<>"",F6<>"",E6=F6),"EMPATE: jugar OT",""),INDEX(Parejas!$B$5:$B$16,K6))} -> Luciano / Gonzalo | K6: =IF(OR(C6="",H6="",E6="",F6=""),"",IF(E6>F6,C6,IF(F6>E6,H6,""))) -> 4 | L6: {=IF(K6="","",INDEX(Calculo!$D$2:$D$13,H6))} -> 1 | M6: {=IF(K6="","",INDEX(Calculo!$D$2:$D$13,C6))} -> 1
A7: 3 | B7: R1 | C7: 11 | D7: {=IF(C7="","",INDEX(Parejas!$B$5:$B$16,C7))} -> Agustin / Rodrigo | E7: 3 | F7: 9 | G7: {=IF(H7="","",INDEX(Parejas!$B$5:$B$16,H7))} -> Francisco / Marcos | H7: 5 | I7: Nuke | J7: {=IF(K7="",IF(AND(E7<>"",F7<>"",E7=F7),"EMPATE: jugar OT",""),INDEX(Parejas!$B$5:$B$16,K7))} -> Francisco / Marcos | K7: =IF(OR(C7="",H7="",E7="",F7=""),"",IF(E7>F7,C7,IF(F7>E7,H7,""))) -> 5 | L7: {=IF(K7="","",INDEX(Calculo!$D$2:$D$13,H7))} -> 2 | M7: {=IF(K7="","",INDEX(Calculo!$D$2:$D$13,C7))} -> 2
A8: 4 | B8: R1 | C8: 8 | D8: {=IF(C8="","",INDEX(Parejas!$B$5:$B$16,C8))} -> Rodrigo / Nazareno | E8: 7 | F8: 9 | G8: {=IF(H8="","",INDEX(Parejas!$B$5:$B$16,H8))} -> Enzo / Gonza | H8: 12 | I8: Overpass | J8: {=IF(K8="",IF(AND(E8<>"",F8<>"",E8=F8),"EMPATE: jugar OT",""),INDEX(Parejas!$B$5:$B$16,K8))} -> Enzo / Gonza | K8: =IF(OR(C8="",H8="",E8="",F8=""),"",IF(E8>F8,C8,IF(F8>E8,H8,""))) -> 12 | L8: {=IF(K8="","",INDEX(Calculo!$D$2:$D$13,H8))} -> 2 | M8: {=IF(K8="","",INDEX(Calculo!$D$2:$D$13,C8))} -> 1
A9: 5 | B9: R1 | C9: 10 | D9: {=IF(C9="","",INDEX(Parejas!$B$5:$B$16,C9))} -> Lucas / Martin | E9: 7 | F9: 9 | G9: {=IF(H9="","",INDEX(Parejas!$B$5:$B$16,H9))} -> Bautista / Luciano | H9: 9 | I9: Nuke | J9: {=IF(K9="",IF(AND(E9<>"",F9<>"",E9=F9),"EMPATE: jugar OT",""),INDEX(Parejas!$B$5:$B$16,K9))} -> Bautista / Luciano | K9: =IF(OR(C9="",H9="",E9="",F9=""),"",IF(E9>F9,C9,IF(F9>E9,H9,""))) -> 9 | L9: {=IF(K9="","",INDEX(Calculo!$D$2:$D$13,H9))} -> 3 | M9: {=IF(K9="","",INDEX(Calculo!$D$2:$D$13,C9))} -> 0
A10: 6 | B10: R1 | C10: 6 | D10: {=IF(C10="","",INDEX(Parejas!$B$5:$B$16,C10))} -> Luciano / Lautaro | E10: 1 | F10: 9 | G10: {=IF(H10="","",INDEX(Parejas!$B$5:$B$16,H10))} -> Blas / Agustin | H10: 2 | I10: Inferno | J10: {=IF(K10="",IF(AND(E10<>"",F10<>"",E10=F10),"EMPATE: jugar OT",""),INDEX(Parejas!$B$5:$B$16,K10))} -> Blas / Agustin | K10: =IF(OR(C10="",H10="",E10="",F10=""),"",IF(E10>F10,C10,IF(F10>E10,H10,""))) -> 2 | L10: {=IF(K10="","",INDEX(Calculo!$D$2:$D$13,H10))} -> 2 | M10: {=IF(K10="","",INDEX(Calculo!$D$2:$D$13,C10))} -> 0
A11: 7 | B11: R2 | C11: =IF(Emparejar!$D$1=1,Emparejar!$D$17,"") -> 2 | D11: {=IF(C11="","",INDEX(Parejas!$B$5:$B$16,C11))} -> Blas / Agustin | E11: 3 | F11: 9 | G11: {=IF(H11="","",INDEX(Parejas!$B$5:$B$16,H11))} -> Francisco / Marcos | H11: =IF(Emparejar!$D$1=1,Emparejar!$E$17,"") -> 5 | J11: {=IF(K11="",IF(AND(E11<>"",F11<>"",E11=F11),"EMPATE: jugar OT",""),INDEX(Parejas!$B$5:$B$16,K11))} -> Francisco / Marcos | K11: =IF(OR(C11="",H11="",E11="",F11=""),"",IF(E11>F11,C11,IF(F11>E11,H11,""))) -> 5 | L11: {=IF(K11="","",INDEX(Calculo!$D$2:$D$13,H11))} -> 2 | M11: {=IF(K11="","",INDEX(Calculo!$D$2:$D$13,C11))} -> 2
A12: 8 | B12: R2 | C12: =IF(Emparejar!$D$1=1,Emparejar!$D$18,"") -> 1 | D12: {=IF(C12="","",INDEX(Parejas!$B$5:$B$16,C12))} -> Cardozo / Cardozo | E12: 9 | F12: 1 | G12: {=IF(H12="","",INDEX(Parejas!$B$5:$B$16,H12))} -> Luciano / Gonzalo | H12: =IF(Emparejar!$D$1=1,Emparejar!$E$18,"") -> 4 | J12: {=IF(K12="",IF(AND(E12<>"",F12<>"",E12=F12),"EMPATE: jugar OT",""),INDEX(Parejas!$B$5:$B$16,K12))} -> Cardozo / Cardozo | K12: =IF(OR(C12="",H12="",E12="",F12=""),"",IF(E12>F12,C12,IF(F12>E12,H12,""))) -> 1 | L12: {=IF(K12="","",INDEX(Calculo!$D$2:$D$13,H12))} -> 1 | M12: {=IF(K12="","",INDEX(Calculo!$D$2:$D$13,C12))} -> 3
A13: 9 | B13: R2 | C13: =IF(Emparejar!$D$1=1,Emparejar!$D$19,"") -> 9 | D13: {=IF(C13="","",INDEX(Parejas!$B$5:$B$16,C13))} -> Bautista / Luciano | E13: 9 | F13: 0 | G13: {=IF(H13="","",INDEX(Parejas!$B$5:$B$16,H13))} -> Enzo / Gonza | H13: =IF(Emparejar!$D$1=1,Emparejar!$E$19,"") -> 12 | J13: {=IF(K13="",IF(AND(E13<>"",F13<>"",E13=F13),"EMPATE: jugar OT",""),INDEX(Parejas!$B$5:$B$16,K13))} -> Bautista / Luciano | K13: =IF(OR(C13="",H13="",E13="",F13=""),"",IF(E13>F13,C13,IF(F13>E13,H13,""))) -> 9 | L13: {=IF(K13="","",INDEX(Calculo!$D$2:$D$13,H13))} -> 2 | M13: {=IF(K13="","",INDEX(Calculo!$D$2:$D$13,C13))} -> 3
A14: 10 | B14: R2 | C14: =IF(Emparejar!$D$1=1,Emparejar!$D$20,"") -> 3 | D14: {=IF(C14="","",INDEX(Parejas!$B$5:$B$16,C14))} -> Diego / (a confirmar) | E14: 9 | F14: 2 | G14: {=IF(H14="","",INDEX(Parejas!$B$5:$B$16,H14))} -> Rodrigo / Nazareno | H14: =IF(Emparejar!$D$1=1,Emparejar!$E$20,"") -> 8 | J14: {=IF(K14="",IF(AND(E14<>"",F14<>"",E14=F14),"EMPATE: jugar OT",""),INDEX(Parejas!$B$5:$B$16,K14))} -> Diego / (a confirmar) | K14: =IF(OR(C14="",H14="",E14="",F14=""),"",IF(E14>F14,C14,IF(F14>E14,H14,""))) -> 3 | L14: {=IF(K14="","",INDEX(Calculo!$D$2:$D$13,H14))} -> 1 | M14: {=IF(K14="","",INDEX(Calculo!$D$2:$D$13,C14))} -> 1
A15: 11 | B15: R2 | C15: =IF(Emparejar!$D$1=1,Emparejar!$D$21,"") -> 10 | D15: {=IF(C15="","",INDEX(Parejas!$B$5:$B$16,C15))} -> Lucas / Martin | E15: 5 | F15: 9 | G15: {=IF(H15="","",INDEX(Parejas!$B$5:$B$16,H15))} -> Simon / Joaquin | H15: =IF(Emparejar!$D$1=1,Emparejar!$E$21,"") -> 7 | J15: {=IF(K15="",IF(AND(E15<>"",F15<>"",E15=F15),"EMPATE: jugar OT",""),INDEX(Parejas!$B$5:$B$16,K15))} -> Simon / Joaquin | K15: =IF(OR(C15="",H15="",E15="",F15=""),"",IF(E15>F15,C15,IF(F15>E15,H15,""))) -> 7 | L15: {=IF(K15="","",INDEX(Calculo!$D$2:$D$13,H15))} -> 1 | M15: {=IF(K15="","",INDEX(Calculo!$D$2:$D$13,C15))} -> 0
A16: 12 | B16: R2 | C16: =IF(Emparejar!$D$1=1,Emparejar!$D$22,"") -> 11 | D16: {=IF(C16="","",INDEX(Parejas!$B$5:$B$16,C16))} -> Agustin / Rodrigo | E16: 9 | F16: 7 | G16: {=IF(H16="","",INDEX(Parejas!$B$5:$B$16,H16))} -> Luciano / Lautaro | H16: =IF(Emparejar!$D$1=1,Emparejar!$E$22,"") -> 6 | J16: {=IF(K16="",IF(AND(E16<>"",F16<>"",E16=F16),"EMPATE: jugar OT",""),INDEX(Parejas!$B$5:$B$16,K16))} -> Agustin / Rodrigo | K16: =IF(OR(C16="",H16="",E16="",F16=""),"",IF(E16>F16,C16,IF(F16>E16,H16,""))) -> 11 | L16: {=IF(K16="","",INDEX(Calculo!$D$2:$D$13,H16))} -> 0 | M16: {=IF(K16="","",INDEX(Calculo!$D$2:$D$13,C16))} -> 2
A17: 13 | B17: R3 | C17: =IF(Emparejar!$D$30=1,Emparejar!$D$46,"") -> 1 | D17: {=IF(C17="","",INDEX(Parejas!$B$5:$B$16,C17))} -> Cardozo / Cardozo | E17: 9 | F17: 7 | G17: {=IF(H17="","",INDEX(Parejas!$B$5:$B$16,H17))} -> Francisco / Marcos | H17: =IF(Emparejar!$D$30=1,Emparejar!$E$46,"") -> 5 | J17: {=IF(K17="",IF(AND(E17<>"",F17<>"",E17=F17),"EMPATE: jugar OT",""),INDEX(Parejas!$B$5:$B$16,K17))} -> Cardozo / Cardozo | K17: =IF(OR(C17="",H17="",E17="",F17=""),"",IF(E17>F17,C17,IF(F17>E17,H17,""))) -> 1 | L17: {=IF(K17="","",INDEX(Calculo!$D$2:$D$13,H17))} -> 2 | M17: {=IF(K17="","",INDEX(Calculo!$D$2:$D$13,C17))} -> 3
A18: 14 | B18: R3 | C18: =IF(Emparejar!$D$30=1,Emparejar!$D$47,"") -> 9 | D18: {=IF(C18="","",INDEX(Parejas!$B$5:$B$16,C18))} -> Bautista / Luciano | E18: 9 | F18: 5 | G18: {=IF(H18="","",INDEX(Parejas!$B$5:$B$16,H18))} -> Diego / (a confirmar) | H18: =IF(Emparejar!$D$30=1,Emparejar!$E$47,"") -> 3 | J18: {=IF(K18="",IF(AND(E18<>"",F18<>"",E18=F18),"EMPATE: jugar OT",""),INDEX(Parejas!$B$5:$B$16,K18))} -> Bautista / Luciano | K18: =IF(OR(C18="",H18="",E18="",F18=""),"",IF(E18>F18,C18,IF(F18>E18,H18,""))) -> 9 | L18: {=IF(K18="","",INDEX(Calculo!$D$2:$D$13,H18))} -> 1 | M18: {=IF(K18="","",INDEX(Calculo!$D$2:$D$13,C18))} -> 3
A19: 15 | B19: R3 | C19: =IF(Emparejar!$D$30=1,Emparejar!$D$48,"") -> 2 | D19: {=IF(C19="","",INDEX(Parejas!$B$5:$B$16,C19))} -> Blas / Agustin | E19: 9 | F19: 2 | G19: {=IF(H19="","",INDEX(Parejas!$B$5:$B$16,H19))} -> Simon / Joaquin | H19: =IF(Emparejar!$D$30=1,Emparejar!$E$48,"") -> 7 | J19: {=IF(K19="",IF(AND(E19<>"",F19<>"",E19=F19),"EMPATE: jugar OT",""),INDEX(Parejas!$B$5:$B$16,K19))} -> Blas / Agustin | K19: =IF(OR(C19="",H19="",E19="",F19=""),"",IF(E19>F19,C19,IF(F19>E19,H19,""))) -> 2 | L19: {=IF(K19="","",INDEX(Calculo!$D$2:$D$13,H19))} -> 1 | M19: {=IF(K19="","",INDEX(Calculo!$D$2:$D$13,C19))} -> 2
A20: 16 | B20: R3 | C20: =IF(Emparejar!$D$30=1,Emparejar!$D$49,"") -> 11 | D20: {=IF(C20="","",INDEX(Parejas!$B$5:$B$16,C20))} -> Agustin / Rodrigo | E20: 9 | F20: 7 | G20: {=IF(H20="","",INDEX(Parejas!$B$5:$B$16,H20))} -> Luciano / Gonzalo | H20: =IF(Emparejar!$D$30=1,Emparejar!$E$49,"") -> 4 | J20: {=IF(K20="",IF(AND(E20<>"",F20<>"",E20=F20),"EMPATE: jugar OT",""),INDEX(Parejas!$B$5:$B$16,K20))} -> Agustin / Rodrigo | K20: =IF(OR(C20="",H20="",E20="",F20=""),"",IF(E20>F20,C20,IF(F20>E20,H20,""))) -> 11 | L20: {=IF(K20="","",INDEX(Calculo!$D$2:$D$13,H20))} -> 1 | M20: {=IF(K20="","",INDEX(Calculo!$D$2:$D$13,C20))} -> 2
A21: 17 | B21: R3 | C21: =IF(Emparejar!$D$30=1,Emparejar!$D$50,"") -> 12 | D21: {=IF(C21="","",INDEX(Parejas!$B$5:$B$16,C21))} -> Enzo / Gonza | E21: 9 | F21: 5 | G21: {=IF(H21="","",INDEX(Parejas!$B$5:$B$16,H21))} -> Lucas / Martin | H21: =IF(Emparejar!$D$30=1,Emparejar!$E$50,"") -> 10 | J21: {=IF(K21="",IF(AND(E21<>"",F21<>"",E21=F21),"EMPATE: jugar OT",""),INDEX(Parejas!$B$5:$B$16,K21))} -> Enzo / Gonza | K21: =IF(OR(C21="",H21="",E21="",F21=""),"",IF(E21>F21,C21,IF(F21>E21,H21,""))) -> 12 | L21: {=IF(K21="","",INDEX(Calculo!$D$2:$D$13,H21))} -> 0 | M21: {=IF(K21="","",INDEX(Calculo!$D$2:$D$13,C21))} -> 2
A22: 18 | B22: R3 | C22: =IF(Emparejar!$D$30=1,Emparejar!$D$51,"") -> 8 | D22: {=IF(C22="","",INDEX(Parejas!$B$5:$B$16,C22))} -> Rodrigo / Nazareno | E22: 9 | F22: 3 | G22: {=IF(H22="","",INDEX(Parejas!$B$5:$B$16,H22))} -> Luciano / Lautaro | H22: =IF(Emparejar!$D$30=1,Emparejar!$E$51,"") -> 6 | J22: {=IF(K22="",IF(AND(E22<>"",F22<>"",E22=F22),"EMPATE: jugar OT",""),INDEX(Parejas!$B$5:$B$16,K22))} -> Rodrigo / Nazareno | K22: =IF(OR(C22="",H22="",E22="",F22=""),"",IF(E22>F22,C22,IF(F22>E22,H22,""))) -> 8 | L22: {=IF(K22="","",INDEX(Calculo!$D$2:$D$13,H22))} -> 0 | M22: {=IF(K22="","",INDEX(Calculo!$D$2:$D$13,C22))} -> 1
A24: Ronda 1: sorteo al azar. Rondas 2 y 3: los cruces aparecen solos cuando termina la ronda anterior (mismo récord, sin repetir rival).
A25: Si querés cambiar un cruce a mano, escribí el ID encima (esa celda deja de ser automática).
A26: Si un partido termina 8-8, jueguen overtime y anotá el resultado final.

Sheet Calculo
A1: ID | B1: Pareja | C1: PJ | D1: PG | E1: PP | F1: RF | G1: RC | H1: Dif | I1: Buchholz | J1: Clave orden
A2: 1 | B2: {=INDEX(Parejas!$B$5:$B$16,A2)} -> Cardozo / Cardozo | C2: =COUNTIFS(Suizo!$C$5:$C$22,A2,Suizo!$K$5:$K$22,">0")+COUNTIFS(Suizo!$H$5:$H$22,A2,Suizo!$K$5:$K$22,">0") -> 3 | D2: =COUNTIF(Suizo!$K$5:$K$22,A2) -> 3 | E2: =C2-D2 -> 0 | F2: =SUMIFS(Suizo!$E$5:$E$22,Suizo!$C$5:$C$22,A2,Suizo!$K$5:$K$22,">0")+SUMIFS(Suizo!$F$5:$F$22,Suizo!$H$5:$H$22,A2,Suizo!$K$5:$K$22,">0") -> 27 | G2: =SUMIFS(Suizo!$F$5:$F$22,Suizo!$C$5:$C$22,A2,Suizo!$K$5:$K$22,">0")+SUMIFS(Suizo!$E$5:$E$22,Suizo!$H$5:$H$22,A2,Suizo!$K$5:$K$22,">0") -> 12 | H2: =F2-G2 -> 15 | I2: =SUMIFS(Suizo!$L$5:$L$22,Suizo!$C$5:$C$22,A2)+SUMIFS(Suizo!$M$5:$M$22,Suizo!$H$5:$H$22,A2) -> 4 | J2: =D2*1000000000+(H2+500)*1000000+I2*10000+F2*10-A2/100 -> 3515040270
A3: 2 | B3: {=INDEX(Parejas!$B$5:$B$16,A3)} -> Blas / Agustin | C3: =COUNTIFS(Suizo!$C$5:$C$22,A3,Suizo!$K$5:$K$22,">0")+COUNTIFS(Suizo!$H$5:$H$22,A3,Suizo!$K$5:$K$22,">0") -> 3 | D3: =COUNTIF(Suizo!$K$5:$K$22,A3) -> 2 | E3: =C3-D3 -> 1 | F3: =SUMIFS(Suizo!$E$5:$E$22,Suizo!$C$5:$C$22,A3,Suizo!$K$5:$K$22,">0")+SUMIFS(Suizo!$F$5:$F$22,Suizo!$H$5:$H$22,A3,Suizo!$K$5:$K$22,">0") -> 21 | G3: =SUMIFS(Suizo!$F$5:$F$22,Suizo!$C$5:$C$22,A3,Suizo!$K$5:$K$22,">0")+SUMIFS(Suizo!$E$5:$E$22,Suizo!$H$5:$H$22,A3,Suizo!$K$5:$K$22,">0") -> 12 | H3: =F3-G3 -> 9 | I3: =SUMIFS(Suizo!$L$5:$L$22,Suizo!$C$5:$C$22,A3)+SUMIFS(Suizo!$M$5:$M$22,Suizo!$H$5:$H$22,A3) -> 3 | J3: =D3*1000000000+(H3+500)*1000000+I3*10000+F3*10-A3/100 -> 2509030210
A4: 3 | B4: {=INDEX(Parejas!$B$5:$B$16,A4)} -> Diego / (a confirmar) | C4: =COUNTIFS(Suizo!$C$5:$C$22,A4,Suizo!$K$5:$K$22,">0")+COUNTIFS(Suizo!$H$5:$H$22,A4,Suizo!$K$5:$K$22,">0") -> 3 | D4: =COUNTIF(Suizo!$K$5:$K$22,A4) -> 1 | E4: =C4-D4 -> 2 | F4: =SUMIFS(Suizo!$E$5:$E$22,Suizo!$C$5:$C$22,A4,Suizo!$K$5:$K$22,">0")+SUMIFS(Suizo!$F$5:$F$22,Suizo!$H$5:$H$22,A4,Suizo!$K$5:$K$22,">0") -> 21 | G4: =SUMIFS(Suizo!$F$5:$F$22,Suizo!$C$5:$C$22,A4,Suizo!$K$5:$K$22,">0")+SUMIFS(Suizo!$E$5:$E$22,Suizo!$H$5:$H$22,A4,Suizo!$K$5:$K$22,">0") -> 20 | H4: =F4-G4 -> 1 | I4: =SUMIFS(Suizo!$L$5:$L$22,Suizo!$C$5:$C$22,A4)+SUMIFS(Suizo!$M$5:$M$22,Suizo!$H$5:$H$22,A4) -> 5 | J4: =D4*1000000000+(H4+500)*1000000+I4*10000+F4*10-A4/100 -> 1501050210
A5: 4 | B5: {=INDEX(Parejas!$B$5:$B$16,A5)} -> Luciano / Gonzalo | C5: =COUNTIFS(Suizo!$C$5:$C$22,A5,Suizo!$K$5:$K$22,">0")+COUNTIFS(Suizo!$H$5:$H$22,A5,Suizo!$K$5:$K$22,">0") -> 3 | D5: =COUNTIF(Suizo!$K$5:$K$22,A5) -> 1 | E5: =C5-D5 -> 2 | F5: =SUMIFS(Suizo!$E$5:$E$22,Suizo!$C$5:$C$22,A5,Suizo!$K$5:$K$22,">0")+SUMIFS(Suizo!$F$5:$F$22,Suizo!$H$5:$H$22,A5,Suizo!$K$5:$K$22,">0") -> 17 | G5: =SUMIFS(Suizo!$F$5:$F$22,Suizo!$C$5:$C$22,A5,Suizo!$K$5:$K$22,">0")+SUMIFS(Suizo!$E$5:$E$22,Suizo!$H$5:$H$22,A5,Suizo!$K$5:$K$22,">0") -> 25 | H5: =F5-G5 -> -8 | I5: =SUMIFS(Suizo!$L$5:$L$22,Suizo!$C$5:$C$22,A5)+SUMIFS(Suizo!$M$5:$M$22,Suizo!$H$5:$H$22,A5) -> 6 | J5: =D5*1000000000+(H5+500)*1000000+I5*10000+F5*10-A5/100 -> 1492060170
A6: 5 | B6: {=INDEX(Parejas!$B$5:$B$16,A6)} -> Francisco / Marcos | C6: =COUNTIFS(Suizo!$C$5:$C$22,A6,Suizo!$K$5:$K$22,">0")+COUNTIFS(Suizo!$H$5:$H$22,A6,Suizo!$K$5:$K$22,">0") -> 3 | D6: =COUNTIF(Suizo!$K$5:$K$22,A6) -> 2 | E6: =C6-D6 -> 1 | F6: =SUMIFS(Suizo!$E$5:$E$22,Suizo!$C$5:$C$22,A6,Suizo!$K$5:$K$22,">0")+SUMIFS(Suizo!$F$5:$F$22,Suizo!$H$5:$H$22,A6,Suizo!$K$5:$K$22,">0") -> 25 | G6: =SUMIFS(Suizo!$F$5:$F$22,Suizo!$C$5:$C$22,A6,Suizo!$K$5:$K$22,">0")+SUMIFS(Suizo!$E$5:$E$22,Suizo!$H$5:$H$22,A6,Suizo!$K$5:$K$22,">0") -> 15 | H6: =F6-G6 -> 10 | I6: =SUMIFS(Suizo!$L$5:$L$22,Suizo!$C$5:$C$22,A6)+SUMIFS(Suizo!$M$5:$M$22,Suizo!$H$5:$H$22,A6) -> 7 | J6: =D6*1000000000+(H6+500)*1000000+I6*10000+F6*10-A6/100 -> 2510070250
A7: 6 | B7: {=INDEX(Parejas!$B$5:$B$16,A7)} -> Luciano / Lautaro | C7: =COUNTIFS(Suizo!$C$5:$C$22,A7,Suizo!$K$5:$K$22,">0")+COUNTIFS(Suizo!$H$5:$H$22,A7,Suizo!$K$5:$K$22,">0") -> 3 | D7: =COUNTIF(Suizo!$K$5:$K$22,A7) -> 0 | E7: =C7-D7 -> 3 | F7: =SUMIFS(Suizo!$E$5:$E$22,Suizo!$C$5:$C$22,A7,Suizo!$K$5:$K$22,">0")+SUMIFS(Suizo!$F$5:$F$22,Suizo!$H$5:$H$22,A7,Suizo!$K$5:$K$22,">0") -> 11 | G7: =SUMIFS(Suizo!$F$5:$F$22,Suizo!$C$5:$C$22,A7,Suizo!$K$5:$K$22,">0")+SUMIFS(Suizo!$E$5:$E$22,Suizo!$H$5:$H$22,A7,Suizo!$K$5:$K$22,">0") -> 27 | H7: =F7-G7 -> -16 | I7: =SUMIFS(Suizo!$L$5:$L$22,Suizo!$C$5:$C$22,A7)+SUMIFS(Suizo!$M$5:$M$22,Suizo!$H$5:$H$22,A7) -> 5 | J7: =D7*1000000000+(H7+500)*1000000+I7*10000+F7*10-A7/100 -> 4.8405011e+08
A8: 7 | B8: {=INDEX(Parejas!$B$5:$B$16,A8)} -> Simon / Joaquin | C8: =COUNTIFS(Suizo!$C$5:$C$22,A8,Suizo!$K$5:$K$22,">0")+COUNTIFS(Suizo!$H$5:$H$22,A8,Suizo!$K$5:$K$22,">0") -> 3 | D8: =COUNTIF(Suizo!$K$5:$K$22,A8) -> 1 | E8: =C8-D8 -> 2 | F8: =SUMIFS(Suizo!$E$5:$E$22,Suizo!$C$5:$C$22,A8,Suizo!$K$5:$K$22,">0")+SUMIFS(Suizo!$F$5:$F$22,Suizo!$H$5:$H$22,A8,Suizo!$K$5:$K$22,">0") -> 15 | G8: =SUMIFS(Suizo!$F$5:$F$22,Suizo!$C$5:$C$22,A8,Suizo!$K$5:$K$22,">0")+SUMIFS(Suizo!$E$5:$E$22,Suizo!$H$5:$H$22,A8,Suizo!$K$5:$K$22,">0") -> 23 | H8: =F8-G8 -> -8 | I8: =SUMIFS(Suizo!$L$5:$L$22,Suizo!$C$5:$C$22,A8)+SUMIFS(Suizo!$M$5:$M$22,Suizo!$H$5:$H$22,A8) -> 5 | J8: =D8*1000000000+(H8+500)*1000000+I8*10000+F8*10-A8/100 -> 1492050150
A9: 8 | B9: {=INDEX(Parejas!$B$5:$B$16,A9)} -> Rodrigo / Nazareno | C9: =COUNTIFS(Suizo!$C$5:$C$22,A9,Suizo!$K$5:$K$22,">0")+COUNTIFS(Suizo!$H$5:$H$22,A9,Suizo!$K$5:$K$22,">0") -> 3 | D9: =COUNTIF(Suizo!$K$5:$K$22,A9) -> 1 | E9: =C9-D9 -> 2 | F9: =SUMIFS(Suizo!$E$5:$E$22,Suizo!$C$5:$C$22,A9,Suizo!$K$5:$K$22,">0")+SUMIFS(Suizo!$F$5:$F$22,Suizo!$H$5:$H$22,A9,Suizo!$K$5:$K$22,">0") -> 18 | G9: =SUMIFS(Suizo!$F$5:$F$22,Suizo!$C$5:$C$22,A9,Suizo!$K$5:$K$22,">0")+SUMIFS(Suizo!$E$5:$E$22,Suizo!$H$5:$H$22,A9,Suizo!$K$5:$K$22,">0") -> 21 | H9: =F9-G9 -> -3 | I9: =SUMIFS(Suizo!$L$5:$L$22,Suizo!$C$5:$C$22,A9)+SUMIFS(Suizo!$M$5:$M$22,Suizo!$H$5:$H$22,A9) -> 3 | J9: =D9*1000000000+(H9+500)*1000000+I9*10000+F9*10-A9/100 -> 1497030180
A10: 9 | B10: {=INDEX(Parejas!$B$5:$B$16,A10)} -> Bautista / Luciano | C10: =COUNTIFS(Suizo!$C$5:$C$22,A10,Suizo!$K$5:$K$22,">0")+COUNTIFS(Suizo!$H$5:$H$22,A10,Suizo!$K$5:$K$22,">0") -> 3 | D10: =COUNTIF(Suizo!$K$5:$K$22,A10) -> 3 | E10: =C10-D10 -> 0 | F10: =SUMIFS(Suizo!$E$5:$E$22,Suizo!$C$5:$C$22,A10,Suizo!$K$5:$K$22,">0")+SUMIFS(Suizo!$F$5:$F$22,Suizo!$H$5:$H$22,A10,Suizo!$K$5:$K$22,">0") -> 27 | G10: =SUMIFS(Suizo!$F$5:$F$22,Suizo!$C$5:$C$22,A10,Suizo!$K$5:$K$22,">0")+SUMIFS(Suizo!$E$5:$E$22,Suizo!$H$5:$H$22,A10,Suizo!$K$5:$K$22,">0") -> 12 | H10: =F10-G10 -> 15 | I10: =SUMIFS(Suizo!$L$5:$L$22,Suizo!$C$5:$C$22,A10)+SUMIFS(Suizo!$M$5:$M$22,Suizo!$H$5:$H$22,A10) -> 3 | J10: =D10*1000000000+(H10+500)*1000000+I10*10000+F10*10-A10/100 -> 3515030270
A11: 10 | B11: {=INDEX(Parejas!$B$5:$B$16,A11)} -> Lucas / Martin | C11: =COUNTIFS(Suizo!$C$5:$C$22,A11,Suizo!$K$5:$K$22,">0")+COUNTIFS(Suizo!$H$5:$H$22,A11,Suizo!$K$5:$K$22,">0") -> 3 | D11: =COUNTIF(Suizo!$K$5:$K$22,A11) -> 0 | E11: =C11-D11 -> 3 | F11: =SUMIFS(Suizo!$E$5:$E$22,Suizo!$C$5:$C$22,A11,Suizo!$K$5:$K$22,">0")+SUMIFS(Suizo!$F$5:$F$22,Suizo!$H$5:$H$22,A11,Suizo!$K$5:$K$22,">0") -> 17 | G11: =SUMIFS(Suizo!$F$5:$F$22,Suizo!$C$5:$C$22,A11,Suizo!$K$5:$K$22,">0")+SUMIFS(Suizo!$E$5:$E$22,Suizo!$H$5:$H$22,A11,Suizo!$K$5:$K$22,">0") -> 27 | H11: =F11-G11 -> -10 | I11: =SUMIFS(Suizo!$L$5:$L$22,Suizo!$C$5:$C$22,A11)+SUMIFS(Suizo!$M$5:$M$22,Suizo!$H$5:$H$22,A11) -> 6 | J11: =D11*1000000000+(H11+500)*1000000+I11*10000+F11*10-A11/100 -> 4.9006017e+08
A12: 11 | B12: {=INDEX(Parejas!$B$5:$B$16,A12)} -> Agustin / Rodrigo | C12: =COUNTIFS(Suizo!$C$5:$C$22,A12,Suizo!$K$5:$K$22,">0")+COUNTIFS(Suizo!$H$5:$H$22,A12,Suizo!$K$5:$K$22,">0") -> 3 | D12: =COUNTIF(Suizo!$K$5:$K$22,A12) -> 2 | E12: =C12-D12 -> 1 | F12: =SUMIFS(Suizo!$E$5:$E$22,Suizo!$C$5:$C$22,A12,Suizo!$K$5:$K$22,">0")+SUMIFS(Suizo!$F$5:$F$22,Suizo!$H$5:$H$22,A12,Suizo!$K$5:$K$22,">0") -> 21 | G12: =SUMIFS(Suizo!$F$5:$F$22,Suizo!$C$5:$C$22,A12,Suizo!$K$5:$K$22,">0")+SUMIFS(Suizo!$E$5:$E$22,Suizo!$H$5:$H$22,A12,Suizo!$K$5:$K$22,">0") -> 23 | H12: =F12-G12 -> -2 | I12: =SUMIFS(Suizo!$L$5:$L$22,Suizo!$C$5:$C$22,A12)+SUMIFS(Suizo!$M$5:$M$22,Suizo!$H$5:$H$22,A12) -> 3 | J12: =D12*1000000000+(H12+500)*1000000+I12*10000+F12*10-A12/100 -> 2498030210
A13: 12 | B13: {=INDEX(Parejas!$B$5:$B$16,A13)} -> Enzo / Gonza | C13: =COUNTIFS(Suizo!$C$5:$C$22,A13,Suizo!$K$5:$K$22,">0")+COUNTIFS(Suizo!$H$5:$H$22,A13,Suizo!$K$5:$K$22,">0") -> 3 | D13: =COUNTIF(Suizo!$K$5:$K$22,A13) -> 2 | E13: =C13-D13 -> 1 | F13: =SUMIFS(Suizo!$E$5:$E$22,Suizo!$C$5:$C$22,A13,Suizo!$K$5:$K$22,">0")+SUMIFS(Suizo!$F$5:$F$22,Suizo!$H$5:$H$22,A13,Suizo!$K$5:$K$22,">0") -> 18 | G13: =SUMIFS(Suizo!$F$5:$F$22,Suizo!$C$5:$C$22,A13,Suizo!$K$5:$K$22,">0")+SUMIFS(Suizo!$E$5:$E$22,Suizo!$H$5:$H$22,A13,Suizo!$K$5:$K$22,">0") -> 21 | H13: =F13-G13 -> -3 | I13: =SUMIFS(Suizo!$L$5:$L$22,Suizo!$C$5:$C$22,A13)+SUMIFS(Suizo!$M$5:$M$22,Suizo!$H$5:$H$22,A13) -> 4 | J13: =D13*1000000000+(H13+500)*1000000+I13*10000+F13*10-A13/100 -> 2497040180
A15: Hoja de cálculo interna: no editar. Clave = PG > Dif. rounds > Buchholz > Rounds a favor > ID (desempate final).

Sheet Emparejar
A1: Ronda 2 | C1: lista | D1: =IF(COUNTIF(Suizo!$K$5:$K$10,">0")=6,1,0) -> 1
A2: ID | B2: PG | C2: Dif | D2: RF | E2: Clave | F2: Pos | G2: ID en pos
A3: 1 | B3: =COUNTIF(Suizo!$K$5:$K$10,A3) -> 1 | C3: =(SUMIFS(Suizo!$E$5:$E$10,Suizo!$C$5:$C$10,A3,Suizo!$K$5:$K$10,">0")+SUMIFS(Suizo!$F$5:$F$10,Suizo!$H$5:$H$10,A3,Suizo!$K$5:$K$10,">0"))-(SUMIFS(Suizo!$F$5:$F$10,Suizo!$C$5:$C$10,A3,Suizo!$K$5:$K$10,">0")+SUMIFS(Suizo!$E$5:$E$10,Suizo!$H$5:$H$10,A3,Suizo!$K$5:$K$10,">0")) -> 5 | D3: =(SUMIFS(Suizo!$E$5:$E$10,Suizo!$C$5:$C$10,A3,Suizo!$K$5:$K$10,">0")+SUMIFS(Suizo!$F$5:$F$10,Suizo!$H$5:$H$10,A3,Suizo!$K$5:$K$10,">0")) -> 9 | E3: =B3*100000000+(C3+500)*100000+D3*100-A3 -> 150500899 | F3: 1 | G3: =INDEX($A$3:$A$14,MATCH(LARGE($E$3:$E$14,F3),$E$3:$E$14,0)) -> 2
A4: 2 | B4: =COUNTIF(Suizo!$K$5:$K$10,A4) -> 1 | C4: =(SUMIFS(Suizo!$E$5:$E$10,Suizo!$C$5:$C$10,A4,Suizo!$K$5:$K$10,">0")+SUMIFS(Suizo!$F$5:$F$10,Suizo!$H$5:$H$10,A4,Suizo!$K$5:$K$10,">0"))-(SUMIFS(Suizo!$F$5:$F$10,Suizo!$C$5:$C$10,A4,Suizo!$K$5:$K$10,">0")+SUMIFS(Suizo!$E$5:$E$10,Suizo!$H$5:$H$10,A4,Suizo!$K$5:$K$10,">0")) -> 8 | D4: =(SUMIFS(Suizo!$E$5:$E$10,Suizo!$C$5:$C$10,A4,Suizo!$K$5:$K$10,">0")+SUMIFS(Suizo!$F$5:$F$10,Suizo!$H$5:$H$10,A4,Suizo!$K$5:$K$10,">0")) -> 9 | E4: =B4*100000000+(C4+500)*100000+D4*100-A4 -> 150800898 | F4: 2 | G4: =INDEX($A$3:$A$14,MATCH(LARGE($E$3:$E$14,F4),$E$3:$E$14,0)) -> 5
A5: 3 | B5: =COUNTIF(Suizo!$K$5:$K$10,A5) -> 0 | C5: =(SUMIFS(Suizo!$E$5:$E$10,Suizo!$C$5:$C$10,A5,Suizo!$K$5:$K$10,">0")+SUMIFS(Suizo!$F$5:$F$10,Suizo!$H$5:$H$10,A5,Suizo!$K$5:$K$10,">0"))-(SUMIFS(Suizo!$F$5:$F$10,Suizo!$C$5:$C$10,A5,Suizo!$K$5:$K$10,">0")+SUMIFS(Suizo!$E$5:$E$10,Suizo!$H$5:$H$10,A5,Suizo!$K$5:$K$10,">0")) -> -2 | D5: =(SUMIFS(Suizo!$E$5:$E$10,Suizo!$C$5:$C$10,A5,Suizo!$K$5:$K$10,">0")+SUMIFS(Suizo!$F$5:$F$10,Suizo!$H$5:$H$10,A5,Suizo!$K$5:$K$10,">0")) -> 7 | E5: =B5*100000000+(C5+500)*100000+D5*100-A5 -> 49800697 | F5: 3 | G5: =INDEX($A$3:$A$14,MATCH(LARGE($E$3:$E$14,F5),$E$3:$E$14,0)) -> 1
A6: 4 | B6: =COUNTIF(Suizo!$K$5:$K$10,A6) -> 1 | C6: =(SUMIFS(Suizo!$E$5:$E$10,Suizo!$C$5:$C$10,A6,Suizo!$K$5:$K$10,">0")+SUMIFS(Suizo!$F$5:$F$10,Suizo!$H$5:$H$10,A6,Suizo!$K$5:$K$10,">0"))-(SUMIFS(Suizo!$F$5:$F$10,Suizo!$C$5:$C$10,A6,Suizo!$K$5:$K$10,">0")+SUMIFS(Suizo!$E$5:$E$10,Suizo!$H$5:$H$10,A6,Suizo!$K$5:$K$10,">0")) -> 2 | D6: =(SUMIFS(Suizo!$E$5:$E$10,Suizo!$C$5:$C$10,A6,Suizo!$K$5:$K$10,">0")+SUMIFS(Suizo!$F$5:$F$10,Suizo!$H$5:$H$10,A6,Suizo!$K$5:$K$10,">0")) -> 9 | E6: =B6*100000000+(C6+500)*100000+D6*100-A6 -> 150200896 | F6: 4 | G6: =INDEX($A$3:$A$14,MATCH(LARGE($E$3:$E$14,F6),$E$3:$E$14,0)) -> 4
A7: 5 | B7: =COUNTIF(Suizo!$K$5:$K$10,A7) -> 1 | C7: =(SUMIFS(Suizo!$E$5:$E$10,Suizo!$C$5:$C$10,A7,Suizo!$K$5:$K$10,">0")+SUMIFS(Suizo!$F$5:$F$10,Suizo!$H$5:$H$10,A7,Suizo!$K$5:$K$10,">0"))-(SUMIFS(Suizo!$F$5:$F$10,Suizo!$C$5:$C$10,A7,Suizo!$K$5:$K$10,">0")+SUMIFS(Suizo!$E$5:$E$10,Suizo!$H$5:$H$10,A7,Suizo!$K$5:$K$10,">0")) -> 6 | D7: =(SUMIFS(Suizo!$E$5:$E$10,Suizo!$C$5:$C$10,A7,Suizo!$K$5:$K$10,">0")+SUMIFS(Suizo!$F$5:$F$10,Suizo!$H$5:$H$10,A7,Suizo!$K$5:$K$10,">0")) -> 9 | E7: =B7*100000000+(C7+500)*100000+D7*100-A7 -> 150600895 | F7: 5 | G7: =INDEX($A$3:$A$14,MATCH(LARGE($E$3:$E$14,F7),$E$3:$E$14,0)) -> 9
A8: 6 | B8: =COUNTIF(Suizo!$K$5:$K$10,A8) -> 0 | C8: =(SUMIFS(Suizo!$E$5:$E$10,Suizo!$C$5:$C$10,A8,Suizo!$K$5:$K$10,">0")+SUMIFS(Suizo!$F$5:$F$10,Suizo!$H$5:$H$10,A8,Suizo!$K$5:$K$10,">0"))-(SUMIFS(Suizo!$F$5:$F$10,Suizo!$C$5:$C$10,A8,Suizo!$K$5:$K$10,">0")+SUMIFS(Suizo!$E$5:$E$10,Suizo!$H$5:$H$10,A8,Suizo!$K$5:$K$10,">0")) -> -8 | D8: =(SUMIFS(Suizo!$E$5:$E$10,Suizo!$C$5:$C$10,A8,Suizo!$K$5:$K$10,">0")+SUMIFS(Suizo!$F$5:$F$10,Suizo!$H$5:$H$10,A8,Suizo!$K$5:$K$10,">0")) -> 1 | E8: =B8*100000000+(C8+500)*100000+D8*100-A8 -> 49200094 | F8: 6 | G8: =INDEX($A$3:$A$14,MATCH(LARGE($E$3:$E$14,F8),$E$3:$E$14,0)) -> 12
A9: 7 | B9: =COUNTIF(Suizo!$K$5:$K$10,A9) -> 0 | C9: =(SUMIFS(Suizo!$E$5:$E$10,Suizo!$C$5:$C$10,A9,Suizo!$K$5:$K$10,">0")+SUMIFS(Suizo!$F$5:$F$10,Suizo!$H$5:$H$10,A9,Suizo!$K$5:$K$10,">0"))-(SUMIFS(Suizo!$F$5:$F$10,Suizo!$C$5:$C$10,A9,Suizo!$K$5:$K$10,">0")+SUMIFS(Suizo!$E$5:$E$10,Suizo!$H$5:$H$10,A9,Suizo!$K$5:$K$10,">0")) -> -5 | D9: =(SUMIFS(Suizo!$E$5:$E$10,Suizo!$C$5:$C$10,A9,Suizo!$K$5:$K$10,">0")+SUMIFS(Suizo!$F$5:$F$10,Suizo!$H$5:$H$10,A9,Suizo!$K$5:$K$10,">0")) -> 4 | E9: =B9*100000000+(C9+500)*100000+D9*100-A9 -> 49500393 | F9: 7 | G9: =INDEX($A$3:$A$14,MATCH(LARGE($E$3:$E$14,F9),$E$3:$E$14,0)) -> 3
A10: 8 | B10: =COUNTIF(Suizo!$K$5:$K$10,A10) -> 0 | C10: =(SUMIFS(Suizo!$E$5:$E$10,Suizo!$C$5:$C$10,A10,Suizo!$K$5:$K$10,">0")+SUMIFS(Suizo!$F$5:$F$10,Suizo!$H$5:$H$10,A10,Suizo!$K$5:$K$10,">0"))-(SUMIFS(Suizo!$F$5:$F$10,Suizo!$C$5:$C$10,A10,Suizo!$K$5:$K$10,">0")+SUMIFS(Suizo!$E$5:$E$10,Suizo!$H$5:$H$10,A10,Suizo!$K$5:$K$10,">0")) -> -2 | D10: =(SUMIFS(Suizo!$E$5:$E$10,Suizo!$C$5:$C$10,A10,Suizo!$K$5:$K$10,">0")+SUMIFS(Suizo!$F$5:$F$10,Suizo!$H$5:$H$10,A10,Suizo!$K$5:$K$10,">0")) -> 7 | E10: =B10*100000000+(C10+500)*100000+D10*100-A10 -> 49800692 | F10: 8 | G10: =INDEX($A$3:$A$14,MATCH(LARGE($E$3:$E$14,F10),$E$3:$E$14,0)) -> 8
A11: 9 | B11: =COUNTIF(Suizo!$K$5:$K$10,A11) -> 1 | C11: =(SUMIFS(Suizo!$E$5:$E$10,Suizo!$C$5:$C$10,A11,Suizo!$K$5:$K$10,">0")+SUMIFS(Suizo!$F$5:$F$10,Suizo!$H$5:$H$10,A11,Suizo!$K$5:$K$10,">0"))-(SUMIFS(Suizo!$F$5:$F$10,Suizo!$C$5:$C$10,A11,Suizo!$K$5:$K$10,">0")+SUMIFS(Suizo!$E$5:$E$10,Suizo!$H$5:$H$10,A11,Suizo!$K$5:$K$10,">0")) -> 2 | D11: =(SUMIFS(Suizo!$E$5:$E$10,Suizo!$C$5:$C$10,A11,Suizo!$K$5:$K$10,">0")+SUMIFS(Suizo!$F$5:$F$10,Suizo!$H$5:$H$10,A11,Suizo!$K$5:$K$10,">0")) -> 9 | E11: =B11*100000000+(C11+500)*100000+D11*100-A11 -> 150200891 | F11: 9 | G11: =INDEX($A$3:$A$14,MATCH(LARGE($E$3:$E$14,F11),$E$3:$E$14,0)) -> 10
A12: 10 | B12: =COUNTIF(Suizo!$K$5:$K$10,A12) -> 0 | C12: =(SUMIFS(Suizo!$E$5:$E$10,Suizo!$C$5:$C$10,A12,Suizo!$K$5:$K$10,">0")+SUMIFS(Suizo!$F$5:$F$10,Suizo!$H$5:$H$10,A12,Suizo!$K$5:$K$10,">0"))-(SUMIFS(Suizo!$F$5:$F$10,Suizo!$C$5:$C$10,A12,Suizo!$K$5:$K$10,">0")+SUMIFS(Suizo!$E$5:$E$10,Suizo!$H$5:$H$10,A12,Suizo!$K$5:$K$10,">0")) -> -2 | D12: =(SUMIFS(Suizo!$E$5:$E$10,Suizo!$C$5:$C$10,A12,Suizo!$K$5:$K$10,">0")+SUMIFS(Suizo!$F$5:$F$10,Suizo!$H$5:$H$10,A12,Suizo!$K$5:$K$10,">0")) -> 7 | E12: =B12*100000000+(C12+500)*100000+D12*100-A12 -> 49800690 | F12: 10 | G12: =INDEX($A$3:$A$14,MATCH(LARGE($E$3:$E$14,F12),$E$3:$E$14,0)) -> 7
A13: 11 | B13: =COUNTIF(Suizo!$K$5:$K$10,A13) -> 0 | C13: =(SUMIFS(Suizo!$E$5:$E$10,Suizo!$C$5:$C$10,A13,Suizo!$K$5:$K$10,">0")+SUMIFS(Suizo!$F$5:$F$10,Suizo!$H$5:$H$10,A13,Suizo!$K$5:$K$10,">0"))-(SUMIFS(Suizo!$F$5:$F$10,Suizo!$C$5:$C$10,A13,Suizo!$K$5:$K$10,">0")+SUMIFS(Suizo!$E$5:$E$10,Suizo!$H$5:$H$10,A13,Suizo!$K$5:$K$10,">0")) -> -6 | D13: =(SUMIFS(Suizo!$E$5:$E$10,Suizo!$C$5:$C$10,A13,Suizo!$K$5:$K$10,">0")+SUMIFS(Suizo!$F$5:$F$10,Suizo!$H$5:$H$10,A13,Suizo!$K$5:$K$10,">0")) -> 3 | E13: =B13*100000000+(C13+500)*100000+D13*100-A13 -> 49400289 | F13: 11 | G13: =INDEX($A$3:$A$14,MATCH(LARGE($E$3:$E$14,F13),$E$3:$E$14,0)) -> 11
A14: 12 | B14: =COUNTIF(Suizo!$K$5:$K$10,A14) -> 1 | C14: =(SUMIFS(Suizo!$E$5:$E$10,Suizo!$C$5:$C$10,A14,Suizo!$K$5:$K$10,">0")+SUMIFS(Suizo!$F$5:$F$10,Suizo!$H$5:$H$10,A14,Suizo!$K$5:$K$10,">0"))-(SUMIFS(Suizo!$F$5:$F$10,Suizo!$C$5:$C$10,A14,Suizo!$K$5:$K$10,">0")+SUMIFS(Suizo!$E$5:$E$10,Suizo!$H$5:$H$10,A14,Suizo!$K$5:$K$10,">0")) -> 2 | D14: =(SUMIFS(Suizo!$E$5:$E$10,Suizo!$C$5:$C$10,A14,Suizo!$K$5:$K$10,">0")+SUMIFS(Suizo!$F$5:$F$10,Suizo!$H$5:$H$10,A14,Suizo!$K$5:$K$10,">0")) -> 9 | E14: =B14*100000000+(C14+500)*100000+D14*100-A14 -> 150200888 | F14: 12 | G14: =INDEX($A$3:$A$14,MATCH(LARGE($E$3:$E$14,F14),$E$3:$E$14,0)) -> 6
A16: Paso | B16: PosA | C16: PosB | D16: ID A | E16: ID B
A17: 1 | B17: =MATCH(0,F17:Q17,0) -> 1 | C17: =IF(MIN(R17:AC17)<99,MIN(R17:AC17),MIN(AD17:AO17)) -> 2 | D17: =INDEX($G$3:$G$14,B17) -> 2 | E17: =INDEX($G$3:$G$14,C17) -> 5 | F17: 0 | G17: 0 | H17: 0 | I17: 0 | J17: 0 | K17: 0 | L17: 0 | M17: 0 | N17: 0 | O17: 0 | P17: 0 | Q17: 0 | R17: {=IF(AND(F17=0,1>B17,(COUNTIFS(Suizo!$C$5:$C$10,D17,Suizo!$H$5:$H$10,INDEX($G$3:$G$14,1))+COUNTIFS(Suizo!$C$5:$C$10,INDEX($G$3:$G$14,1),Suizo!$H$5:$H$10,D17))=0),1,99)} -> 99 | S17: {=IF(AND(G17=0,2>B17,(COUNTIFS(Suizo!$C$5:$C$10,D17,Suizo!$H$5:$H$10,INDEX($G$3:$G$14,2))+COUNTIFS(Suizo!$C$5:$C$10,INDEX($G$3:$G$14,2),Suizo!$H$5:$H$10,D17))=0),2,99)} -> 2 | T17: {=IF(AND(H17=0,3>B17,(COUNTIFS(Suizo!$C$5:$C$10,D17,Suizo!$H$5:$H$10,INDEX($G$3:$G$14,3))+COUNTIFS(Suizo!$C$5:$C$10,INDEX($G$3:$G$14,3),Suizo!$H$5:$H$10,D17))=0),3,99)} -> 3 | U17: {=IF(AND(I17=0,4>B17,(COUNTIFS(Suizo!$C$5:$C$10,D17,Suizo!$H$5:$H$10,INDEX($G$3:$G$14,4))+COUNTIFS(Suizo!$C$5:$C$10,INDEX($G$3:$G$14,4),Suizo!$H$5:$H$10,D17))=0),4,99)} -> 4 | V17: {=IF(AND(J17=0,5>B17,(COUNTIFS(Suizo!$C$5:$C$10,D17,Suizo!$H$5:$H$10,INDEX($G$3:$G$14,5))+COUNTIFS(Suizo!$C$5:$C$10,INDEX($G$3:$G$14,5),Suizo!$H$5:$H$10,D17))=0),5,99)} -> 5 | W17: {=IF(AND(K17=0,6>B17,(COUNTIFS(Suizo!$C$5:$C$10,D17,Suizo!$H$5:$H$10,INDEX($G$3:$G$14,6))+COUNTIFS(Suizo!$C$5:$C$10,INDEX($G$3:$G$14,6),Suizo!$H$5:$H$10,D17))=0),6,99)} -> 6 | X17: {=IF(AND(L17=0,7>B17,(COUNTIFS(Suizo!$C$5:$C$10,D17,Suizo!$H$5:$H$10,INDEX($G$3:$G$14,7))+COUNTIFS(Suizo!$C$5:$C$10,INDEX($G$3:$G$14,7),Suizo!$H$5:$H$10,D17))=0),7,99)} -> 7 | Y17: {=IF(AND(M17=0,8>B17,(COUNTIFS(Suizo!$C$5:$C$10,D17,Suizo!$H$5:$H$10,INDEX($G$3:$G$14,8))+COUNTIFS(Suizo!$C$5:$C$10,INDEX($G$3:$G$14,8),Suizo!$H$5:$H$10,D17))=0),8,99)} -> 8 | Z17: {=IF(AND(N17=0,9>B17,(COUNTIFS(Suizo!$C$5:$C$10,D17,Suizo!$H$5:$H$10,INDEX($G$3:$G$14,9))+COUNTIFS(Suizo!$C$5:$C$10,INDEX($G$3:$G$14,9),Suizo!$H$5:$H$10,D17))=0),9,99)} -> 9 | AA17: {=IF(AND(O17=0,10>B17,(COUNTIFS(Suizo!$C$5:$C$10,D17,Suizo!$H$5:$H$10,INDEX($G$3:$G$14,10))+COUNTIFS(Suizo!$C$5:$C$10,INDEX($G$3:$G$14,10),Suizo!$H$5:$H$10,D17))=0),10,99)} -> 10 | AB17: {=IF(AND(P17=0,11>B17,(COUNTIFS(Suizo!$C$5:$C$10,D17,Suizo!$H$5:$H$10,INDEX($G$3:$G$14,11))+COUNTIFS(Suizo!$C$5:$C$10,INDEX($G$3:$G$14,11),Suizo!$H$5:$H$10,D17))=0),11,99)} -> 11 | AC17: {=IF(AND(Q17=0,12>B17,(COUNTIFS(Suizo!$C$5:$C$10,D17,Suizo!$H$5:$H$10,INDEX($G$3:$G$14,12))+COUNTIFS(Suizo!$C$5:$C$10,INDEX($G$3:$G$14,12),Suizo!$H$5:$H$10,D17))=0),12,99)} -> 99 | AD17: =IF(AND(F17=0,1>B17),1,99) -> 99 | AE17: =IF(AND(G17=0,2>B17),2,99) -> 2 | AF17: =IF(AND(H17=0,3>B17),3,99) -> 3 | AG17: =IF(AND(I17=0,4>B17),4,99) -> 4 | AH17: =IF(AND(J17=0,5>B17),5,99) -> 5 | AI17: =IF(AND(K17=0,6>B17),6,99) -> 6 | AJ17: =IF(AND(L17=0,7>B17),7,99) -> 7 | AK17: =IF(AND(M17=0,8>B17),8,99) -> 8 | AL17: =IF(AND(N17=0,9>B17),9,99) -> 9 | AM17: =IF(AND(O17=0,10>B17),10,99) -> 10 | AN17: =IF(AND(P17=0,11>B17),11,99) -> 11 | AO17: =IF(AND(Q17=0,12>B17),12,99) -> 12 | AP17: =IF(MIN(R17:AC17)=99,"REVANCHA","")
A18: 2 | B18: =MATCH(0,F18:Q18,0) -> 3 | C18: =IF(MIN(R18:AC18)<99,MIN(R18:AC18),MIN(AD18:AO18)) -> 4 | D18: =INDEX($G$3:$G$14,B18) -> 1 | E18: =INDEX($G$3:$G$14,C18) -> 4 | F18: =IF(OR(F17=1,B17=1,C17=1),1,0) -> 1 | G18: =IF(OR(G17=1,B17=2,C17=2),1,0) -> 1 | H18: =IF(OR(H17=1,B17=3,C17=3),1,0) -> 0 | I18: =IF(OR(I17=1,B17=4,C17=4),1,0) -> 0 | J18: =IF(OR(J17=1,B17=5,C17=5),1,0) -> 0 | K18: =IF(OR(K17=1,B17=6,C17=6),1,0) -> 0 | L18: =IF(OR(L17=1,B17=7,C17=7),1,0) -> 0 | M18: =IF(OR(M17=1,B17=8,C17=8),1,0) -> 0 | N18: =IF(OR(N17=1,B17=9,C17=9),1,0) -> 0 | O18: =IF(OR(O17=1,B17=10,C17=10),1,0) -> 0 | P18: =IF(OR(P17=1,B17=11,C17=11),1,0) -> 0 | Q18: =IF(OR(Q17=1,B17=12,C17=12),1,0) -> 0 | R18: {=IF(AND(F18=0,1>B18,(COUNTIFS(Suizo!$C$5:$C$10,D18,Suizo!$H$5:$H$10,INDEX($G$3:$G$14,1))+COUNTIFS(Suizo!$C$5:$C$10,INDEX($G$3:$G$14,1),Suizo!$H$5:$H$10,D18))=0),1,99)} -> 99 | S18: {=IF(AND(G18=0,2>B18,(COUNTIFS(Suizo!$C$5:$C$10,D18,Suizo!$H$5:$H$10,INDEX($G$3:$G$14,2))+COUNTIFS(Suizo!$C$5:$C$10,INDEX($G$3:$G$14,2),Suizo!$H$5:$H$10,D18))=0),2,99)} -> 99 | T18: {=IF(AND(H18=0,3>B18,(COUNTIFS(Suizo!$C$5:$C$10,D18,Suizo!$H$5:$H$10,INDEX($G$3:$G$14,3))+COUNTIFS(Suizo!$C$5:$C$10,INDEX($G$3:$G$14,3),Suizo!$H$5:$H$10,D18))=0),3,99)} -> 99 | U18: {=IF(AND(I18=0,4>B18,(COUNTIFS(Suizo!$C$5:$C$10,D18,Suizo!$H$5:$H$10,INDEX($G$3:$G$14,4))+COUNTIFS(Suizo!$C$5:$C$10,INDEX($G$3:$G$14,4),Suizo!$H$5:$H$10,D18))=0),4,99)} -> 4 | V18: {=IF(AND(J18=0,5>B18,(COUNTIFS(Suizo!$C$5:$C$10,D18,Suizo!$H$5:$H$10,INDEX($G$3:$G$14,5))+COUNTIFS(Suizo!$C$5:$C$10,INDEX($G$3:$G$14,5),Suizo!$H$5:$H$10,D18))=0),5,99)} -> 5 | W18: {=IF(AND(K18=0,6>B18,(COUNTIFS(Suizo!$C$5:$C$10,D18,Suizo!$H$5:$H$10,INDEX($G$3:$G$14,6))+COUNTIFS(Suizo!$C$5:$C$10,INDEX($G$3:$G$14,6),Suizo!$H$5:$H$10,D18))=0),6,99)} -> 6 | X18: {=IF(AND(L18=0,7>B18,(COUNTIFS(Suizo!$C$5:$C$10,D18,Suizo!$H$5:$H$10,INDEX($G$3:$G$14,7))+COUNTIFS(Suizo!$C$5:$C$10,INDEX($G$3:$G$14,7),Suizo!$H$5:$H$10,D18))=0),7,99)} -> 7 | Y18: {=IF(AND(M18=0,8>B18,(COUNTIFS(Suizo!$C$5:$C$10,D18,Suizo!$H$5:$H$10,INDEX($G$3:$G$14,8))+COUNTIFS(Suizo!$C$5:$C$10,INDEX($G$3:$G$14,8),Suizo!$H$5:$H$10,D18))=0),8,99)} -> 8 | Z18: {=IF(AND(N18=0,9>B18,(COUNTIFS(Suizo!$C$5:$C$10,D18,Suizo!$H$5:$H$10,INDEX($G$3:$G$14,9))+COUNTIFS(Suizo!$C$5:$C$10,INDEX($G$3:$G$14,9),Suizo!$H$5:$H$10,D18))=0),9,99)} -> 9 | AA18: {=IF(AND(O18=0,10>B18,(COUNTIFS(Suizo!$C$5:$C$10,D18,Suizo!$H$5:$H$10,INDEX($G$3:$G$14,10))+COUNTIFS(Suizo!$C$5:$C$10,INDEX($G$3:$G$14,10),Suizo!$H$5:$H$10,D18))=0),10,99)} -> 99 | AB18: {=IF(AND(P18=0,11>B18,(COUNTIFS(Suizo!$C$5:$C$10,D18,Suizo!$H$5:$H$10,INDEX($G$3:$G$14,11))+COUNTIFS(Suizo!$C$5:$C$10,INDEX($G$3:$G$14,11),Suizo!$H$5:$H$10,D18))=0),11,99)} -> 11 | AC18: {=IF(AND(Q18=0,12>B18,(COUNTIFS(Suizo!$C$5:$C$10,D18,Suizo!$H$5:$H$10,INDEX($G$3:$G$14,12))+COUNTIFS(Suizo!$C$5:$C$10,INDEX($G$3:$G$14,12),Suizo!$H$5:$H$10,D18))=0),12,99)} -> 12 | AD18: =IF(AND(F18=0,1>B18),1,99) -> 99 | AE18: =IF(AND(G18=0,2>B18),2,99) -> 99 | AF18: =IF(AND(H18=0,3>B18),3,99) -> 99 | AG18: =IF(AND(I18=0,4>B18),4,99) -> 4 | AH18: =IF(AND(J18=0,5>B18),5,99) -> 5 | AI18: =IF(AND(K18=0,6>B18),6,99) -> 6 | AJ18: =IF(AND(L18=0,7>B18),7,99) -> 7 | AK18: =IF(AND(M18=0,8>B18),8,99) -> 8 | AL18: =IF(AND(N18=0,9>B18),9,99) -> 9 | AM18: =IF(AND(O18=0,10>B18),10,99) -> 10 | AN18: =IF(AND(P18=0,11>B18),11,99) -> 11 | AO18: =IF(AND(Q18=0,12>B18),12,99) -> 12 | AP18: =IF(MIN(R18:AC18)=99,"REVANCHA","")
A19: 3 | B19: =MATCH(0,F19:Q19,0) -> 5 | C19: =IF(MIN(R19:AC19)<99,MIN(R19:AC19),MIN(AD19:AO19)) -> 6 | D19: =INDEX($G$3:$G$14,B19) -> 9 | E19: =INDEX($G$3:$G$14,C19) -> 12 | F19: =IF(OR(F18=1,B18=1,C18=1),1,0) -> 1 | G19: =IF(OR(G18=1,B18=2,C18=2),1,0) -> 1 | H19: =IF(OR(H18=1,B18=3,C18=3),1,0) -> 1 | I19: =IF(OR(I18=1,B18=4,C18=4),1,0) -> 1 | J19: =IF(OR(J18=1,B18=5,C18=5),1,0) -> 0 | K19: =IF(OR(K18=1,B18=6,C18=6),1,0) -> 0 | L19: =IF(OR(L18=1,B18=7,C18=7),1,0) -> 0 | M19: =IF(OR(M18=1,B18=8,C18=8),1,0) -> 0 | N19: =IF(OR(N18=1,B18=9,C18=9),1,0) -> 0 | O19: =IF(OR(O18=1,B18=10,C18=10),1,0) -> 0 | P19: =IF(OR(P18=1,B18=11,C18=11),1,0) -> 0 | Q19: =IF(OR(Q18=1,B18=12,C18=12),1,0) -> 0 | R19: {=IF(AND(F19=0,1>B19,(COUNTIFS(Suizo!$C$5:$C$10,D19,Suizo!$H$5:$H$10,INDEX($G$3:$G$14,1))+COUNTIFS(Suizo!$C$5:$C$10,INDEX($G$3:$G$14,1),Suizo!$H$5:$H$10,D19))=0),1,99)} -> 99 | S19: {=IF(AND(G19=0,2>B19,(COUNTIFS(Suizo!$C$5:$C$10,D19,Suizo!$H$5:$H$10,INDEX($G$3:$G$14,2))+COUNTIFS(Suizo!$C$5:$C$10,INDEX($G$3:$G$14,2),Suizo!$H$5:$H$10,D19))=0),2,99)} -> 99 | T19: {=IF(AND(H19=0,3>B19,(COUNTIFS(Suizo!$C$5:$C$10,D19,Suizo!$H$5:$H$10,INDEX($G$3:$G$14,3))+COUNTIFS(Suizo!$C$5:$C$10,INDEX($G$3:$G$14,3),Suizo!$H$5:$H$10,D19))=0),3,99)} -> 99 | U19: {=IF(AND(I19=0,4>B19,(COUNTIFS(Suizo!$C$5:$C$10,D19,Suizo!$H$5:$H$10,INDEX($G$3:$G$14,4))+COUNTIFS(Suizo!$C$5:$C$10,INDEX($G$3:$G$14,4),Suizo!$H$5:$H$10,D19))=0),4,99)} -> 99 | V19: {=IF(AND(J19=0,5>B19,(COUNTIFS(Suizo!$C$5:$C$10,D19,Suizo!$H$5:$H$10,INDEX($G$3:$G$14,5))+COUNTIFS(Suizo!$C$5:$C$10,INDEX($G$3:$G$14,5),Suizo!$H$5:$H$10,D19))=0),5,99)} -> 99 | W19: {=IF(AND(K19=0,6>B19,(COUNTIFS(Suizo!$C$5:$C$10,D19,Suizo!$H$5:$H$10,INDEX($G$3:$G$14,6))+COUNTIFS(Suizo!$C$5:$C$10,INDEX($G$3:$G$14,6),Suizo!$H$5:$H$10,D19))=0),6,99)} -> 6 | X19: {=IF(AND(L19=0,7>B19,(COUNTIFS(Suizo!$C$5:$C$10,D19,Suizo!$H$5:$H$10,INDEX($G$3:$G$14,7))+COUNTIFS(Suizo!$C$5:$C$10,INDEX($G$3:$G$14,7),Suizo!$H$5:$H$10,D19))=0),7,99)} -> 7 | Y19: {=IF(AND(M19=0,8>B19,(COUNTIFS(Suizo!$C$5:$C$10,D19,Suizo!$H$5:$H$10,INDEX($G$3:$G$14,8))+COUNTIFS(Suizo!$C$5:$C$10,INDEX($G$3:$G$14,8),Suizo!$H$5:$H$10,D19))=0),8,99)} -> 8 | Z19: {=IF(AND(N19=0,9>B19,(COUNTIFS(Suizo!$C$5:$C$10,D19,Suizo!$H$5:$H$10,INDEX($G$3:$G$14,9))+COUNTIFS(Suizo!$C$5:$C$10,INDEX($G$3:$G$14,9),Suizo!$H$5:$H$10,D19))=0),9,99)} -> 99 | AA19: {=IF(AND(O19=0,10>B19,(COUNTIFS(Suizo!$C$5:$C$10,D19,Suizo!$H$5:$H$10,INDEX($G$3:$G$14,10))+COUNTIFS(Suizo!$C$5:$C$10,INDEX($G$3:$G$14,10),Suizo!$H$5:$H$10,D19))=0),10,99)} -> 10 | AB19: {=IF(AND(P19=0,11>B19,(COUNTIFS(Suizo!$C$5:$C$10,D19,Suizo!$H$5:$H$10,INDEX($G$3:$G$14,11))+COUNTIFS(Suizo!$C$5:$C$10,INDEX($G$3:$G$14,11),Suizo!$H$5:$H$10,D19))=0),11,99)} -> 11 | AC19: {=IF(AND(Q19=0,12>B19,(COUNTIFS(Suizo!$C$5:$C$10,D19,Suizo!$H$5:$H$10,INDEX($G$3:$G$14,12))+COUNTIFS(Suizo!$C$5:$C$10,INDEX($G$3:$G$14,12),Suizo!$H$5:$H$10,D19))=0),12,99)} -> 12 | AD19: =IF(AND(F19=0,1>B19),1,99) -> 99 | AE19: =IF(AND(G19=0,2>B19),2,99) -> 99 | AF19: =IF(AND(H19=0,3>B19),3,99) -> 99 | AG19: =IF(AND(I19=0,4>B19),4,99) -> 99 | AH19: =IF(AND(J19=0,5>B19),5,99) -> 99 | AI19: =IF(AND(K19=0,6>B19),6,99) -> 6 | AJ19: =IF(AND(L19=0,7>B19),7,99) -> 7 | AK19: =IF(AND(M19=0,8>B19),8,99) -> 8 | AL19: =IF(AND(N19=0,9>B19),9,99) -> 9 | AM19: =IF(AND(O19=0,10>B19),10,99) -> 10 | AN19: =IF(AND(P19=0,11>B19),11,99) -> 11 | AO19: =IF(AND(Q19=0,12>B19),12,99) -> 12 | AP19: =IF(MIN(R19:AC19)=99,"REVANCHA","")
A20: 4 | B20: =MATCH(0,F20:Q20,0) -> 7 | C20: =IF(MIN(R20:AC20)<99,MIN(R20:AC20),MIN(AD20:AO20)) -> 8 | D20: =INDEX($G$3:$G$14,B20) -> 3 | E20: =INDEX($G$3:$G$14,C20) -> 8 | F20: =IF(OR(F19=1,B19=1,C19=1),1,0) -> 1 | G20: =IF(OR(G19=1,B19=2,C19=2),1,0) -> 1 | H20: =IF(OR(H19=1,B19=3,C19=3),1,0) -> 1 | I20: =IF(OR(I19=1,B19=4,C19=4),1,0) -> 1 | J20: =IF(OR(J19=1,B19=5,C19=5),1,0) -> 1 | K20: =IF(OR(K19=1,B19=6,C19=6),1,0) -> 1 | L20: =IF(OR(L19=1,B19=7,C19=7),1,0) -> 0 | M20: =IF(OR(M19=1,B19=8,C19=8),1,0) -> 0 | N20: =IF(OR(N19=1,B19=9,C19=9),1,0) -> 0 | O20: =IF(OR(O19=1,B19=10,C19=10),1,0) -> 0 | P20: =IF(OR(P19=1,B19=11,C19=11),1,0) -> 0 | Q20: =IF(OR(Q19=1,B19=12,C19=12),1,0) -> 0 | R20: {=IF(AND(F20=0,1>B20,(COUNTIFS(Suizo!$C$5:$C$10,D20,Suizo!$H$5:$H$10,INDEX($G$3:$G$14,1))+COUNTIFS(Suizo!$C$5:$C$10,INDEX($G$3:$G$14,1),Suizo!$H$5:$H$10,D20))=0),1,99)} -> 99 | S20: {=IF(AND(G20=0,2>B20,(COUNTIFS(Suizo!$C$5:$C$10,D20,Suizo!$H$5:$H$10,INDEX($G$3:$G$14,2))+COUNTIFS(Suizo!$C$5:$C$10,INDEX($G$3:$G$14,2),Suizo!$H$5:$H$10,D20))=0),2,99)} -> 99 | T20: {=IF(AND(H20=0,3>B20,(COUNTIFS(Suizo!$C$5:$C$10,D20,Suizo!$H$5:$H$10,INDEX($G$3:$G$14,3))+COUNTIFS(Suizo!$C$5:$C$10,INDEX($G$3:$G$14,3),Suizo!$H$5:$H$10,D20))=0),3,99)} -> 99 | U20: {=IF(AND(I20=0,4>B20,(COUNTIFS(Suizo!$C$5:$C$10,D20,Suizo!$H$5:$H$10,INDEX($G$3:$G$14,4))+COUNTIFS(Suizo!$C$5:$C$10,INDEX($G$3:$G$14,4),Suizo!$H$5:$H$10,D20))=0),4,99)} -> 99 | V20: {=IF(AND(J20=0,5>B20,(COUNTIFS(Suizo!$C$5:$C$10,D20,Suizo!$H$5:$H$10,INDEX($G$3:$G$14,5))+COUNTIFS(Suizo!$C$5:$C$10,INDEX($G$3:$G$14,5),Suizo!$H$5:$H$10,D20))=0),5,99)} -> 99 | W20: {=IF(AND(K20=0,6>B20,(COUNTIFS(Suizo!$C$5:$C$10,D20,Suizo!$H$5:$H$10,INDEX($G$3:$G$14,6))+COUNTIFS(Suizo!$C$5:$C$10,INDEX($G$3:$G$14,6),Suizo!$H$5:$H$10,D20))=0),6,99)} -> 99 | X20: {=IF(AND(L20=0,7>B20,(COUNTIFS(Suizo!$C$5:$C$10,D20,Suizo!$H$5:$H$10,INDEX($G$3:$G$14,7))+COUNTIFS(Suizo!$C$5:$C$10,INDEX($G$3:$G$14,7),Suizo!$H$5:$H$10,D20))=0),7,99)} -> 99 | Y20: {=IF(AND(M20=0,8>B20,(COUNTIFS(Suizo!$C$5:$C$10,D20,Suizo!$H$5:$H$10,INDEX($G$3:$G$14,8))+COUNTIFS(Suizo!$C$5:$C$10,INDEX($G$3:$G$14,8),Suizo!$H$5:$H$10,D20))=0),8,99)} -> 8 | Z20: {=IF(AND(N20=0,9>B20,(COUNTIFS(Suizo!$C$5:$C$10,D20,Suizo!$H$5:$H$10,INDEX($G$3:$G$14,9))+COUNTIFS(Suizo!$C$5:$C$10,INDEX($G$3:$G$14,9),Suizo!$H$5:$H$10,D20))=0),9,99)} -> 9 | AA20: {=IF(AND(O20=0,10>B20,(COUNTIFS(Suizo!$C$5:$C$10,D20,Suizo!$H$5:$H$10,INDEX($G$3:$G$14,10))+COUNTIFS(Suizo!$C$5:$C$10,INDEX($G$3:$G$14,10),Suizo!$H$5:$H$10,D20))=0),10,99)} -> 10 | AB20: {=IF(AND(P20=0,11>B20,(COUNTIFS(Suizo!$C$5:$C$10,D20,Suizo!$H$5:$H$10,INDEX($G$3:$G$14,11))+COUNTIFS(Suizo!$C$5:$C$10,INDEX($G$3:$G$14,11),Suizo!$H$5:$H$10,D20))=0),11,99)} -> 11 | AC20: {=IF(AND(Q20=0,12>B20,(COUNTIFS(Suizo!$C$5:$C$10,D20,Suizo!$H$5:$H$10,INDEX($G$3:$G$14,12))+COUNTIFS(Suizo!$C$5:$C$10,INDEX($G$3:$G$14,12),Suizo!$H$5:$H$10,D20))=0),12,99)} -> 12 | AD20: =IF(AND(F20=0,1>B20),1,99) -> 99 | AE20: =IF(AND(G20=0,2>B20),2,99) -> 99 | AF20: =IF(AND(H20=0,3>B20),3,99) -> 99 | AG20: =IF(AND(I20=0,4>B20),4,99) -> 99 | AH20: =IF(AND(J20=0,5>B20),5,99) -> 99 | AI20: =IF(AND(K20=0,6>B20),6,99) -> 99 | AJ20: =IF(AND(L20=0,7>B20),7,99) -> 99 | AK20: =IF(AND(M20=0,8>B20),8,99) -> 8 | AL20: =IF(AND(N20=0,9>B20),9,99) -> 9 | AM20: =IF(AND(O20=0,10>B20),10,99) -> 10 | AN20: =IF(AND(P20=0,11>B20),11,99) -> 11 | AO20: =IF(AND(Q20=0,12>B20),12,99) -> 12 | AP20: =IF(MIN(R20:AC20)=99,"REVANCHA","")
A21: 5 | B21: =MATCH(0,F21:Q21,0) -> 9 | C21: =IF(MIN(R21:AC21)<99,MIN(R21:AC21),MIN(AD21:AO21)) -> 10 | D21: =INDEX($G$3:$G$14,B21) -> 10 | E21: =INDEX($G$3:$G$14,C21) -> 7 | F21: =IF(OR(F20=1,B20=1,C20=1),1,0) -> 1 | G21: =IF(OR(G20=1,B20=2,C20=2),1,0) -> 1 | H21: =IF(OR(H20=1,B20=3,C20=3),1,0) -> 1 | I21: =IF(OR(I20=1,B20=4,C20=4),1,0) -> 1 | J21: =IF(OR(J20=1,B20=5,C20=5),1,0) -> 1 | K21: =IF(OR(K20=1,B20=6,C20=6),1,0) -> 1 | L21: =IF(OR(L20=1,B20=7,C20=7),1,0) -> 1 | M21: =IF(OR(M20=1,B20=8,C20=8),1,0) -> 1 | N21: =IF(OR(N20=1,B20=9,C20=9),1,0) -> 0 | O21: =IF(OR(O20=1,B20=10,C20=10),1,0) -> 0 | P21: =IF(OR(P20=1,B20=11,C20=11),1,0) -> 0 | Q21: =IF(OR(Q20=1,B20=12,C20=12),1,0) -> 0 | R21: {=IF(AND(F21=0,1>B21,(COUNTIFS(Suizo!$C$5:$C$10,D21,Suizo!$H$5:$H$10,INDEX($G$3:$G$14,1))+COUNTIFS(Suizo!$C$5:$C$10,INDEX($G$3:$G$14,1),Suizo!$H$5:$H$10,D21))=0),1,99)} -> 99 | S21: {=IF(AND(G21=0,2>B21,(COUNTIFS(Suizo!$C$5:$C$10,D21,Suizo!$H$5:$H$10,INDEX($G$3:$G$14,2))+COUNTIFS(Suizo!$C$5:$C$10,INDEX($G$3:$G$14,2),Suizo!$H$5:$H$10,D21))=0),2,99)} -> 99 | T21: {=IF(AND(H21=0,3>B21,(COUNTIFS(Suizo!$C$5:$C$10,D21,Suizo!$H$5:$H$10,INDEX($G$3:$G$14,3))+COUNTIFS(Suizo!$C$5:$C$10,INDEX($G$3:$G$14,3),Suizo!$H$5:$H$10,D21))=0),3,99)} -> 99 | U21: {=IF(AND(I21=0,4>B21,(COUNTIFS(Suizo!$C$5:$C$10,D21,Suizo!$H$5:$H$10,INDEX($G$3:$G$14,4))+COUNTIFS(Suizo!$C$5:$C$10,INDEX($G$3:$G$14,4),Suizo!$H$5:$H$10,D21))=0),4,99)} -> 99 | V21: {=IF(AND(J21=0,5>B21,(COUNTIFS(Suizo!$C$5:$C$10,D21,Suizo!$H$5:$H$10,INDEX($G$3:$G$14,5))+COUNTIFS(Suizo!$C$5:$C$10,INDEX($G$3:$G$14,5),Suizo!$H$5:$H$10,D21))=0),5,99)} -> 99 | W21: {=IF(AND(K21=0,6>B21,(COUNTIFS(Suizo!$C$5:$C$10,D21,Suizo!$H$5:$H$10,INDEX($G$3:$G$14,6))+COUNTIFS(Suizo!$C$5:$C$10,INDEX($G$3:$G$14,6),Suizo!$H$5:$H$10,D21))=0),6,99)} -> 99 | X21: {=IF(AND(L21=0,7>B21,(COUNTIFS(Suizo!$C$5:$C$10,D21,Suizo!$H$5:$H$10,INDEX($G$3:$G$14,7))+COUNTIFS(Suizo!$C$5:$C$10,INDEX($G$3:$G$14,7),Suizo!$H$5:$H$10,D21))=0),7,99)} -> 99 | Y21: {=IF(AND(M21=0,8>B21,(COUNTIFS(Suizo!$C$5:$C$10,D21,Suizo!$H$5:$H$10,INDEX($G$3:$G$14,8))+COUNTIFS(Suizo!$C$5:$C$10,INDEX($G$3:$G$14,8),Suizo!$H$5:$H$10,D21))=0),8,99)} -> 99 | Z21: {=IF(AND(N21=0,9>B21,(COUNTIFS(Suizo!$C$5:$C$10,D21,Suizo!$H$5:$H$10,INDEX($G$3:$G$14,9))+COUNTIFS(Suizo!$C$5:$C$10,INDEX($G$3:$G$14,9),Suizo!$H$5:$H$10,D21))=0),9,99)} -> 99 | AA21: {=IF(AND(O21=0,10>B21,(COUNTIFS(Suizo!$C$5:$C$10,D21,Suizo!$H$5:$H$10,INDEX($G$3:$G$14,10))+COUNTIFS(Suizo!$C$5:$C$10,INDEX($G$3:$G$14,10),Suizo!$H$5:$H$10,D21))=0),10,99)} -> 10 | AB21: {=IF(AND(P21=0,11>B21,(COUNTIFS(Suizo!$C$5:$C$10,D21,Suizo!$H$5:$H$10,INDEX($G$3:$G$14,11))+COUNTIFS(Suizo!$C$5:$C$10,INDEX($G$3:$G$14,11),Suizo!$H$5:$H$10,D21))=0),11,99)} -> 11 | AC21: {=IF(AND(Q21=0,12>B21,(COUNTIFS(Suizo!$C$5:$C$10,D21,Suizo!$H$5:$H$10,INDEX($G$3:$G$14,12))+COUNTIFS(Suizo!$C$5:$C$10,INDEX($G$3:$G$14,12),Suizo!$H$5:$H$10,D21))=0),12,99)} -> 12 | AD21: =IF(AND(F21=0,1>B21),1,99) -> 99 | AE21: =IF(AND(G21=0,2>B21),2,99) -> 99 | AF21: =IF(AND(H21=0,3>B21),3,99) -> 99 | AG21: =IF(AND(I21=0,4>B21),4,99) -> 99 | AH21: =IF(AND(J21=0,5>B21),5,99) -> 99 | AI21: =IF(AND(K21=0,6>B21),6,99) -> 99 | AJ21: =IF(AND(L21=0,7>B21),7,99) -> 99 | AK21: =IF(AND(M21=0,8>B21),8,99) -> 99 | AL21: =IF(AND(N21=0,9>B21),9,99) -> 99 | AM21: =IF(AND(O21=0,10>B21),10,99) -> 10 | AN21: =IF(AND(P21=0,11>B21),11,99) -> 11 | AO21: =IF(AND(Q21=0,12>B21),12,99) -> 12 | AP21: =IF(MIN(R21:AC21)=99,"REVANCHA","")
A22: 6 | B22: =MATCH(0,F22:Q22,0) -> 11 | C22: =IF(MIN(R22:AC22)<99,MIN(R22:AC22),MIN(AD22:AO22)) -> 12 | D22: =INDEX($G$3:$G$14,B22) -> 11 | E22: =INDEX($G$3:$G$14,C22) -> 6 | F22: =IF(OR(F21=1,B21=1,C21=1),1,0) -> 1 | G22: =IF(OR(G21=1,B21=2,C21=2),1,0) -> 1 | H22: =IF(OR(H21=1,B21=3,C21=3),1,0) -> 1 | I22: =IF(OR(I21=1,B21=4,C21=4),1,0) -> 1 | J22: =IF(OR(J21=1,B21=5,C21=5),1,0) -> 1 | K22: =IF(OR(K21=1,B21=6,C21=6),1,0) -> 1 | L22: =IF(OR(L21=1,B21=7,C21=7),1,0) -> 1 | M22: =IF(OR(M21=1,B21=8,C21=8),1,0) -> 1 | N22: =IF(OR(N21=1,B21=9,C21=9),1,0) -> 1 | O22: =IF(OR(O21=1,B21=10,C21=10),1,0) -> 1 | P22: =IF(OR(P21=1,B21=11,C21=11),1,0) -> 0 | Q22: =IF(OR(Q21=1,B21=12,C21=12),1,0) -> 0 | R22: {=IF(AND(F22=0,1>B22,(COUNTIFS(Suizo!$C$5:$C$10,D22,Suizo!$H$5:$H$10,INDEX($G$3:$G$14,1))+COUNTIFS(Suizo!$C$5:$C$10,INDEX($G$3:$G$14,1),Suizo!$H$5:$H$10,D22))=0),1,99)} -> 99 | S22: {=IF(AND(G22=0,2>B22,(COUNTIFS(Suizo!$C$5:$C$10,D22,Suizo!$H$5:$H$10,INDEX($G$3:$G$14,2))+COUNTIFS(Suizo!$C$5:$C$10,INDEX($G$3:$G$14,2),Suizo!$H$5:$H$10,D22))=0),2,99)} -> 99 | T22: {=IF(AND(H22=0,3>B22,(COUNTIFS(Suizo!$C$5:$C$10,D22,Suizo!$H$5:$H$10,INDEX($G$3:$G$14,3))+COUNTIFS(Suizo!$C$5:$C$10,INDEX($G$3:$G$14,3),Suizo!$H$5:$H$10,D22))=0),3,99)} -> 99 | U22: {=IF(AND(I22=0,4>B22,(COUNTIFS(Suizo!$C$5:$C$10,D22,Suizo!$H$5:$H$10,INDEX($G$3:$G$14,4))+COUNTIFS(Suizo!$C$5:$C$10,INDEX($G$3:$G$14,4),Suizo!$H$5:$H$10,D22))=0),4,99)} -> 99 | V22: {=IF(AND(J22=0,5>B22,(COUNTIFS(Suizo!$C$5:$C$10,D22,Suizo!$H$5:$H$10,INDEX($G$3:$G$14,5))+COUNTIFS(Suizo!$C$5:$C$10,INDEX($G$3:$G$14,5),Suizo!$H$5:$H$10,D22))=0),5,99)} -> 99 | W22: {=IF(AND(K22=0,6>B22,(COUNTIFS(Suizo!$C$5:$C$10,D22,Suizo!$H$5:$H$10,INDEX($G$3:$G$14,6))+COUNTIFS(Suizo!$C$5:$C$10,INDEX($G$3:$G$14,6),Suizo!$H$5:$H$10,D22))=0),6,99)} -> 99 | X22: {=IF(AND(L22=0,7>B22,(COUNTIFS(Suizo!$C$5:$C$10,D22,Suizo!$H$5:$H$10,INDEX($G$3:$G$14,7))+COUNTIFS(Suizo!$C$5:$C$10,INDEX($G$3:$G$14,7),Suizo!$H$5:$H$10,D22))=0),7,99)} -> 99 | Y22: {=IF(AND(M22=0,8>B22,(COUNTIFS(Suizo!$C$5:$C$10,D22,Suizo!$H$5:$H$10,INDEX($G$3:$G$14,8))+COUNTIFS(Suizo!$C$5:$C$10,INDEX($G$3:$G$14,8),Suizo!$H$5:$H$10,D22))=0),8,99)} -> 99 | Z22: {=IF(AND(N22=0,9>B22,(COUNTIFS(Suizo!$C$5:$C$10,D22,Suizo!$H$5:$H$10,INDEX($G$3:$G$14,9))+COUNTIFS(Suizo!$C$5:$C$10,INDEX($G$3:$G$14,9),Suizo!$H$5:$H$10,D22))=0),9,99)} -> 99 | AA22: {=IF(AND(O22=0,10>B22,(COUNTIFS(Suizo!$C$5:$C$10,D22,Suizo!$H$5:$H$10,INDEX($G$3:$G$14,10))+COUNTIFS(Suizo!$C$5:$C$10,INDEX($G$3:$G$14,10),Suizo!$H$5:$H$10,D22))=0),10,99)} -> 99 | AB22: {=IF(AND(P22=0,11>B22,(COUNTIFS(Suizo!$C$5:$C$10,D22,Suizo!$H$5:$H$10,INDEX($G$3:$G$14,11))+COUNTIFS(Suizo!$C$5:$C$10,INDEX($G$3:$G$14,11),Suizo!$H$5:$H$10,D22))=0),11,99)} -> 99 | AC22: {=IF(AND(Q22=0,12>B22,(COUNTIFS(Suizo!$C$5:$C$10,D22,Suizo!$H$5:$H$10,INDEX($G$3:$G$14,12))+COUNTIFS(Suizo!$C$5:$C$10,INDEX($G$3:$G$14,12),Suizo!$H$5:$H$10,D22))=0),12,99)} -> 12 | AD22: =IF(AND(F22=0,1>B22),1,99) -> 99 | AE22: =IF(AND(G22=0,2>B22),2,99) -> 99 | AF22: =IF(AND(H22=0,3>B22),3,99) -> 99 | AG22: =IF(AND(I22=0,4>B22),4,99) -> 99 | AH22: =IF(AND(J22=0,5>B22),5,99) -> 99 | AI22: =IF(AND(K22=0,6>B22),6,99) -> 99 | AJ22: =IF(AND(L22=0,7>B22),7,99) -> 99 | AK22: =IF(AND(M22=0,8>B22),8,99) -> 99 | AL22: =IF(AND(N22=0,9>B22),9,99) -> 99 | AM22: =IF(AND(O22=0,10>B22),10,99) -> 99 | AN22: =IF(AND(P22=0,11>B22),11,99) -> 99 | AO22: =IF(AND(Q22=0,12>B22),12,99) -> 12 | AP22: =IF(MIN(R22:AC22)=99,"REVANCHA","")
A30: Ronda 3 | C30: lista | D30: =IF(COUNTIF(Suizo!$K$5:$K$16,">0")=12,1,0) -> 1
A31: ID | B31: PG | C31: Dif | D31: RF | E31: Clave | F31: Pos | G31: ID en pos
A32: 1 | B32: =COUNTIF(Suizo!$K$5:$K$16,A32) -> 2 | C32: =(SUMIFS(Suizo!$E$5:$E$16,Suizo!$C$5:$C$16,A32,Suizo!$K$5:$K$16,">0")+SUMIFS(Suizo!$F$5:$F$16,Suizo!$H$5:$H$16,A32,Suizo!$K$5:$K$16,">0"))-(SUMIFS(Suizo!$F$5:$F$16,Suizo!$C$5:$C$16,A32,Suizo!$K$5:$K$16,">0")+SUMIFS(Suizo!$E$5:$E$16,Suizo!$H$5:$H$16,A32,Suizo!$K$5:$K$16,">0")) -> 13 | D32: =(SUMIFS(Suizo!$E$5:$E$16,Suizo!$C$5:$C$16,A32,Suizo!$K$5:$K$16,">0")+SUMIFS(Suizo!$F$5:$F$16,Suizo!$H$5:$H$16,A32,Suizo!$K$5:$K$16,">0")) -> 18 | E32: =B32*100000000+(C32+500)*100000+D32*100-A32 -> 251301799 | F32: 1 | G32: =INDEX($A$32:$A$43,MATCH(LARGE($E$32:$E$43,F32),$E$32:$E$43,0)) -> 1
A33: 2 | B33: =COUNTIF(Suizo!$K$5:$K$16,A33) -> 1 | C33: =(SUMIFS(Suizo!$E$5:$E$16,Suizo!$C$5:$C$16,A33,Suizo!$K$5:$K$16,">0")+SUMIFS(Suizo!$F$5:$F$16,Suizo!$H$5:$H$16,A33,Suizo!$K$5:$K$16,">0"))-(SUMIFS(Suizo!$F$5:$F$16,Suizo!$C$5:$C$16,A33,Suizo!$K$5:$K$16,">0")+SUMIFS(Suizo!$E$5:$E$16,Suizo!$H$5:$H$16,A33,Suizo!$K$5:$K$16,">0")) -> 2 | D33: =(SUMIFS(Suizo!$E$5:$E$16,Suizo!$C$5:$C$16,A33,Suizo!$K$5:$K$16,">0")+SUMIFS(Suizo!$F$5:$F$16,Suizo!$H$5:$H$16,A33,Suizo!$K$5:$K$16,">0")) -> 12 | E33: =B33*100000000+(C33+500)*100000+D33*100-A33 -> 150201198 | F33: 2 | G33: =INDEX($A$32:$A$43,MATCH(LARGE($E$32:$E$43,F33),$E$32:$E$43,0)) -> 5
A34: 3 | B34: =COUNTIF(Suizo!$K$5:$K$16,A34) -> 1 | C34: =(SUMIFS(Suizo!$E$5:$E$16,Suizo!$C$5:$C$16,A34,Suizo!$K$5:$K$16,">0")+SUMIFS(Suizo!$F$5:$F$16,Suizo!$H$5:$H$16,A34,Suizo!$K$5:$K$16,">0"))-(SUMIFS(Suizo!$F$5:$F$16,Suizo!$C$5:$C$16,A34,Suizo!$K$5:$K$16,">0")+SUMIFS(Suizo!$E$5:$E$16,Suizo!$H$5:$H$16,A34,Suizo!$K$5:$K$16,">0")) -> 5 | D34: =(SUMIFS(Suizo!$E$5:$E$16,Suizo!$C$5:$C$16,A34,Suizo!$K$5:$K$16,">0")+SUMIFS(Suizo!$F$5:$F$16,Suizo!$H$5:$H$16,A34,Suizo!$K$5:$K$16,">0")) -> 16 | E34: =B34*100000000+(C34+500)*100000+D34*100-A34 -> 150501597 | F34: 3 | G34: =INDEX($A$32:$A$43,MATCH(LARGE($E$32:$E$43,F34),$E$32:$E$43,0)) -> 9
A35: 4 | B35: =COUNTIF(Suizo!$K$5:$K$16,A35) -> 1 | C35: =(SUMIFS(Suizo!$E$5:$E$16,Suizo!$C$5:$C$16,A35,Suizo!$K$5:$K$16,">0")+SUMIFS(Suizo!$F$5:$F$16,Suizo!$H$5:$H$16,A35,Suizo!$K$5:$K$16,">0"))-(SUMIFS(Suizo!$F$5:$F$16,Suizo!$C$5:$C$16,A35,Suizo!$K$5:$K$16,">0")+SUMIFS(Suizo!$E$5:$E$16,Suizo!$H$5:$H$16,A35,Suizo!$K$5:$K$16,">0")) -> -6 | D35: =(SUMIFS(Suizo!$E$5:$E$16,Suizo!$C$5:$C$16,A35,Suizo!$K$5:$K$16,">0")+SUMIFS(Suizo!$F$5:$F$16,Suizo!$H$5:$H$16,A35,Suizo!$K$5:$K$16,">0")) -> 10 | E35: =B35*100000000+(C35+500)*100000+D35*100-A35 -> 149400996 | F35: 4 | G35: =INDEX($A$32:$A$43,MATCH(LARGE($E$32:$E$43,F35),$E$32:$E$43,0)) -> 3
A36: 5 | B36: =COUNTIF(Suizo!$K$5:$K$16,A36) -> 2 | C36: =(SUMIFS(Suizo!$E$5:$E$16,Suizo!$C$5:$C$16,A36,Suizo!$K$5:$K$16,">0")+SUMIFS(Suizo!$F$5:$F$16,Suizo!$H$5:$H$16,A36,Suizo!$K$5:$K$16,">0"))-(SUMIFS(Suizo!$F$5:$F$16,Suizo!$C$5:$C$16,A36,Suizo!$K$5:$K$16,">0")+SUMIFS(Suizo!$E$5:$E$16,Suizo!$H$5:$H$16,A36,Suizo!$K$5:$K$16,">0")) -> 12 | D36: =(SUMIFS(Suizo!$E$5:$E$16,Suizo!$C$5:$C$16,A36,Suizo!$K$5:$K$16,">0")+SUMIFS(Suizo!$F$5:$F$16,Suizo!$H$5:$H$16,A36,Suizo!$K$5:$K$16,">0")) -> 18 | E36: =B36*100000000+(C36+500)*100000+D36*100-A36 -> 251201795 | F36: 5 | G36: =INDEX($A$32:$A$43,MATCH(LARGE($E$32:$E$43,F36),$E$32:$E$43,0)) -> 2
A37: 6 | B37: =COUNTIF(Suizo!$K$5:$K$16,A37) -> 0 | C37: =(SUMIFS(Suizo!$E$5:$E$16,Suizo!$C$5:$C$16,A37,Suizo!$K$5:$K$16,">0")+SUMIFS(Suizo!$F$5:$F$16,Suizo!$H$5:$H$16,A37,Suizo!$K$5:$K$16,">0"))-(SUMIFS(Suizo!$F$5:$F$16,Suizo!$C$5:$C$16,A37,Suizo!$K$5:$K$16,">0")+SUMIFS(Suizo!$E$5:$E$16,Suizo!$H$5:$H$16,A37,Suizo!$K$5:$K$16,">0")) -> -10 | D37: =(SUMIFS(Suizo!$E$5:$E$16,Suizo!$C$5:$C$16,A37,Suizo!$K$5:$K$16,">0")+SUMIFS(Suizo!$F$5:$F$16,Suizo!$H$5:$H$16,A37,Suizo!$K$5:$K$16,">0")) -> 8 | E37: =B37*100000000+(C37+500)*100000+D37*100-A37 -> 49000794 | F37: 6 | G37: =INDEX($A$32:$A$43,MATCH(LARGE($E$32:$E$43,F37),$E$32:$E$43,0)) -> 7
A38: 7 | B38: =COUNTIF(Suizo!$K$5:$K$16,A38) -> 1 | C38: =(SUMIFS(Suizo!$E$5:$E$16,Suizo!$C$5:$C$16,A38,Suizo!$K$5:$K$16,">0")+SUMIFS(Suizo!$F$5:$F$16,Suizo!$H$5:$H$16,A38,Suizo!$K$5:$K$16,">0"))-(SUMIFS(Suizo!$F$5:$F$16,Suizo!$C$5:$C$16,A38,Suizo!$K$5:$K$16,">0")+SUMIFS(Suizo!$E$5:$E$16,Suizo!$H$5:$H$16,A38,Suizo!$K$5:$K$16,">0")) -> -1 | D38: =(SUMIFS(Suizo!$E$5:$E$16,Suizo!$C$5:$C$16,A38,Suizo!$K$5:$K$16,">0")+SUMIFS(Suizo!$F$5:$F$16,Suizo!$H$5:$H$16,A38,Suizo!$K$5:$K$16,">0")) -> 13 | E38: =B38*100000000+(C38+500)*100000+D38*100-A38 -> 149901293 | F38: 7 | G38: =INDEX($A$32:$A$43,MATCH(LARGE($E$32:$E$43,F38),$E$32:$E$43,0)) -> 11
A39: 8 | B39: =COUNTIF(Suizo!$K$5:$K$16,A39) -> 0 | C39: =(SUMIFS(Suizo!$E$5:$E$16,Suizo!$C$5:$C$16,A39,Suizo!$K$5:$K$16,">0")+SUMIFS(Suizo!$F$5:$F$16,Suizo!$H$5:$H$16,A39,Suizo!$K$5:$K$16,">0"))-(SUMIFS(Suizo!$F$5:$F$16,Suizo!$C$5:$C$16,A39,Suizo!$K$5:$K$16,">0")+SUMIFS(Suizo!$E$5:$E$16,Suizo!$H$5:$H$16,A39,Suizo!$K$5:$K$16,">0")) -> -9 | D39: =(SUMIFS(Suizo!$E$5:$E$16,Suizo!$C$5:$C$16,A39,Suizo!$K$5:$K$16,">0")+SUMIFS(Suizo!$F$5:$F$16,Suizo!$H$5:$H$16,A39,Suizo!$K$5:$K$16,">0")) -> 9 | E39: =B39*100000000+(C39+500)*100000+D39*100-A39 -> 49100892 | F39: 8 | G39: =INDEX($A$32:$A$43,MATCH(LARGE($E$32:$E$43,F39),$E$32:$E$43,0)) -> 4
A40: 9 | B40: =COUNTIF(Suizo!$K$5:$K$16,A40) -> 2 | C40: =(SUMIFS(Suizo!$E$5:$E$16,Suizo!$C$5:$C$16,A40,Suizo!$K$5:$K$16,">0")+SUMIFS(Suizo!$F$5:$F$16,Suizo!$H$5:$H$16,A40,Suizo!$K$5:$K$16,">0"))-(SUMIFS(Suizo!$F$5:$F$16,Suizo!$C$5:$C$16,A40,Suizo!$K$5:$K$16,">0")+SUMIFS(Suizo!$E$5:$E$16,Suizo!$H$5:$H$16,A40,Suizo!$K$5:$K$16,">0")) -> 11 | D40: =(SUMIFS(Suizo!$E$5:$E$16,Suizo!$C$5:$C$16,A40,Suizo!$K$5:$K$16,">0")+SUMIFS(Suizo!$F$5:$F$16,Suizo!$H$5:$H$16,A40,Suizo!$K$5:$K$16,">0")) -> 18 | E40: =B40*100000000+(C40+500)*100000+D40*100-A40 -> 251101791 | F40: 9 | G40: =INDEX($A$32:$A$43,MATCH(LARGE($E$32:$E$43,F40),$E$32:$E$43,0)) -> 12
A41: 10 | B41: =COUNTIF(Suizo!$K$5:$K$16,A41) -> 0 | C41: =(SUMIFS(Suizo!$E$5:$E$16,Suizo!$C$5:$C$16,A41,Suizo!$K$5:$K$16,">0")+SUMIFS(Suizo!$F$5:$F$16,Suizo!$H$5:$H$16,A41,Suizo!$K$5:$K$16,">0"))-(SUMIFS(Suizo!$F$5:$F$16,Suizo!$C$5:$C$16,A41,Suizo!$K$5:$K$16,">0")+SUMIFS(Suizo!$E$5:$E$16,Suizo!$H$5:$H$16,A41,Suizo!$K$5:$K$16,">0")) -> -6 | D41: =(SUMIFS(Suizo!$E$5:$E$16,Suizo!$C$5:$C$16,A41,Suizo!$K$5:$K$16,">0")+SUMIFS(Suizo!$F$5:$F$16,Suizo!$H$5:$H$16,A41,Suizo!$K$5:$K$16,">0")) -> 12 | E41: =B41*100000000+(C41+500)*100000+D41*100-A41 -> 49401190 | F41: 10 | G41: =INDEX($A$32:$A$43,MATCH(LARGE($E$32:$E$43,F41),$E$32:$E$43,0)) -> 10
A42: 11 | B42: =COUNTIF(Suizo!$K$5:$K$16,A42) -> 1 | C42: =(SUMIFS(Suizo!$E$5:$E$16,Suizo!$C$5:$C$16,A42,Suizo!$K$5:$K$16,">0")+SUMIFS(Suizo!$F$5:$F$16,Suizo!$H$5:$H$16,A42,Suizo!$K$5:$K$16,">0"))-(SUMIFS(Suizo!$F$5:$F$16,Suizo!$C$5:$C$16,A42,Suizo!$K$5:$K$16,">0")+SUMIFS(Suizo!$E$5:$E$16,Suizo!$H$5:$H$16,A42,Suizo!$K$5:$K$16,">0")) -> -4 | D42: =(SUMIFS(Suizo!$E$5:$E$16,Suizo!$C$5:$C$16,A42,Suizo!$K$5:$K$16,">0")+SUMIFS(Suizo!$F$5:$F$16,Suizo!$H$5:$H$16,A42,Suizo!$K$5:$K$16,">0")) -> 12 | E42: =B42*100000000+(C42+500)*100000+D42*100-A42 -> 149601189 | F42: 11 | G42: =INDEX($A$32:$A$43,MATCH(LARGE($E$32:$E$43,F42),$E$32:$E$43,0)) -> 8
A43: 12 | B43: =COUNTIF(Suizo!$K$5:$K$16,A43) -> 1 | C43: =(SUMIFS(Suizo!$E$5:$E$16,Suizo!$C$5:$C$16,A43,Suizo!$K$5:$K$16,">0")+SUMIFS(Suizo!$F$5:$F$16,Suizo!$H$5:$H$16,A43,Suizo!$K$5:$K$16,">0"))-(SUMIFS(Suizo!$F$5:$F$16,Suizo!$C$5:$C$16,A43,Suizo!$K$5:$K$16,">0")+SUMIFS(Suizo!$E$5:$E$16,Suizo!$H$5:$H$16,A43,Suizo!$K$5:$K$16,">0")) -> -7 | D43: =(SUMIFS(Suizo!$E$5:$E$16,Suizo!$C$5:$C$16,A43,Suizo!$K$5:$K$16,">0")+SUMIFS(Suizo!$F$5:$F$16,Suizo!$H$5:$H$16,A43,Suizo!$K$5:$K$16,">0")) -> 9 | E43: =B43*100000000+(C43+500)*100000+D43*100-A43 -> 149300888 | F43: 12 | G43: =INDEX($A$32:$A$43,MATCH(LARGE($E$32:$E$43,F43),$E$32:$E$43,0)) -> 6
A45: Paso | B45: PosA | C45: PosB | D45: ID A | E45: ID B
