Workbook

Sheet Parejas
A1: Coliseo Arena Gamer · CS2 Wingman 2v2
A2: Editá los nombres en amarillo. El ID no se cambia: los partidos usan el ID.
A4: ID | B4: Pareja (nombre corto) | C4: Jugador 1 | D4: Jugador 2
A5: 1 | B5: Cardozo / Cardozo | C5: José Cardozo | D5: Maximiliano Cardozo
A6: 2 | B6: Blas / Agustin | C6: Blas Machado Susseret | D6: Agustin Chioraia
A7: 3 | B7: Diego / (a confirmar) | C7: Diego Villan | D7: (a confirmar)
A8: 4 | B8: Luciano / Gonzalo | C8: Luciano | D8: Gonzalo
A9: 5 | B9: Francisco / Marcos | C9: Francisco | D9: Marcos
A10: 6 | B10: Luciano / Lautaro | C10: Luciano Pua | D10: Lautaro Montes
A11: 7 | B11: Simon / Joaquin | C11: Simon Cerra | D11: Joaquín Mucci
A12: 8 | B12: Rodrigo / Nazareno | C12: Rodrigo Antonino | D12: Nazareno Acosta
A13: 9 | B13: Bautista / Luciano | C13: Bautista Barrera | D13: Luciano Barrera
A14: 10 | B14: Lucas / Martin | C14: Lucas Tissera | D14: Martín Rodríguez
A15: 11 | B15: Agustin / Rodrigo | C15: Agustin Caceres | D15: Rodrigo Dimare
A16: 12 | B16: Enzo / Gonza | C16: Enzo | D16: Gonza
A17: 13 | B17: Pareja 13
A18: 14 | B18: Pareja 14
A19: 15 | B19: Pareja 15
A20: 16 | B20: Pareja 16

Sheet Suizo
A1: Fase suiza · 2 rondas · BO1
A2: Completá en amarillo: ID de cada pareja, rounds ganados y mapa. Wingman: gana quien llega a 9 rounds. No muevas las columnas.
A4: Partido | B4: Ronda | C4: ID A | D4: Pareja A | E4: Rounds A | F4: Rounds B | G4: Pareja B | H4: ID B | I4: Mapa | J4: Ganador | K4: id_ganador | L4: victorias_rival_A | M4: victorias_rival_B
A5: 1 | B5: R1 | C5: 1 | D5: =IF(C5="","",INDEX(Parejas!$B$5:$B$20,C5)) -> Cardozo / Cardozo | G5: =IF(H5="","",INDEX(Parejas!$B$5:$B$20,H5)) -> Simon / Joaquin | H5: 7 | J5: =IF(K5="",IF(AND(E5<>"",F5<>"",E5=F5),"EMPATE: jugar OT",""),INDEX(Parejas!$B$5:$B$20,K5)) | K5: =IF(OR(C5="",H5="",E5="",F5=""),"",IF(E5>F5,C5,IF(F5>E5,H5,""))) | L5: =IF(K5="","",INDEX(Calculo!$D$2:$D$17,H5)) | M5: =IF(K5="","",INDEX(Calculo!$D$2:$D$17,C5))
A6: 2 | B6: R1 | C6: 3 | D6: =IF(C6="","",INDEX(Parejas!$B$5:$B$20,C6)) -> Diego / (a confirmar) | G6: =IF(H6="","",INDEX(Parejas!$B$5:$B$20,H6)) -> Luciano / Gonzalo | H6: 4 | J6: =IF(K6="",IF(AND(E6<>"",F6<>"",E6=F6),"EMPATE: jugar OT",""),INDEX(Parejas!$B$5:$B$20,K6)) | K6: =IF(OR(C6="",H6="",E6="",F6=""),"",IF(E6>F6,C6,IF(F6>E6,H6,""))) | L6: =IF(K6="","",INDEX(Calculo!$D$2:$D$17,H6)) | M6: =IF(K6="","",INDEX(Calculo!$D$2:$D$17,C6))
A7: 3 | B7: R1 | C7: 11 | D7: =IF(C7="","",INDEX(Parejas!$B$5:$B$20,C7)) -> Agustin / Rodrigo | G7: =IF(H7="","",INDEX(Parejas!$B$5:$B$20,H7)) -> Francisco / Marcos | H7: 5 | J7: =IF(K7="",IF(AND(E7<>"",F7<>"",E7=F7),"EMPATE: jugar OT",""),INDEX(Parejas!$B$5:$B$20,K7)) | K7: =IF(OR(C7="",H7="",E7="",F7=""),"",IF(E7>F7,C7,IF(F7>E7,H7,""))) | L7: =IF(K7="","",INDEX(Calculo!$D$2:$D$17,H7)) | M7: =IF(K7="","",INDEX(Calculo!$D$2:$D$17,C7))
A8: 4 | B8: R1 | C8: 8 | D8: =IF(C8="","",INDEX(Parejas!$B$5:$B$20,C8)) -> Rodrigo / Nazareno | G8: =IF(H8="","",INDEX(Parejas!$B$5:$B$20,H8)) -> Enzo / Gonza | H8: 12 | J8: =IF(K8="",IF(AND(E8<>"",F8<>"",E8=F8),"EMPATE: jugar OT",""),INDEX(Parejas!$B$5:$B$20,K8)) | K8: =IF(OR(C8="",H8="",E8="",F8=""),"",IF(E8>F8,C8,IF(F8>E8,H8,""))) | L8: =IF(K8="","",INDEX(Calculo!$D$2:$D$17,H8)) | M8: =IF(K8="","",INDEX(Calculo!$D$2:$D$17,C8))
A9: 5 | B9: R1 | C9: 10 | D9: =IF(C9="","",INDEX(Parejas!$B$5:$B$20,C9)) -> Lucas / Martin | G9: =IF(H9="","",INDEX(Parejas!$B$5:$B$20,H9)) -> Bautista / Luciano | H9: 9 | J9: =IF(K9="",IF(AND(E9<>"",F9<>"",E9=F9),"EMPATE: jugar OT",""),INDEX(Parejas!$B$5:$B$20,K9)) | K9: =IF(OR(C9="",H9="",E9="",F9=""),"",IF(E9>F9,C9,IF(F9>E9,H9,""))) | L9: =IF(K9="","",INDEX(Calculo!$D$2:$D$17,H9)) | M9: =IF(K9="","",INDEX(Calculo!$D$2:$D$17,C9))
A10: 6 | B10: R1 | C10: 6 | D10: =IF(C10="","",INDEX(Parejas!$B$5:$B$20,C10)) -> Luciano / Lautaro | G10: =IF(H10="","",INDEX(Parejas!$B$5:$B$20,H10)) -> Blas / Agustin | H10: 2 | J10: =IF(K10="",IF(AND(E10<>"",F10<>"",E10=F10),"EMPATE: jugar OT",""),INDEX(Parejas!$B$5:$B$20,K10)) | K10: =IF(OR(C10="",H10="",E10="",F10=""),"",IF(E10>F10,C10,IF(F10>E10,H10,""))) | L10: =IF(K10="","",INDEX(Calculo!$D$2:$D$17,H10)) | M10: =IF(K10="","",INDEX(Calculo!$D$2:$D$17,C10))
A11: 7 | B11: R1 | C11: 13 | D11: =IF(C11="","",INDEX(Parejas!$B$5:$B$20,C11)) -> Pareja 13 | G11: =IF(H11="","",INDEX(Parejas!$B$5:$B$20,H11)) -> Pareja 14 | H11: 14 | J11: =IF(K11="",IF(AND(E11<>"",F11<>"",E11=F11),"EMPATE: jugar OT",""),INDEX(Parejas!$B$5:$B$20,K11)) | K11: =IF(OR(C11="",H11="",E11="",F11=""),"",IF(E11>F11,C11,IF(F11>E11,H11,""))) | L11: =IF(K11="","",INDEX(Calculo!$D$2:$D$17,H11)) | M11: =IF(K11="","",INDEX(Calculo!$D$2:$D$17,C11))
A12: 8 | B12: R1 | C12: 15 | D12: =IF(C12="","",INDEX(Parejas!$B$5:$B$20,C12)) -> Pareja 15 | G12: =IF(H12="","",INDEX(Parejas!$B$5:$B$20,H12)) -> Pareja 16 | H12: 16 | J12: =IF(K12="",IF(AND(E12<>"",F12<>"",E12=F12),"EMPATE: jugar OT",""),INDEX(Parejas!$B$5:$B$20,K12)) | K12: =IF(OR(C12="",H12="",E12="",F12=""),"",IF(E12>F12,C12,IF(F12>E12,H12,""))) | L12: =IF(K12="","",INDEX(Calculo!$D$2:$D$17,H12)) | M12: =IF(K12="","",INDEX(Calculo!$D$2:$D$17,C12))
A13: 9 | B13: R2 | C13: =IF(Emparejar!$D$1=1,Emparejar!$D$21,"") | D13: =IF(C13<>"",INDEX(Parejas!$B$5:$B$20,C13),"Esperando ronda 1: faltan "&(8-COUNTIF($K$5:$K$12,">0"))&" ganador(es)") -> Esperando ronda 1: faltan 8 ganador(es) | G13: =IF(H13<>"",INDEX(Parejas!$B$5:$B$20,H13),IF(SUMPRODUCT(($E$5:$E$12<>"")*($F$5:$F$12<>"")*($E$5:$E$12=$F$5:$F$12))>0,"Hay empate: anotá el OT (ej. 10-8)","")) | H13: =IF(Emparejar!$D$1=1,Emparejar!$E$21,"") | J13: =IF(K13="",IF(AND(E13<>"",F13<>"",E13=F13),"EMPATE: jugar OT",""),INDEX(Parejas!$B$5:$B$20,K13)) | K13: =IF(OR(C13="",H13="",E13="",F13=""),"",IF(E13>F13,C13,IF(F13>E13,H13,""))) | L13: =IF(K13="","",INDEX(Calculo!$D$2:$D$17,H13)) | M13: =IF(K13="","",INDEX(Calculo!$D$2:$D$17,C13))
A14: 10 | B14: R2 | C14: =IF(Emparejar!$D$1=1,Emparejar!$D$22,"") | D14: =IF(C14<>"",INDEX(Parejas!$B$5:$B$20,C14),"Esperando ronda 1: faltan "&(8-COUNTIF($K$5:$K$12,">0"))&" ganador(es)") -> Esperando ronda 1: faltan 8 ganador(es) | G14: =IF(H14<>"",INDEX(Parejas!$B$5:$B$20,H14),IF(SUMPRODUCT(($E$5:$E$12<>"")*($F$5:$F$12<>"")*($E$5:$E$12=$F$5:$F$12))>0,"Hay empate: anotá el OT (ej. 10-8)","")) | H14: =IF(Emparejar!$D$1=1,Emparejar!$E$22,"") | J14: =IF(K14="",IF(AND(E14<>"",F14<>"",E14=F14),"EMPATE: jugar OT",""),INDEX(Parejas!$B$5:$B$20,K14)) | K14: =IF(OR(C14="",H14="",E14="",F14=""),"",IF(E14>F14,C14,IF(F14>E14,H14,""))) | L14: =IF(K14="","",INDEX(Calculo!$D$2:$D$17,H14)) | M14: =IF(K14="","",INDEX(Calculo!$D$2:$D$17,C14))
A15: 11 | B15: R2 | C15: =IF(Emparejar!$D$1=1,Emparejar!$D$23,"") | D15: =IF(C15<>"",INDEX(Parejas!$B$5:$B$20,C15),"Esperando ronda 1: faltan "&(8-COUNTIF($K$5:$K$12,">0"))&" ganador(es)") -> Esperando ronda 1: faltan 8 ganador(es) | G15: =IF(H15<>"",INDEX(Parejas!$B$5:$B$20,H15),IF(SUMPRODUCT(($E$5:$E$12<>"")*($F$5:$F$12<>"")*($E$5:$E$12=$F$5:$F$12))>0,"Hay empate: anotá el OT (ej. 10-8)","")) | H15: =IF(Emparejar!$D$1=1,Emparejar!$E$23,"") | J15: =IF(K15="",IF(AND(E15<>"",F15<>"",E15=F15),"EMPATE: jugar OT",""),INDEX(Parejas!$B$5:$B$20,K15)) | K15: =IF(OR(C15="",H15="",E15="",F15=""),"",IF(E15>F15,C15,IF(F15>E15,H15,""))) | L15: =IF(K15="","",INDEX(Calculo!$D$2:$D$17,H15)) | M15: =IF(K15="","",INDEX(Calculo!$D$2:$D$17,C15))
A16: 12 | B16: R2 | C16: =IF(Emparejar!$D$1=1,Emparejar!$D$24,"") | D16: =IF(C16<>"",INDEX(Parejas!$B$5:$B$20,C16),"Esperando ronda 1: faltan "&(8-COUNTIF($K$5:$K$12,">0"))&" ganador(es)") -> Esperando ronda 1: faltan 8 ganador(es) | G16: =IF(H16<>"",INDEX(Parejas!$B$5:$B$20,H16),IF(SUMPRODUCT(($E$5:$E$12<>"")*($F$5:$F$12<>"")*($E$5:$E$12=$F$5:$F$12))>0,"Hay empate: anotá el OT (ej. 10-8)","")) | H16: =IF(Emparejar!$D$1=1,Emparejar!$E$24,"") | J16: =IF(K16="",IF(AND(E16<>"",F16<>"",E16=F16),"EMPATE: jugar OT",""),INDEX(Parejas!$B$5:$B$20,K16)) | K16: =IF(OR(C16="",H16="",E16="",F16=""),"",IF(E16>F16,C16,IF(F16>E16,H16,""))) | L16: =IF(K16="","",INDEX(Calculo!$D$2:$D$17,H16)) | M16: =IF(K16="","",INDEX(Calculo!$D$2:$D$17,C16))
A17: 13 | B17: R2 | C17: =IF(Emparejar!$D$1=1,Emparejar!$D$25,"") | D17: =IF(C17<>"",INDEX(Parejas!$B$5:$B$20,C17),"Esperando ronda 1: faltan "&(8-COUNTIF($K$5:$K$12,">0"))&" ganador(es)") -> Esperando ronda 1: faltan 8 ganador(es) | G17: =IF(H17<>"",INDEX(Parejas!$B$5:$B$20,H17),IF(SUMPRODUCT(($E$5:$E$12<>"")*($F$5:$F$12<>"")*($E$5:$E$12=$F$5:$F$12))>0,"Hay empate: anotá el OT (ej. 10-8)","")) | H17: =IF(Emparejar!$D$1=1,Emparejar!$E$25,"") | J17: =IF(K17="",IF(AND(E17<>"",F17<>"",E17=F17),"EMPATE: jugar OT",""),INDEX(Parejas!$B$5:$B$20,K17)) | K17: =IF(OR(C17="",H17="",E17="",F17=""),"",IF(E17>F17,C17,IF(F17>E17,H17,""))) | L17: =IF(K17="","",INDEX(Calculo!$D$2:$D$17,H17)) | M17: =IF(K17="","",INDEX(Calculo!$D$2:$D$17,C17))
A18: 14 | B18: R2 | C18: =IF(Emparejar!$D$1=1,Emparejar!$D$26,"") | D18: =IF(C18<>"",INDEX(Parejas!$B$5:$B$20,C18),"Esperando ronda 1: faltan "&(8-COUNTIF($K$5:$K$12,">0"))&" ganador(es)") -> Esperando ronda 1: faltan 8 ganador(es) | G18: =IF(H18<>"",INDEX(Parejas!$B$5:$B$20,H18),IF(SUMPRODUCT(($E$5:$E$12<>"")*($F$5:$F$12<>"")*($E$5:$E$12=$F$5:$F$12))>0,"Hay empate: anotá el OT (ej. 10-8)","")) | H18: =IF(Emparejar!$D$1=1,Emparejar!$E$26,"") | J18: =IF(K18="",IF(AND(E18<>"",F18<>"",E18=F18),"EMPATE: jugar OT",""),INDEX(Parejas!$B$5:$B$20,K18)) | K18: =IF(OR(C18="",H18="",E18="",F18=""),"",IF(E18>F18,C18,IF(F18>E18,H18,""))) | L18: =IF(K18="","",INDEX(Calculo!$D$2:$D$17,H18)) | M18: =IF(K18="","",INDEX(Calculo!$D$2:$D$17,C18))
A19: 15 | B19: R2 | C19: =IF(Emparejar!$D$1=1,Emparejar!$D$27,"") | D19: =IF(C19<>"",INDEX(Parejas!$B$5:$B$20,C19),"Esperando ronda 1: faltan "&(8-COUNTIF($K$5:$K$12,">0"))&" ganador(es)") -> Esperando ronda 1: faltan 8 ganador(es) | G19: =IF(H19<>"",INDEX(Parejas!$B$5:$B$20,H19),IF(SUMPRODUCT(($E$5:$E$12<>"")*($F$5:$F$12<>"")*($E$5:$E$12=$F$5:$F$12))>0,"Hay empate: anotá el OT (ej. 10-8)","")) | H19: =IF(Emparejar!$D$1=1,Emparejar!$E$27,"") | J19: =IF(K19="",IF(AND(E19<>"",F19<>"",E19=F19),"EMPATE: jugar OT",""),INDEX(Parejas!$B$5:$B$20,K19)) | K19: =IF(OR(C19="",H19="",E19="",F19=""),"",IF(E19>F19,C19,IF(F19>E19,H19,""))) | L19: =IF(K19="","",INDEX(Calculo!$D$2:$D$17,H19)) | M19: =IF(K19="","",INDEX(Calculo!$D$2:$D$17,C19))
A20: 16 | B20: R2 | C20: =IF(Emparejar!$D$1=1,Emparejar!$D$28,"") | D20: =IF(C20<>"",INDEX(Parejas!$B$5:$B$20,C20),"Esperando ronda 1: faltan "&(8-COUNTIF($K$5:$K$12,">0"))&" ganador(es)") -> Esperando ronda 1: faltan 8 ganador(es) | G20: =IF(H20<>"",INDEX(Parejas!$B$5:$B$20,H20),IF(SUMPRODUCT(($E$5:$E$12<>"")*($F$5:$F$12<>"")*($E$5:$E$12=$F$5:$F$12))>0,"Hay empate: anotá el OT (ej. 10-8)","")) | H20: =IF(Emparejar!$D$1=1,Emparejar!$E$28,"") | J20: =IF(K20="",IF(AND(E20<>"",F20<>"",E20=F20),"EMPATE: jugar OT",""),INDEX(Parejas!$B$5:$B$20,K20)) | K20: =IF(OR(C20="",H20="",E20="",F20=""),"",IF(E20>F20,C20,IF(F20>E20,H20,""))) | L20: =IF(K20="","",INDEX(Calculo!$D$2:$D$17,H20)) | M20: =IF(K20="","",INDEX(Calculo!$D$2:$D$17,C20))
A22: Ronda 1: sorteo al azar. Ronda 2: los cruces aparecen solos cuando termina la ronda 1 (mismo récord, sin repetir rival).
A23: Si querés cambiar un cruce a mano, escribí el ID encima (esa celda deja de ser automática).
A24: Si un partido termina 8-8, jueguen overtime y anotá el resultado final.

Sheet Calculo
A1: ID | B1: Pareja | C1: PJ | D1: PG | E1: PP | F1: RF | G1: RC | H1: Dif | I1: Buchholz | J1: Clave orden
A2: 1 | B2: =INDEX(Parejas!$B$5:$B$20,A2) -> Cardozo / Cardozo | C2: =COUNTIFS(Suizo!$C$5:$C$20,A2,Suizo!$K$5:$K$20,">0")+COUNTIFS(Suizo!$H$5:$H$20,A2,Suizo!$K$5:$K$20,">0") -> 0 | D2: =COUNTIF(Suizo!$K$5:$K$20,A2) -> 0 | E2: =C2-D2 -> 0 | F2: =SUMIFS(Suizo!$E$5:$E$20,Suizo!$C$5:$C$20,A2,Suizo!$K$5:$K$20,">0")+SUMIFS(Suizo!$F$5:$F$20,Suizo!$H$5:$H$20,A2,Suizo!$K$5:$K$20,">0") -> 0 | G2: =SUMIFS(Suizo!$F$5:$F$20,Suizo!$C$5:$C$20,A2,Suizo!$K$5:$K$20,">0")+SUMIFS(Suizo!$E$5:$E$20,Suizo!$H$5:$H$20,A2,Suizo!$K$5:$K$20,">0") -> 0 | H2: =F2-G2 -> 0 | I2: =SUMIFS(Suizo!$L$5:$L$20,Suizo!$C$5:$C$20,A2)+SUMIFS(Suizo!$M$5:$M$20,Suizo!$H$5:$H$20,A2) -> 0 | J2: =D2*1000000000+(H2+500)*1000000+I2*10000+F2*10-A2/100 -> 5e+08
A3: 2 | B3: =INDEX(Parejas!$B$5:$B$20,A3) -> Blas / Agustin | C3: =COUNTIFS(Suizo!$C$5:$C$20,A3,Suizo!$K$5:$K$20,">0")+COUNTIFS(Suizo!$H$5:$H$20,A3,Suizo!$K$5:$K$20,">0") -> 0 | D3: =COUNTIF(Suizo!$K$5:$K$20,A3) -> 0 | E3: =C3-D3 -> 0 | F3: =SUMIFS(Suizo!$E$5:$E$20,Suizo!$C$5:$C$20,A3,Suizo!$K$5:$K$20,">0")+SUMIFS(Suizo!$F$5:$F$20,Suizo!$H$5:$H$20,A3,Suizo!$K$5:$K$20,">0") -> 0 | G3: =SUMIFS(Suizo!$F$5:$F$20,Suizo!$C$5:$C$20,A3,Suizo!$K$5:$K$20,">0")+SUMIFS(Suizo!$E$5:$E$20,Suizo!$H$5:$H$20,A3,Suizo!$K$5:$K$20,">0") -> 0 | H3: =F3-G3 -> 0 | I3: =SUMIFS(Suizo!$L$5:$L$20,Suizo!$C$5:$C$20,A3)+SUMIFS(Suizo!$M$5:$M$20,Suizo!$H$5:$H$20,A3) -> 0 | J3: =D3*1000000000+(H3+500)*1000000+I3*10000+F3*10-A3/100 -> 5e+08
A4: 3 | B4: =INDEX(Parejas!$B$5:$B$20,A4) -> Diego / (a confirmar) | C4: =COUNTIFS(Suizo!$C$5:$C$20,A4,Suizo!$K$5:$K$20,">0")+COUNTIFS(Suizo!$H$5:$H$20,A4,Suizo!$K$5:$K$20,">0") -> 0 | D4: =COUNTIF(Suizo!$K$5:$K$20,A4) -> 0 | E4: =C4-D4 -> 0 | F4: =SUMIFS(Suizo!$E$5:$E$20,Suizo!$C$5:$C$20,A4,Suizo!$K$5:$K$20,">0")+SUMIFS(Suizo!$F$5:$F$20,Suizo!$H$5:$H$20,A4,Suizo!$K$5:$K$20,">0") -> 0 | G4: =SUMIFS(Suizo!$F$5:$F$20,Suizo!$C$5:$C$20,A4,Suizo!$K$5:$K$20,">0")+SUMIFS(Suizo!$E$5:$E$20,Suizo!$H$5:$H$20,A4,Suizo!$K$5:$K$20,">0") -> 0 | H4: =F4-G4 -> 0 | I4: =SUMIFS(Suizo!$L$5:$L$20,Suizo!$C$5:$C$20,A4)+SUMIFS(Suizo!$M$5:$M$20,Suizo!$H$5:$H$20,A4) -> 0 | J4: =D4*1000000000+(H4+500)*1000000+I4*10000+F4*10-A4/100 -> 5e+08
A5: 4 | B5: =INDEX(Parejas!$B$5:$B$20,A5) -> Luciano / Gonzalo | C5: =COUNTIFS(Suizo!$C$5:$C$20,A5,Suizo!$K$5:$K$20,">0")+COUNTIFS(Suizo!$H$5:$H$20,A5,Suizo!$K$5:$K$20,">0") -> 0 | D5: =COUNTIF(Suizo!$K$5:$K$20,A5) -> 0 | E5: =C5-D5 -> 0 | F5: =SUMIFS(Suizo!$E$5:$E$20,Suizo!$C$5:$C$20,A5,Suizo!$K$5:$K$20,">0")+SUMIFS(Suizo!$F$5:$F$20,Suizo!$H$5:$H$20,A5,Suizo!$K$5:$K$20,">0") -> 0 | G5: =SUMIFS(Suizo!$F$5:$F$20,Suizo!$C$5:$C$20,A5,Suizo!$K$5:$K$20,">0")+SUMIFS(Suizo!$E$5:$E$20,Suizo!$H$5:$H$20,A5,Suizo!$K$5:$K$20,">0") -> 0 | H5: =F5-G5 -> 0 | I5: =SUMIFS(Suizo!$L$5:$L$20,Suizo!$C$5:$C$20,A5)+SUMIFS(Suizo!$M$5:$M$20,Suizo!$H$5:$H$20,A5) -> 0 | J5: =D5*1000000000+(H5+500)*1000000+I5*10000+F5*10-A5/100 -> 5e+08
A6: 5 | B6: =INDEX(Parejas!$B$5:$B$20,A6) -> Francisco / Marcos | C6: =COUNTIFS(Suizo!$C$5:$C$20,A6,Suizo!$K$5:$K$20,">0")+COUNTIFS(Suizo!$H$5:$H$20,A6,Suizo!$K$5:$K$20,">0") -> 0 | D6: =COUNTIF(Suizo!$K$5:$K$20,A6) -> 0 | E6: =C6-D6 -> 0 | F6: =SUMIFS(Suizo!$E$5:$E$20,Suizo!$C$5:$C$20,A6,Suizo!$K$5:$K$20,">0")+SUMIFS(Suizo!$F$5:$F$20,Suizo!$H$5:$H$20,A6,Suizo!$K$5:$K$20,">0") -> 0 | G6: =SUMIFS(Suizo!$F$5:$F$20,Suizo!$C$5:$C$20,A6,Suizo!$K$5:$K$20,">0")+SUMIFS(Suizo!$E$5:$E$20,Suizo!$H$5:$H$20,A6,Suizo!$K$5:$K$20,">0") -> 0 | H6: =F6-G6 -> 0 | I6: =SUMIFS(Suizo!$L$5:$L$20,Suizo!$C$5:$C$20,A6)+SUMIFS(Suizo!$M$5:$M$20,Suizo!$H$5:$H$20,A6) -> 0 | J6: =D6*1000000000+(H6+500)*1000000+I6*10000+F6*10-A6/100 -> 5e+08
A7: 6 | B7: =INDEX(Parejas!$B$5:$B$20,A7) -> Luciano / Lautaro | C7: =COUNTIFS(Suizo!$C$5:$C$20,A7,Suizo!$K$5:$K$20,">0")+COUNTIFS(Suizo!$H$5:$H$20,A7,Suizo!$K$5:$K$20,">0") -> 0 | D7: =COUNTIF(Suizo!$K$5:$K$20,A7) -> 0 | E7: =C7-D7 -> 0 | F7: =SUMIFS(Suizo!$E$5:$E$20,Suizo!$C$5:$C$20,A7,Suizo!$K$5:$K$20,">0")+SUMIFS(Suizo!$F$5:$F$20,Suizo!$H$5:$H$20,A7,Suizo!$K$5:$K$20,">0") -> 0 | G7: =SUMIFS(Suizo!$F$5:$F$20,Suizo!$C$5:$C$20,A7,Suizo!$K$5:$K$20,">0")+SUMIFS(Suizo!$E$5:$E$20,Suizo!$H$5:$H$20,A7,Suizo!$K$5:$K$20,">0") -> 0 | H7: =F7-G7 -> 0 | I7: =SUMIFS(Suizo!$L$5:$L$20,Suizo!$C$5:$C$20,A7)+SUMIFS(Suizo!$M$5:$M$20,Suizo!$H$5:$H$20,A7) -> 0 | J7: =D7*1000000000+(H7+500)*1000000+I7*10000+F7*10-A7/100 -> 5e+08
A8: 7 | B8: =INDEX(Parejas!$B$5:$B$20,A8) -> Simon / Joaquin | C8: =COUNTIFS(Suizo!$C$5:$C$20,A8,Suizo!$K$5:$K$20,">0")+COUNTIFS(Suizo!$H$5:$H$20,A8,Suizo!$K$5:$K$20,">0") -> 0 | D8: =COUNTIF(Suizo!$K$5:$K$20,A8) -> 0 | E8: =C8-D8 -> 0 | F8: =SUMIFS(Suizo!$E$5:$E$20,Suizo!$C$5:$C$20,A8,Suizo!$K$5:$K$20,">0")+SUMIFS(Suizo!$F$5:$F$20,Suizo!$H$5:$H$20,A8,Suizo!$K$5:$K$20,">0") -> 0 | G8: =SUMIFS(Suizo!$F$5:$F$20,Suizo!$C$5:$C$20,A8,Suizo!$K$5:$K$20,">0")+SUMIFS(Suizo!$E$5:$E$20,Suizo!$H$5:$H$20,A8,Suizo!$K$5:$K$20,">0") -> 0 | H8: =F8-G8 -> 0 | I8: =SUMIFS(Suizo!$L$5:$L$20,Suizo!$C$5:$C$20,A8)+SUMIFS(Suizo!$M$5:$M$20,Suizo!$H$5:$H$20,A8) -> 0 | J8: =D8*1000000000+(H8+500)*1000000+I8*10000+F8*10-A8/100 -> 5e+08
A9: 8 | B9: =INDEX(Parejas!$B$5:$B$20,A9) -> Rodrigo / Nazareno | C9: =COUNTIFS(Suizo!$C$5:$C$20,A9,Suizo!$K$5:$K$20,">0")+COUNTIFS(Suizo!$H$5:$H$20,A9,Suizo!$K$5:$K$20,">0") -> 0 | D9: =COUNTIF(Suizo!$K$5:$K$20,A9) -> 0 | E9: =C9-D9 -> 0 | F9: =SUMIFS(Suizo!$E$5:$E$20,Suizo!$C$5:$C$20,A9,Suizo!$K$5:$K$20,">0")+SUMIFS(Suizo!$F$5:$F$20,Suizo!$H$5:$H$20,A9,Suizo!$K$5:$K$20,">0") -> 0 | G9: =SUMIFS(Suizo!$F$5:$F$20,Suizo!$C$5:$C$20,A9,Suizo!$K$5:$K$20,">0")+SUMIFS(Suizo!$E$5:$E$20,Suizo!$H$5:$H$20,A9,Suizo!$K$5:$K$20,">0") -> 0 | H9: =F9-G9 -> 0 | I9: =SUMIFS(Suizo!$L$5:$L$20,Suizo!$C$5:$C$20,A9)+SUMIFS(Suizo!$M$5:$M$20,Suizo!$H$5:$H$20,A9) -> 0 | J9: =D9*1000000000+(H9+500)*1000000+I9*10000+F9*10-A9/100 -> 5e+08
A10: 9 | B10: =INDEX(Parejas!$B$5:$B$20,A10) -> Bautista / Luciano | C10: =COUNTIFS(Suizo!$C$5:$C$20,A10,Suizo!$K$5:$K$20,">0")+COUNTIFS(Suizo!$H$5:$H$20,A10,Suizo!$K$5:$K$20,">0") -> 0 | D10: =COUNTIF(Suizo!$K$5:$K$20,A10) -> 0 | E10: =C10-D10 -> 0 | F10: =SUMIFS(Suizo!$E$5:$E$20,Suizo!$C$5:$C$20,A10,Suizo!$K$5:$K$20,">0")+SUMIFS(Suizo!$F$5:$F$20,Suizo!$H$5:$H$20,A10,Suizo!$K$5:$K$20,">0") -> 0 | G10: =SUMIFS(Suizo!$F$5:$F$20,Suizo!$C$5:$C$20,A10,Suizo!$K$5:$K$20,">0")+SUMIFS(Suizo!$E$5:$E$20,Suizo!$H$5:$H$20,A10,Suizo!$K$5:$K$20,">0") -> 0 | H10: =F10-G10 -> 0 | I10: =SUMIFS(Suizo!$L$5:$L$20,Suizo!$C$5:$C$20,A10)+SUMIFS(Suizo!$M$5:$M$20,Suizo!$H$5:$H$20,A10) -> 0 | J10: =D10*1000000000+(H10+500)*1000000+I10*10000+F10*10-A10/100 -> 5e+08
A11: 10 | B11: =INDEX(Parejas!$B$5:$B$20,A11) -> Lucas / Martin | C11: =COUNTIFS(Suizo!$C$5:$C$20,A11,Suizo!$K$5:$K$20,">0")+COUNTIFS(Suizo!$H$5:$H$20,A11,Suizo!$K$5:$K$20,">0") -> 0 | D11: =COUNTIF(Suizo!$K$5:$K$20,A11) -> 0 | E11: =C11-D11 -> 0 | F11: =SUMIFS(Suizo!$E$5:$E$20,Suizo!$C$5:$C$20,A11,Suizo!$K$5:$K$20,">0")+SUMIFS(Suizo!$F$5:$F$20,Suizo!$H$5:$H$20,A11,Suizo!$K$5:$K$20,">0") -> 0 | G11: =SUMIFS(Suizo!$F$5:$F$20,Suizo!$C$5:$C$20,A11,Suizo!$K$5:$K$20,">0")+SUMIFS(Suizo!$E$5:$E$20,Suizo!$H$5:$H$20,A11,Suizo!$K$5:$K$20,">0") -> 0 | H11: =F11-G11 -> 0 | I11: =SUMIFS(Suizo!$L$5:$L$20,Suizo!$C$5:$C$20,A11)+SUMIFS(Suizo!$M$5:$M$20,Suizo!$H$5:$H$20,A11) -> 0 | J11: =D11*1000000000+(H11+500)*1000000+I11*10000+F11*10-A11/100 -> 5e+08
A12: 11 | B12: =INDEX(Parejas!$B$5:$B$20,A12) -> Agustin / Rodrigo | C12: =COUNTIFS(Suizo!$C$5:$C$20,A12,Suizo!$K$5:$K$20,">0")+COUNTIFS(Suizo!$H$5:$H$20,A12,Suizo!$K$5:$K$20,">0") -> 0 | D12: =COUNTIF(Suizo!$K$5:$K$20,A12) -> 0 | E12: =C12-D12 -> 0 | F12: =SUMIFS(Suizo!$E$5:$E$20,Suizo!$C$5:$C$20,A12,Suizo!$K$5:$K$20,">0")+SUMIFS(Suizo!$F$5:$F$20,Suizo!$H$5:$H$20,A12,Suizo!$K$5:$K$20,">0") -> 0 | G12: =SUMIFS(Suizo!$F$5:$F$20,Suizo!$C$5:$C$20,A12,Suizo!$K$5:$K$20,">0")+SUMIFS(Suizo!$E$5:$E$20,Suizo!$H$5:$H$20,A12,Suizo!$K$5:$K$20,">0") -> 0 | H12: =F12-G12 -> 0 | I12: =SUMIFS(Suizo!$L$5:$L$20,Suizo!$C$5:$C$20,A12)+SUMIFS(Suizo!$M$5:$M$20,Suizo!$H$5:$H$20,A12) -> 0 | J12: =D12*1000000000+(H12+500)*1000000+I12*10000+F12*10-A12/100 -> 5e+08
A13: 12 | B13: =INDEX(Parejas!$B$5:$B$20,A13) -> Enzo / Gonza | C13: =COUNTIFS(Suizo!$C$5:$C$20,A13,Suizo!$K$5:$K$20,">0")+COUNTIFS(Suizo!$H$5:$H$20,A13,Suizo!$K$5:$K$20,">0") -> 0 | D13: =COUNTIF(Suizo!$K$5:$K$20,A13) -> 0 | E13: =C13-D13 -> 0 | F13: =SUMIFS(Suizo!$E$5:$E$20,Suizo!$C$5:$C$20,A13,Suizo!$K$5:$K$20,">0")+SUMIFS(Suizo!$F$5:$F$20,Suizo!$H$5:$H$20,A13,Suizo!$K$5:$K$20,">0") -> 0 | G13: =SUMIFS(Suizo!$F$5:$F$20,Suizo!$C$5:$C$20,A13,Suizo!$K$5:$K$20,">0")+SUMIFS(Suizo!$E$5:$E$20,Suizo!$H$5:$H$20,A13,Suizo!$K$5:$K$20,">0") -> 0 | H13: =F13-G13 -> 0 | I13: =SUMIFS(Suizo!$L$5:$L$20,Suizo!$C$5:$C$20,A13)+SUMIFS(Suizo!$M$5:$M$20,Suizo!$H$5:$H$20,A13) -> 0 | J13: =D13*1000000000+(H13+500)*1000000+I13*10000+F13*10-A13/100 -> 5e+08
... A17: 16 | B17: =INDEX(Parejas!$B$5:$B$20,A17) -> Pareja 16 | C17: =COUNTIFS(Suizo!$C$5:$C$20,A17,Suizo!$K$5:$K$20,">0")+COUNTIFS(Suizo!$H$5:$H$20,A17,Suizo!$K$5:$K$20,">0") -> 0 | D17: =COUNTIF(Suizo!$K$5:$K$20,A17) -> 0 | E17: =C17-D17 -> 0 | F17: =SUMIFS(Suizo!$E$5:$E$20,Suizo!$C$5:$C$20,A17,Suizo!$K$5:$K$20,">0")+SUMIFS(Suizo!$F$5:$F$20,Suizo!$H$5:$H$20,A17,Suizo!$K$5:$K$20,">0") -> 0 | G17: =SUMIFS(Suizo!$F$5:$F$20,Suizo!$C$5:$C$20,A17,Suizo!$K$5:$K$20,">0")+SUMIFS(Suizo!$E$5:$E$20,Suizo!$H$5:$H$20,A17,Suizo!$K$5:$K$20,">0") -> 0 | H17: =F17-G17 -> 0 | I17: =SUMIFS(Suizo!$L$5:$L$20,Suizo!$C$5:$C$20,A17)+SUMIFS(Suizo!$M$5:$M$20,Suizo!$H$5:$H$20,A17) -> 0 | J17: =D17*1000000000+(H17+500)*1000000+I17*10000+F17*10-A17/100 -> 5e+08
A19: Hoja de cálculo interna: no editar. Clave = PG > Dif. rounds > Buchholz > Rounds a favor > ID (desempate final).

Sheet Emparejar
A1: Ronda 2 | C1: lista | D1: =IF(COUNTIF(Suizo!$K$5:$K$12,">0")=8,1,0) -> 0
A2: ID | B2: PG | C2: Dif | D2: RF | E2: Clave | F2: Pos | G2: ID en pos
A3: 1 | B3: =COUNTIF(Suizo!$K$5:$K$12,A3) -> 0 | C3: =(SUMIFS(Suizo!$E$5:$E$12,Suizo!$C$5:$C$12,A3,Suizo!$K$5:$K$12,">0")+SUMIFS(Suizo!$F$5:$F$12,Suizo!$H$5:$H$12,A3,Suizo!$K$5:$K$12,">0"))-(SUMIFS(Suizo!$F$5:$F$12,Suizo!$C$5:$C$12,A3,Suizo!$K$5:$K$12,">0")+SUMIFS(Suizo!$E$5:$E$12,Suizo!$H$5:$H$12,A3,Suizo!$K$5:$K$12,">0")) -> 0 | D3: =(SUMIFS(Suizo!$E$5:$E$12,Suizo!$C$5:$C$12,A3,Suizo!$K$5:$K$12,">0")+SUMIFS(Suizo!$F$5:$F$12,Suizo!$H$5:$H$12,A3,Suizo!$K$5:$K$12,">0")) -> 0 | E3: =B3*100000000+(C3+500)*100000+D3*100-A3 -> 49999999 | F3: 1 | G3: =INDEX($A$3:$A$18,MATCH(LARGE($E$3:$E$18,F3),$E$3:$E$18,0)) -> 1
A4: 2 | B4: =COUNTIF(Suizo!$K$5:$K$12,A4) -> 0 | C4: =(SUMIFS(Suizo!$E$5:$E$12,Suizo!$C$5:$C$12,A4,Suizo!$K$5:$K$12,">0")+SUMIFS(Suizo!$F$5:$F$12,Suizo!$H$5:$H$12,A4,Suizo!$K$5:$K$12,">0"))-(SUMIFS(Suizo!$F$5:$F$12,Suizo!$C$5:$C$12,A4,Suizo!$K$5:$K$12,">0")+SUMIFS(Suizo!$E$5:$E$12,Suizo!$H$5:$H$12,A4,Suizo!$K$5:$K$12,">0")) -> 0 | D4: =(SUMIFS(Suizo!$E$5:$E$12,Suizo!$C$5:$C$12,A4,Suizo!$K$5:$K$12,">0")+SUMIFS(Suizo!$F$5:$F$12,Suizo!$H$5:$H$12,A4,Suizo!$K$5:$K$12,">0")) -> 0 | E4: =B4*100000000+(C4+500)*100000+D4*100-A4 -> 49999998 | F4: 2 | G4: =INDEX($A$3:$A$18,MATCH(LARGE($E$3:$E$18,F4),$E$3:$E$18,0)) -> 2
A5: 3 | B5: =COUNTIF(Suizo!$K$5:$K$12,A5) -> 0 | C5: =(SUMIFS(Suizo!$E$5:$E$12,Suizo!$C$5:$C$12,A5,Suizo!$K$5:$K$12,">0")+SUMIFS(Suizo!$F$5:$F$12,Suizo!$H$5:$H$12,A5,Suizo!$K$5:$K$12,">0"))-(SUMIFS(Suizo!$F$5:$F$12,Suizo!$C$5:$C$12,A5,Suizo!$K$5:$K$12,">0")+SUMIFS(Suizo!$E$5:$E$12,Suizo!$H$5:$H$12,A5,Suizo!$K$5:$K$12,">0")) -> 0 | D5: =(SUMIFS(Suizo!$E$5:$E$12,Suizo!$C$5:$C$12,A5,Suizo!$K$5:$K$12,">0")+SUMIFS(Suizo!$F$5:$F$12,Suizo!$H$5:$H$12,A5,Suizo!$K$5:$K$12,">0")) -> 0 | E5: =B5*100000000+(C5+500)*100000+D5*100-A5 -> 49999997 | F5: 3 | G5: =INDEX($A$3:$A$18,MATCH(LARGE($E$3:$E$18,F5),$E$3:$E$18,0)) -> 3
A6: 4 | B6: =COUNTIF(Suizo!$K$5:$K$12,A6) -> 0 | C6: =(SUMIFS(Suizo!$E$5:$E$12,Suizo!$C$5:$C$12,A6,Suizo!$K$5:$K$12,">0")+SUMIFS(Suizo!$F$5:$F$12,Suizo!$H$5:$H$12,A6,Suizo!$K$5:$K$12,">0"))-(SUMIFS(Suizo!$F$5:$F$12,Suizo!$C$5:$C$12,A6,Suizo!$K$5:$K$12,">0")+SUMIFS(Suizo!$E$5:$E$12,Suizo!$H$5:$H$12,A6,Suizo!$K$5:$K$12,">0")) -> 0 | D6: =(SUMIFS(Suizo!$E$5:$E$12,Suizo!$C$5:$C$12,A6,Suizo!$K$5:$K$12,">0")+SUMIFS(Suizo!$F$5:$F$12,Suizo!$H$5:$H$12,A6,Suizo!$K$5:$K$12,">0")) -> 0 | E6: =B6*100000000+(C6+500)*100000+D6*100-A6 -> 49999996 | F6: 4 | G6: =INDEX($A$3:$A$18,MATCH(LARGE($E$3:$E$18,F6),$E$3:$E$18,0)) -> 4
A7: 5 | B7: =COUNTIF(Suizo!$K$5:$K$12,A7) -> 0 | C7: =(SUMIFS(Suizo!$E$5:$E$12,Suizo!$C$5:$C$12,A7,Suizo!$K$5:$K$12,">0")+SUMIFS(Suizo!$F$5:$F$12,Suizo!$H$5:$H$12,A7,Suizo!$K$5:$K$12,">0"))-(SUMIFS(Suizo!$F$5:$F$12,Suizo!$C$5:$C$12,A7,Suizo!$K$5:$K$12,">0")+SUMIFS(Suizo!$E$5:$E$12,Suizo!$H$5:$H$12,A7,Suizo!$K$5:$K$12,">0")) -> 0 | D7: =(SUMIFS(Suizo!$E$5:$E$12,Suizo!$C$5:$C$12,A7,Suizo!$K$5:$K$12,">0")+SUMIFS(Suizo!$F$5:$F$12,Suizo!$H$5:$H$12,A7,Suizo!$K$5:$K$12,">0")) -> 0 | E7: =B7*100000000+(C7+500)*100000+D7*100-A7 -> 49999995 | F7: 5 | G7: =INDEX($A$3:$A$18,MATCH(LARGE($E$3:$E$18,F7),$E$3:$E$18,0)) -> 5
A8: 6 | B8: =COUNTIF(Suizo!$K$5:$K$12,A8) -> 0 | C8: =(SUMIFS(Suizo!$E$5:$E$12,Suizo!$C$5:$C$12,A8,Suizo!$K$5:$K$12,">0")+SUMIFS(Suizo!$F$5:$F$12,Suizo!$H$5:$H$12,A8,Suizo!$K$5:$K$12,">0"))-(SUMIFS(Suizo!$F$5:$F$12,Suizo!$C$5:$C$12,A8,Suizo!$K$5:$K$12,">0")+SUMIFS(Suizo!$E$5:$E$12,Suizo!$H$5:$H$12,A8,Suizo!$K$5:$K$12,">0")) -> 0 | D8: =(SUMIFS(Suizo!$E$5:$E$12,Suizo!$C$5:$C$12,A8,Suizo!$K$5:$K$12,">0")+SUMIFS(Suizo!$F$5:$F$12,Suizo!$H$5:$H$12,A8,Suizo!$K$5:$K$12,">0")) -> 0 | E8: =B8*100000000+(C8+500)*100000+D8*100-A8 -> 49999994 | F8: 6 | G8: =INDEX($A$3:$A$18,MATCH(LARGE($E$3:$E$18,F8),$E$3:$E$18,0)) -> 6
A9: 7 | B9: =COUNTIF(Suizo!$K$5:$K$12,A9) -> 0 | C9: =(SUMIFS(Suizo!$E$5:$E$12,Suizo!$C$5:$C$12,A9,Suizo!$K$5:$K$12,">0")+SUMIFS(Suizo!$F$5:$F$12,Suizo!$H$5:$H$12,A9,Suizo!$K$5:$K$12,">0"))-(SUMIFS(Suizo!$F$5:$F$12,Suizo!$C$5:$C$12,A9,Suizo!$K$5:$K$12,">0")+SUMIFS(Suizo!$E$5:$E$12,Suizo!$H$5:$H$12,A9,Suizo!$K$5:$K$12,">0")) -> 0 | D9: =(SUMIFS(Suizo!$E$5:$E$12,Suizo!$C$5:$C$12,A9,Suizo!$K$5:$K$12,">0")+SUMIFS(Suizo!$F$5:$F$12,Suizo!$H$5:$H$12,A9,Suizo!$K$5:$K$12,">0")) -> 0 | E9: =B9*100000000+(C9+500)*100000+D9*100-A9 -> 49999993 | F9: 7 | G9: =INDEX($A$3:$A$18,MATCH(LARGE($E$3:$E$18,F9),$E$3:$E$18,0)) -> 7
A10: 8 | B10: =COUNTIF(Suizo!$K$5:$K$12,A10) -> 0 | C10: =(SUMIFS(Suizo!$E$5:$E$12,Suizo!$C$5:$C$12,A10,Suizo!$K$5:$K$12,">0")+SUMIFS(Suizo!$F$5:$F$12,Suizo!$H$5:$H$12,A10,Suizo!$K$5:$K$12,">0"))-(SUMIFS(Suizo!$F$5:$F$12,Suizo!$C$5:$C$12,A10,Suizo!$K$5:$K$12,">0")+SUMIFS(Suizo!$E$5:$E$12,Suizo!$H$5:$H$12,A10,Suizo!$K$5:$K$12,">0")) -> 0 | D10: =(SUMIFS(Suizo!$E$5:$E$12,Suizo!$C$5:$C$12,A10,Suizo!$K$5:$K$12,">0")+SUMIFS(Suizo!$F$5:$F$12,Suizo!$H$5:$H$12,A10,Suizo!$K$5:$K$12,">0")) -> 0 | E10: =B10*100000000+(C10+500)*100000+D10*100-A10 -> 49999992 | F10: 8 | G10: =INDEX($A$3:$A$18,MATCH(LARGE($E$3:$E$18,F10),$E$3:$E$18,0)) -> 8
A11: 9 | B11: =COUNTIF(Suizo!$K$5:$K$12,A11) -> 0 | C11: =(SUMIFS(Suizo!$E$5:$E$12,Suizo!$C$5:$C$12,A11,Suizo!$K$5:$K$12,">0")+SUMIFS(Suizo!$F$5:$F$12,Suizo!$H$5:$H$12,A11,Suizo!$K$5:$K$12,">0"))-(SUMIFS(Suizo!$F$5:$F$12,Suizo!$C$5:$C$12,A11,Suizo!$K$5:$K$12,">0")+SUMIFS(Suizo!$E$5:$E$12,Suizo!$H$5:$H$12,A11,Suizo!$K$5:$K$12,">0")) -> 0 | D11: =(SUMIFS(Suizo!$E$5:$E$12,Suizo!$C$5:$C$12,A11,Suizo!$K$5:$K$12,">0")+SUMIFS(Suizo!$F$5:$F$12,Suizo!$H$5:$H$12,A11,Suizo!$K$5:$K$12,">0")) -> 0 | E11: =B11*100000000+(C11+500)*100000+D11*100-A11 -> 49999991 | F11: 9 | G11: =INDEX($A$3:$A$18,MATCH(LARGE($E$3:$E$18,F11),$E$3:$E$18,0)) -> 9
A12: 10 | B12: =COUNTIF(Suizo!$K$5:$K$12,A12) -> 0 | C12: =(SUMIFS(Suizo!$E$5:$E$12,Suizo!$C$5:$C$12,A12,Suizo!$K$5:$K$12,">0")+SUMIFS(Suizo!$F$5:$F$12,Suizo!$H$5:$H$12,A12,Suizo!$K$5:$K$12,">0"))-(SUMIFS(Suizo!$F$5:$F$12,Suizo!$C$5:$C$12,A12,Suizo!$K$5:$K$12,">0")+SUMIFS(Suizo!$E$5:$E$12,Suizo!$H$5:$H$12,A12,Suizo!$K$5:$K$12,">0")) -> 0 | D12: =(SUMIFS(Suizo!$E$5:$E$12,Suizo!$C$5:$C$12,A12,Suizo!$K$5:$K$12,">0")+SUMIFS(Suizo!$F$5:$F$12,Suizo!$H$5:$H$12,A12,Suizo!$K$5:$K$12,">0")) -> 0 | E12: =B12*100000000+(C12+500)*100000+D12*100-A12 -> 49999990 | F12: 10 | G12: =INDEX($A$3:$A$18,MATCH(LARGE($E$3:$E$18,F12),$E$3:$E$18,0)) -> 10
A13: 11 | B13: =COUNTIF(Suizo!$K$5:$K$12,A13) -> 0 | C13: =(SUMIFS(Suizo!$E$5:$E$12,Suizo!$C$5:$C$12,A13,Suizo!$K$5:$K$12,">0")+SUMIFS(Suizo!$F$5:$F$12,Suizo!$H$5:$H$12,A13,Suizo!$K$5:$K$12,">0"))-(SUMIFS(Suizo!$F$5:$F$12,Suizo!$C$5:$C$12,A13,Suizo!$K$5:$K$12,">0")+SUMIFS(Suizo!$E$5:$E$12,Suizo!$H$5:$H$12,A13,Suizo!$K$5:$K$12,">0")) -> 0 | D13: =(SUMIFS(Suizo!$E$5:$E$12,Suizo!$C$5:$C$12,A13,Suizo!$K$5:$K$12,">0")+SUMIFS(Suizo!$F$5:$F$12,Suizo!$H$5:$H$12,A13,Suizo!$K$5:$K$12,">0")) -> 0 | E13: =B13*100000000+(C13+500)*100000+D13*100-A13 -> 49999989 | F13: 11 | G13: =INDEX($A$3:$A$18,MATCH(LARGE($E$3:$E$18,F13),$E$3:$E$18,0)) -> 11
A14: 12 | B14: =COUNTIF(Suizo!$K$5:$K$12,A14) -> 0 | C14: =(SUMIFS(Suizo!$E$5:$E$12,Suizo!$C$5:$C$12,A14,Suizo!$K$5:$K$12,">0")+SUMIFS(Suizo!$F$5:$F$12,Suizo!$H$5:$H$12,A14,Suizo!$K$5:$K$12,">0"))-(SUMIFS(Suizo!$F$5:$F$12,Suizo!$C$5:$C$12,A14,Suizo!$K$5:$K$12,">0")+SUMIFS(Suizo!$E$5:$E$12,Suizo!$H$5:$H$12,A14,Suizo!$K$5:$K$12,">0")) -> 0 | D14: =(SUMIFS(Suizo!$E$5:$E$12,Suizo!$C$5:$C$12,A14,Suizo!$K$5:$K$12,">0")+SUMIFS(Suizo!$F$5:$F$12,Suizo!$H$5:$H$12,A14,Suizo!$K$5:$K$12,">0")) -> 0 | E14: =B14*100000000+(C14+500)*100000+D14*100-A14 -> 49999988 | F14: 12 | G14: =INDEX($A$3:$A$18,MATCH(LARGE($E$3:$E$18,F14),$E$3:$E$18,0)) -> 12
... A18: 16 | B18: =COUNTIF(Suizo!$K$5:$K$12,A18) -> 0 | C18: =(SUMIFS(Suizo!$E$5:$E$12,Suizo!$C$5:$C$12,A18,Suizo!$K$5:$K$12,">0")+SUMIFS(Suizo!$F$5:$F$12,Suizo!$H$5:$H$12,A18,Suizo!$K$5:$K$12,">0"))-(SUMIFS(Suizo!$F$5:$F$12,Suizo!$C$5:$C$12,A18,Suizo!$K$5:$K$12,">0")+SUMIFS(Suizo!$E$5:$E$12,Suizo!$H$5:$H$12,A18,Suizo!$K$5:$K$12,">0")) -> 0 | D18: =(SUMIFS(Suizo!$E$5:$E$12,Suizo!$C$5:$C$12,A18,Suizo!$K$5:$K$12,">0")+SUMIFS(Suizo!$F$5:$F$12,Suizo!$H$5:$H$12,A18,Suizo!$K$5:$K$12,">0")) -> 0 | E18: =B18*100000000+(C18+500)*100000+D18*100-A18 -> 49999984 | F18: 16 | G18: =INDEX($A$3:$A$18,MATCH(LARGE($E$3:$E$18,F18),$E$3:$E$18,0)) -> 16
A20: Paso | B20: PosA | C20: PosB | D20: ID A | E20: ID B
A21: 1 | B21: =MATCH(0,F21:U21,0) -> 1 | C21: =IF(MIN(V21:AK21)<99,MIN(V21:AK21),MIN(AL21:BA21)) -> 2 | D21: =INDEX($G$3:$G$18,B21) -> 1 | E21: =INDEX($G$3:$G$18,C21) -> 2 | F21: 0 | G21: 0 | H21: 0 | I21: 0 | J21: 0 | K21: 0 | L21: 0 | M21: 0 | N21: 0 | O21: 0 | P21: 0 | Q21: 0 | R21: 0 | S21: 0 | T21: 0 | U21: 0 | V21: =IF(AND(F21=0,1>B21,(COUNTIFS(Suizo!$C$5:$C$12,D21,Suizo!$H$5:$H$12,INDEX($G$3:$G$18,1))+COUNTIFS(Suizo!$C$5:$C$12,INDEX($G$3:$G$18,1),Suizo!$H$5:$H$12,D21))=0),1,99) -> 99 | W21: =IF(AND(G21=0,2>B21,(COUNTIFS(Suizo!$C$5:$C$12,D21,Suizo!$H$5:$H$12,INDEX($G$3:$G$18,2))+COUNTIFS(Suizo!$C$5:$C$12,INDEX($G$3:$G$18,2),Suizo!$H$5:$H$12,D21))=0),2,99) -> 2 | X21: =IF(AND(H21=0,3>B21,(COUNTIFS(Suizo!$C$5:$C$12,D21,Suizo!$H$5:$H$12,INDEX($G$3:$G$18,3))+COUNTIFS(Suizo!$C$5:$C$12,INDEX($G$3:$G$18,3),Suizo!$H$5:$H$12,D21))=0),3,99) -> 3 | Y21: =IF(AND(I21=0,4>B21,(COUNTIFS(Suizo!$C$5:$C$12,D21,Suizo!$H$5:$H$12,INDEX($G$3:$G$18,4))+COUNTIFS(Suizo!$C$5:$C$12,INDEX($G$3:$G$18,4),Suizo!$H$5:$H$12,D21))=0),4,99) -> 4 | Z21: =IF(AND(J21=0,5>B21,(COUNTIFS(Suizo!$C$5:$C$12,D21,Suizo!$H$5:$H$12,INDEX($G$3:$G$18,5))+COUNTIFS(Suizo!$C$5:$C$12,INDEX($G$3:$G$18,5),Suizo!$H$5:$H$12,D21))=0),5,99) -> 5 | AA21: =IF(AND(K21=0,6>B21,(COUNTIFS(Suizo!$C$5:$C$12,D21,Suizo!$H$5:$H$12,INDEX($G$3:$G$18,6))+COUNTIFS(Suizo!$C$5:$C$12,INDEX($G$3:$G$18,6),Suizo!$H$5:$H$12,D21))=0),6,99) -> 6 | AB21: =IF(AND(L21=0,7>B21,(COUNTIFS(Suizo!$C$5:$C$12,D21,Suizo!$H$5:$H$12,INDEX($G$3:$G$18,7))+COUNTIFS(Suizo!$C$5:$C$12,INDEX($G$3:$G$18,7),Suizo!$H$5:$H$12,D21))=0),7,99) -> 99 | AC21: =IF(AND(M21=0,8>B21,(COUNTIFS(Suizo!$C$5:$C$12,D21,Suizo!$H$5:$H$12,INDEX($G$3:$G$18,8))+COUNTIFS(Suizo!$C$5:$C$12,INDEX($G$3:$G$18,8),Suizo!$H$5:$H$12,D21))=0),8,99) -> 8 | AD21: =IF(AND(N21=0,9>B21,(COUNTIFS(Suizo!$C$5:$C$12,D21,Suizo!$H$5:$H$12,INDEX($G$3:$G$18,9))+COUNTIFS(Suizo!$C$5:$C$12,INDEX($G$3:$G$18,9),Suizo!$H$5:$H$12,D21))=0),9,99) -> 9 | AE21: =IF(AND(O21=0,10>B21,(COUNTIFS(Suizo!$C$5:$C$12,D21,Suizo!$H$5:$H$12,INDEX($G$3:$G$18,10))+COUNTIFS(Suizo!$C$5:$C$12,INDEX($G$3:$G$18,10),Suizo!$H$5:$H$12,D21))=0),10,99) -> 10 | AF21: =IF(AND(P21=0,11>B21,(COUNTIFS(Suizo!$C$5:$C$12,D21,Suizo!$H$5:$H$12,INDEX($G$3:$G$18,11))+COUNTIFS(Suizo!$C$5:$C$12,INDEX($G$3:$G$18,11),Suizo!$H$5:$H$12,D21))=0),11,99) -> 11 | AG21: =IF(AND(Q21=0,12>B21,(COUNTIFS(Suizo!$C$5:$C$12,D21,Suizo!$H$5:$H$12,INDEX($G$3:$G$18,12))+COUNTIFS(Suizo!$C$5:$C$12,INDEX($G$3:$G$18,12),Suizo!$H$5:$H$12,D21))=0),12,99) -> 12 | AH21: =IF(AND(R21=0,13>B21,(COUNTIFS(Suizo!$C$5:$C$12,D21,Suizo!$H$5:$H$12,INDEX($G$3:$G$18,13))+COUNTIFS(Suizo!$C$5:$C$12,INDEX($G$3:$G$18,13),Suizo!$H$5:$H$12,D21))=0),13,99) -> 13 | AI21: =IF(AND(S21=0,14>B21,(COUNTIFS(Suizo!$C$5:$C$12,D21,Suizo!$H$5:$H$12,INDEX($G$3:$G$18,14))+COUNTIFS(Suizo!$C$5:$C$12,INDEX($G$3:$G$18,14),Suizo!$H$5:$H$12,D21))=0),14,99) -> 14 | AJ21: =IF(AND(T21=0,15>B21,(COUNTIFS(Suizo!$C$5:$C$12,D21,Suizo!$H$5:$H$12,INDEX($G$3:$G$18,15))+COUNTIFS(Suizo!$C$5:$C$12,INDEX($G$3:$G$18,15),Suizo!$H$5:$H$12,D21))=0),15,99) -> 15 | AK21: =IF(AND(U21=0,16>B21,(COUNTIFS(Suizo!$C$5:$C$12,D21,Suizo!$H$5:$H$12,INDEX($G$3:$G$18,16))+COUNTIFS(Suizo!$C$5:$C$12,INDEX($G$3:$G$18,16),Suizo!$H$5:$H$12,D21))=0),16,99) -> 16 | AL21: =IF(AND(F21=0,1>B21),1,99) -> 99 | AM21: =IF(AND(G21=0,2>B21),2,99) -> 2 | AN21: =IF(AND(H21=0,3>B21),3,99) -> 3 | AO21: =IF(AND(I21=0,4>B21),4,99) -> 4 | AP21: =IF(AND(J21=0,5>B21),5,99) -> 5 | AQ21: =IF(AND(K21=0,6>B21),6,99) -> 6 | AR21: =IF(AND(L21=0,7>B21),7,99) -> 7 | AS21: =IF(AND(M21=0,8>B21),8,99) -> 8 | AT21: =IF(AND(N21=0,9>B21),9,99) -> 9 | AU21: =IF(AND(O21=0,10>B21),10,99) -> 10 | AV21: =IF(AND(P21=0,11>B21),11,99) -> 11 | AW21: =IF(AND(Q21=0,12>B21),12,99) -> 12 | AX21: =IF(AND(R21=0,13>B21),13,99) -> 13 | AY21: =IF(AND(S21=0,14>B21),14,99) -> 14 | AZ21: =IF(AND(T21=0,15>B21),15,99) -> 15 | BA21: =IF(AND(U21=0,16>B21),16,99) -> 16 | BB21: =IF(MIN(V21:AK21)=99,"REVANCHA","")
A22: 2 | B22: =MATCH(0,F22:U22,0) -> 3 | C22: =IF(MIN(V22:AK22)<99,MIN(V22:AK22),MIN(AL22:BA22)) -> 5 | D22: =INDEX($G$3:$G$18,B22) -> 3 | E22: =INDEX($G$3:$G$18,C22) -> 5 | F22: =IF(OR(F21=1,B21=1,C21=1),1,0) -> 1 | G22: =IF(OR(G21=1,B21=2,C21=2),1,0) -> 1 | H22: =IF(OR(H21=1,B21=3,C21=3),1,0) -> 0 | I22: =IF(OR(I21=1,B21=4,C21=4),1,0) -> 0 | J22: =IF(OR(J21=1,B21=5,C21=5),1,0) -> 0 | K22: =IF(OR(K21=1,B21=6,C21=6),1,0) -> 0 | L22: =IF(OR(L21=1,B21=7,C21=7),1,0) -> 0 | M22: =IF(OR(M21=1,B21=8,C21=8),1,0) -> 0 | N22: =IF(OR(N21=1,B21=9,C21=9),1,0) -> 0 | O22: =IF(OR(O21=1,B21=10,C21=10),1,0) -> 0 | P22: =IF(OR(P21=1,B21=11,C21=11),1,0) -> 0 | Q22: =IF(OR(Q21=1,B21=12,C21=12),1,0) -> 0 | R22: =IF(OR(R21=1,B21=13,C21=13),1,0) -> 0 | S22: =IF(OR(S21=1,B21=14,C21=14),1,0) -> 0 | T22: =IF(OR(T21=1,B21=15,C21=15),1,0) -> 0 | U22: =IF(OR(U21=1,B21=16,C21=16),1,0) -> 0 | V22: =IF(AND(F22=0,1>B22,(COUNTIFS(Suizo!$C$5:$C$12,D22,Suizo!$H$5:$H$12,INDEX($G$3:$G$18,1))+COUNTIFS(Suizo!$C$5:$C$12,INDEX($G$3:$G$18,1),Suizo!$H$5:$H$12,D22))=0),1,99) -> 99 | W22: =IF(AND(G22=0,2>B22,(COUNTIFS(Suizo!$C$5:$C$12,D22,Suizo!$H$5:$H$12,INDEX($G$3:$G$18,2))+COUNTIFS(Suizo!$C$5:$C$12,INDEX($G$3:$G$18,2),Suizo!$H$5:$H$12,D22))=0),2,99) -> 99 | X22: =IF(AND(H22=0,3>B22,(COUNTIFS(Suizo!$C$5:$C$12,D22,Suizo!$H$5:$H$12,INDEX($G$3:$G$18,3))+COUNTIFS(Suizo!$C$5:$C$12,INDEX($G$3:$G$18,3),Suizo!$H$5:$H$12,D22))=0),3,99) -> 99 | Y22: =IF(AND(I22=0,4>B22,(COUNTIFS(Suizo!$C$5:$C$12,D22,Suizo!$H$5:$H$12,INDEX($G$3:$G$18,4))+COUNTIFS(Suizo!$C$5:$C$12,INDEX($G$3:$G$18,4),Suizo!$H$5:$H$12,D22))=0),4,99) -> 99 | Z22: =IF(AND(J22=0,5>B22,(COUNTIFS(Suizo!$C$5:$C$12,D22,Suizo!$H$5:$H$12,INDEX($G$3:$G$18,5))+COUNTIFS(Suizo!$C$5:$C$12,INDEX($G$3:$G$18,5),Suizo!$H$5:$H$12,D22))=0),5,99) -> 5 | AA22: =IF(AND(K22=0,6>B22,(COUNTIFS(Suizo!$C$5:$C$12,D22,Suizo!$H$5:$H$12,INDEX($G$3:$G$18,6))+COUNTIFS(Suizo!$C$5:$C$12,INDEX($G$3:$G$18,6),Suizo!$H$5:$H$12,D22))=0),6,99) -> 6 | AB22: =IF(AND(L22=0,7>B22,(COUNTIFS(Suizo!$C$5:$C$12,D22,Suizo!$H$5:$H$12,INDEX($G$3:$G$18,7))+COUNTIFS(Suizo!$C$5:$C$12,INDEX($G$3:$G$18,7),Suizo!$H$5:$H$12,D22))=0),7,99) -> 7 | AC22: =IF(AND(M22=0,8>B22,(COUNTIFS(Suizo!$C$5:$C$12,D22,Suizo!$H$5:$H$12,INDEX($G$3:$G$18,8))+COUNTIFS(Suizo!$C$5:$C$12,INDEX($G$3:$G$18,8),Suizo!$H$5:$H$12,D22))=0),8,99) -> 8 | AD22: =IF(AND(N22=0,9>B22,(COUNTIFS(Suizo!$C$5:$C$12,D22,Suizo!$H$5:$H$12,INDEX($G$3:$G$18,9))+COUNTIFS(Suizo!$C$5:$C$12,INDEX($G$3:$G$18,9),Suizo!$H$5:$H$12,D22))=0),9,99) -> 9 | AE22: =IF(AND(O22=0,10>B22,(COUNTIFS(Suizo!$C$5:$C$12,D22,Suizo!$H$5:$H$12,INDEX($G$3:$G$18,10))+COUNTIFS(Suizo!$C$5:$C$12,INDEX($G$3:$G$18,10),Suizo!$H$5:$H$12,D22))=0),10,99) -> 10 | AF22: =IF(AND(P22=0,11>B22,(COUNTIFS(Suizo!$C$5:$C$12,D22,Suizo!$H$5:$H$12,INDEX($G$3:$G$18,11))+COUNTIFS(Suizo!$C$5:$C$12,INDEX($G$3:$G$18,11),Suizo!$H$5:$H$12,D22))=0),11,99) -> 11 | AG22: =IF(AND(Q22=0,12>B22,(COUNTIFS(Suizo!$C$5:$C$12,D22,Suizo!$H$5:$H$12,INDEX($G$3:$G$18,12))+COUNTIFS(Suizo!$C$5:$C$12,INDEX($G$3:$G$18,12),Suizo!$H$5:$H$12,D22))=0),12,99) -> 12 | AH22: =IF(AND(R22=0,13>B22,(COUNTIFS(Suizo!$C$5:$C$12,D22,Suizo!$H$5:$H$12,INDEX($G$3:$G$18,13))+COUNTIFS(Suizo!$C$5:$C$12,INDEX($G$3:$G$18,13),Suizo!$H$5:$H$12,D22))=0),13,99) -> 13 | AI22: =IF(AND(S22=0,14>B22,(COUNTIFS(Suizo!$C$5:$C$12,D22,Suizo!$H$5:$H$12,INDEX($G$3:$G$18,14))+COUNTIFS(Suizo!$C$5:$C$12,INDEX($G$3:$G$18,14),Suizo!$H$5:$H$12,D22))=0),14,99) -> 14 | AJ22: =IF(AND(T22=0,15>B22,(COUNTIFS(Suizo!$C$5:$C$12,D22,Suizo!$H$5:$H$12,INDEX($G$3:$G$18,15))+COUNTIFS(Suizo!$C$5:$C$12,INDEX($G$3:$G$18,15),Suizo!$H$5:$H$12,D22))=0),15,99) -> 15 | AK22: =IF(AND(U22=0,16>B22,(COUNTIFS(Suizo!$C$5:$C$12,D22,Suizo!$H$5:$H$12,INDEX($G$3:$G$18,16))+COUNTIFS(Suizo!$C$5:$C$12,INDEX($G$3:$G$18,16),Suizo!$H$5:$H$12,D22))=0),16,99) -> 16 | AL22: =IF(AND(F22=0,1>B22),1,99) -> 99 | AM22: =IF(AND(G22=0,2>B22),2,99) -> 99 | AN22: =IF(AND(H22=0,3>B22),3,99) -> 99 | AO22: =IF(AND(I22=0,4>B22),4,99) -> 4 | AP22: =IF(AND(J22=0,5>B22),5,99) -> 5 | AQ22: =IF(AND(K22=0,6>B22),6,99) -> 6 | AR22: =IF(AND(L22=0,7>B22),7,99) -> 7 | AS22: =IF(AND(M22=0,8>B22),8,99) -> 8 | AT22: =IF(AND(N22=0,9>B22),9,99) -> 9 | AU22: =IF(AND(O22=0,10>B22),10,99) -> 10 | AV22: =IF(AND(P22=0,11>B22),11,99) -> 11 | AW22: =IF(AND(Q22=0,12>B22),12,99) -> 12 | AX22: =IF(AND(R22=0,13>B22),13,99) -> 13 | AY22: =IF(AND(S22=0,14>B22),14,99) -> 14 | AZ22: =IF(AND(T22=0,15>B22),15,99) -> 15 | BA22: =IF(AND(U22=0,16>B22),16,99) -> 16 | BB22: =IF(MIN(V22:AK22)=99,"REVANCHA","")
A23: 3 | B23: =MATCH(0,F23:U23,0) -> 4 | C23: =IF(MIN(V23:AK23)<99,MIN(V23:AK23),MIN(AL23:BA23)) -> 6 | D23: =INDEX($G$3:$G$18,B23) -> 4 | E23: =INDEX($G$3:$G$18,C23) -> 6 | F23: =IF(OR(F22=1,B22=1,C22=1),1,0) -> 1 | G23: =IF(OR(G22=1,B22=2,C22=2),1,0) -> 1 | H23: =IF(OR(H22=1,B22=3,C22=3),1,0) -> 1 | I23: =IF(OR(I22=1,B22=4,C22=4),1,0) -> 0 | J23: =IF(OR(J22=1,B22=5,C22=5),1,0) -> 1 | K23: =IF(OR(K22=1,B22=6,C22=6),1,0) -> 0 | L23: =IF(OR(L22=1,B22=7,C22=7),1,0) -> 0 | M23: =IF(OR(M22=1,B22=8,C22=8),1,0) -> 0 | N23: =IF(OR(N22=1,B22=9,C22=9),1,0) -> 0 | O23: =IF(OR(O22=1,B22=10,C22=10),1,0) -> 0 | P23: =IF(OR(P22=1,B22=11,C22=11),1,0) -> 0 | Q23: =IF(OR(Q22=1,B22=12,C22=12),1,0) -> 0 | R23: =IF(OR(R22=1,B22=13,C22=13),1,0) -> 0 | S23: =IF(OR(S22=1,B22=14,C22=14),1,0) -> 0 | T23: =IF(OR(T22=1,B22=15,C22=15),1,0) -> 0 | U23: =IF(OR(U22=1,B22=16,C22=16),1,0) -> 0 | V23: =IF(AND(F23=0,1>B23,(COUNTIFS(Suizo!$C$5:$C$12,D23,Suizo!$H$5:$H$12,INDEX($G$3:$G$18,1))+COUNTIFS(Suizo!$C$5:$C$12,INDEX($G$3:$G$18,1),Suizo!$H$5:$H$12,D23))=0),1,99) -> 99 | W23: =IF(AND(G23=0,2>B23,(COUNTIFS(Suizo!$C$5:$C$12,D23,Suizo!$H$5:$H$12,INDEX($G$3:$G$18,2))+COUNTIFS(Suizo!$C$5:$C$12,INDEX($G$3:$G$18,2),Suizo!$H$5:$H$12,D23))=0),2,99) -> 99 | X23: =IF(AND(H23=0,3>B23,(COUNTIFS(Suizo!$C$5:$C$12,D23,Suizo!$H$5:$H$12,INDEX($G$3:$G$18,3))+COUNTIFS(Suizo!$C$5:$C$12,INDEX($G$3:$G$18,3),Suizo!$H$5:$H$12,D23))=0),3,99) -> 99 | Y23: =IF(AND(I23=0,4>B23,(COUNTIFS(Suizo!$C$5:$C$12,D23,Suizo!$H$5:$H$12,INDEX($G$3:$G$18,4))+COUNTIFS(Suizo!$C$5:$C$12,INDEX($G$3:$G$18,4),Suizo!$H$5:$H$12,D23))=0),4,99) -> 99 | Z23: =IF(AND(J23=0,5>B23,(COUNTIFS(Suizo!$C$5:$C$12,D23,Suizo!$H$5:$H$12,INDEX($G$3:$G$18,5))+COUNTIFS(Suizo!$C$5:$C$12,INDEX($G$3:$G$18,5),Suizo!$H$5:$H$12,D23))=0),5,99) -> 99 | AA23: =IF(AND(K23=0,6>B23,(COUNTIFS(Suizo!$C$5:$C$12,D23,Suizo!$H$5:$H$12,INDEX($G$3:$G$18,6))+COUNTIFS(Suizo!$C$5:$C$12,INDEX($G$3:$G$18,6),Suizo!$H$5:$H$12,D23))=0),6,99) -> 6 | AB23: =IF(AND(L23=0,7>B23,(COUNTIFS(Suizo!$C$5:$C$12,D23,Suizo!$H$5:$H$12,INDEX($G$3:$G$18,7))+COUNTIFS(Suizo!$C$5:$C$12,INDEX($G$3:$G$18,7),Suizo!$H$5:$H$12,D23))=0),7,99) -> 7 | AC23: =IF(AND(M23=0,8>B23,(COUNTIFS(Suizo!$C$5:$C$12,D23,Suizo!$H$5:$H$12,INDEX($G$3:$G$18,8))+COUNTIFS(Suizo!$C$5:$C$12,INDEX($G$3:$G$18,8),Suizo!$H$5:$H$12,D23))=0),8,99) -> 8 | AD23: =IF(AND(N23=0,9>B23,(COUNTIFS(Suizo!$C$5:$C$12,D23,Suizo!$H$5:$H$12,INDEX($G$3:$G$18,9))+COUNTIFS(Suizo!$C$5:$C$12,INDEX($G$3:$G$18,9),Suizo!$H$5:$H$12,D23))=0),9,99) -> 9 | AE23: =IF(AND(O23=0,10>B23,(COUNTIFS(Suizo!$C$5:$C$12,D23,Suizo!$H$5:$H$12,INDEX($G$3:$G$18,10))+COUNTIFS(Suizo!$C$5:$C$12,INDEX($G$3:$G$18,10),Suizo!$H$5:$H$12,D23))=0),10,99) -> 10 | AF23: =IF(AND(P23=0,11>B23,(COUNTIFS(Suizo!$C$5:$C$12,D23,Suizo!$H$5:$H$12,INDEX($G$3:$G$18,11))+COUNTIFS(Suizo!$C$5:$C$12,INDEX($G$3:$G$18,11),Suizo!$H$5:$H$12,D23))=0),11,99) -> 11 | AG23: =IF(AND(Q23=0,12>B23,(COUNTIFS(Suizo!$C$5:$C$12,D23,Suizo!$H$5:$H$12,INDEX($G$3:$G$18,12))+COUNTIFS(Suizo!$C$5:$C$12,INDEX($G$3:$G$18,12),Suizo!$H$5:$H$12,D23))=0),12,99) -> 12 | AH23: =IF(AND(R23=0,13>B23,(COUNTIFS(Suizo!$C$5:$C$12,D23,Suizo!$H$5:$H$12,INDEX($G$3:$G$18,13))+COUNTIFS(Suizo!$C$5:$C$12,INDEX($G$3:$G$18,13),Suizo!$H$5:$H$12,D23))=0),13,99) -> 13 | AI23: =IF(AND(S23=0,14>B23,(COUNTIFS(Suizo!$C$5:$C$12,D23,Suizo!$H$5:$H$12,INDEX($G$3:$G$18,14))+COUNTIFS(Suizo!$C$5:$C$12,INDEX($G$3:$G$18,14),Suizo!$H$5:$H$12,D23))=0),14,99) -> 14 | AJ23: =IF(AND(T23=0,15>B23,(COUNTIFS(Suizo!$C$5:$C$12,D23,Suizo!$H$5:$H$12,INDEX($G$3:$G$18,15))+COUNTIFS(Suizo!$C$5:$C$12,INDEX($G$3:$G$18,15),Suizo!$H$5:$H$12,D23))=0),15,99) -> 15 | AK23: =IF(AND(U23=0,16>B23,(COUNTIFS(Suizo!$C$5:$C$12,D23,Suizo!$H$5:$H$12,INDEX($G$3:$G$18,16))+COUNTIFS(Suizo!$C$5:$C$12,INDEX($G$3:$G$18,16),Suizo!$H$5:$H$12,D23))=0),16,99) -> 16 | AL23: =IF(AND(F23=0,1>B23),1,99) -> 99 | AM23: =IF(AND(G23=0,2>B23),2,99) -> 99 | AN23: =IF(AND(H23=0,3>B23),3,99) -> 99 | AO23: =IF(AND(I23=0,4>B23),4,99) -> 99 | AP23: =IF(AND(J23=0,5>B23),5,99) -> 99 | AQ23: =IF(AND(K23=0,6>B23),6,99) -> 6 | AR23: =IF(AND(L23=0,7>B23),7,99) -> 7 | AS23: =IF(AND(M23=0,8>B23),8,99) -> 8 | AT23: =IF(AND(N23=0,9>B23),9,99) -> 9 | AU23: =IF(AND(O23=0,10>B23),10,99) -> 10 | AV23: =IF(AND(P23=0,11>B23),11,99) -> 11 | AW23: =IF(AND(Q23=0,12>B23),12,99) -> 12 | AX23: =IF(AND(R23=0,13>B23),13,99) -> 13 | AY23: =IF(AND(S23=0,14>B23),14,99) -> 14 | AZ23: =IF(AND(T23=0,15>B23),15,99) -> 15 | BA23: =IF(AND(U23=0,16>B23),16,99) -> 16 | BB23: =IF(MIN(V23:AK23)=99,"REVANCHA","")
A24: 4 | B24: =MATCH(0,F24:U24,0) -> 7 | C24: =IF(MIN(V24:AK24)<99,MIN(V24:AK24),MIN(AL24:BA24)) -> 8 | D24: =INDEX($G$3:$G$18,B24) -> 7 | E24: =INDEX($G$3:$G$18,C24) -> 8 | F24: =IF(OR(F23=1,B23=1,C23=1),1,0) -> 1 | G24: =IF(OR(G23=1,B23=2,C23=2),1,0) -> 1 | H24: =IF(OR(H23=1,B23=3,C23=3),1,0) -> 1 | I24: =IF(OR(I23=1,B23=4,C23=4),1,0) -> 1 | J24: =IF(OR(J23=1,B23=5,C23=5),1,0) -> 1 | K24: =IF(OR(K23=1,B23=6,C23=6),1,0) -> 1 | L24: =IF(OR(L23=1,B23=7,C23=7),1,0) -> 0 | M24: =IF(OR(M23=1,B23=8,C23=8),1,0) -> 0 | N24: =IF(OR(N23=1,B23=9,C23=9),1,0) -> 0 | O24: =IF(OR(O23=1,B23=10,C23=10),1,0) -> 0 | P24: =IF(OR(P23=1,B23=11,C23=11),1,0) -> 0 | Q24: =IF(OR(Q23=1,B23=12,C23=12),1,0) -> 0 | R24: =IF(OR(R23=1,B23=13,C23=13),1,0) -> 0 | S24: =IF(OR(S23=1,B23=14,C23=14),1,0) -> 0 | T24: =IF(OR(T23=1,B23=15,C23=15),1,0) -> 0 | U24: =IF(OR(U23=1,B23=16,C23=16),1,0) -> 0 | V24: =IF(AND(F24=0,1>B24,(COUNTIFS(Suizo!$C$5:$C$12,D24,Suizo!$H$5:$H$12,INDEX($G$3:$G$18,1))+COUNTIFS(Suizo!$C$5:$C$12,INDEX($G$3:$G$18,1),Suizo!$H$5:$H$12,D24))=0),1,99) -> 99 | W24: =IF(AND(G24=0,2>B24,(COUNTIFS(Suizo!$C$5:$C$12,D24,Suizo!$H$5:$H$12,INDEX($G$3:$G$18,2))+COUNTIFS(Suizo!$C$5:$C$12,INDEX($G$3:$G$18,2),Suizo!$H$5:$H$12,D24))=0),2,99) -> 99 | X24: =IF(AND(H24=0,3>B24,(COUNTIFS(Suizo!$C$5:$C$12,D24,Suizo!$H$5:$H$12,INDEX($G$3:$G$18,3))+COUNTIFS(Suizo!$C$5:$C$12,INDEX($G$3:$G$18,3),Suizo!$H$5:$H$12,D24))=0),3,99) -> 99 | Y24: =IF(AND(I24=0,4>B24,(COUNTIFS(Suizo!$C$5:$C$12,D24,Suizo!$H$5:$H$12,INDEX($G$3:$G$18,4))+COUNTIFS(Suizo!$C$5:$C$12,INDEX($G$3:$G$18,4),Suizo!$H$5:$H$12,D24))=0),4,99) -> 99 | Z24: =IF(AND(J24=0,5>B24,(COUNTIFS(Suizo!$C$5:$C$12,D24,Suizo!$H$5:$H$12,INDEX($G$3:$G$18,5))+COUNTIFS(Suizo!$C$5:$C$12,INDEX($G$3:$G$18,5),Suizo!$H$5:$H$12,D24))=0),5,99) -> 99 | AA24: =IF(AND(K24=0,6>B24,(COUNTIFS(Suizo!$C$5:$C$12,D24,Suizo!$H$5:$H$12,INDEX($G$3:$G$18,6))+COUNTIFS(Suizo!$C$5:$C$12,INDEX($G$3:$G$18,6),Suizo!$H$5:$H$12,D24))=0),6,99) -> 99 | AB24: =IF(AND(L24=0,7>B24,(COUNTIFS(Suizo!$C$5:$C$12,D24,Suizo!$H$5:$H$12,INDEX($G$3:$G$18,7))+COUNTIFS(Suizo!$C$5:$C$12,INDEX($G$3:$G$18,7),Suizo!$H$5:$H$12,D24))=0),7,99) -> 99 | AC24: =IF(AND(M24=0,8>B24,(COUNTIFS(Suizo!$C$5:$C$12,D24,Suizo!$H$5:$H$12,INDEX($G$3:$G$18,8))+COUNTIFS(Suizo!$C$5:$C$12,INDEX($G$3:$G$18,8),Suizo!$H$5:$H$12,D24))=0),8,99) -> 8 | AD24: =IF(AND(N24=0,9>B24,(COUNTIFS(Suizo!$C$5:$C$12,D24,Suizo!$H$5:$H$12,INDEX($G$3:$G$18,9))+COUNTIFS(Suizo!$C$5:$C$12,INDEX($G$3:$G$18,9),Suizo!$H$5:$H$12,D24))=0),9,99) -> 9 | AE24: =IF(AND(O24=0,10>B24,(COUNTIFS(Suizo!$C$5:$C$12,D24,Suizo!$H$5:$H$12,INDEX($G$3:$G$18,10))+COUNTIFS(Suizo!$C$5:$C$12,INDEX($G$3:$G$18,10),Suizo!$H$5:$H$12,D24))=0),10,99) -> 10 | AF24: =IF(AND(P24=0,11>B24,(COUNTIFS(Suizo!$C$5:$C$12,D24,Suizo!$H$5:$H$12,INDEX($G$3:$G$18,11))+COUNTIFS(Suizo!$C$5:$C$12,INDEX($G$3:$G$18,11),Suizo!$H$5:$H$12,D24))=0),11,99) -> 11 | AG24: =IF(AND(Q24=0,12>B24,(COUNTIFS(Suizo!$C$5:$C$12,D24,Suizo!$H$5:$H$12,INDEX($G$3:$G$18,12))+COUNTIFS(Suizo!$C$5:$C$12,INDEX($G$3:$G$18,12),Suizo!$H$5:$H$12,D24))=0),12,99) -> 12 | AH24: =IF(AND(R24=0,13>B24,(COUNTIFS(Suizo!$C$5:$C$12,D24,Suizo!$H$5:$H$12,INDEX($G$3:$G$18,13))+COUNTIFS(Suizo!$C$5:$C$12,INDEX($G$3:$G$18,13),Suizo!$H$5:$H$12,D24))=0),13,99) -> 13 | AI24: =IF(AND(S24=0,14>B24,(COUNTIFS(Suizo!$C$5:$C$12,D24,Suizo!$H$5:$H$12,INDEX($G$3:$G$18,14))+COUNTIFS(Suizo!$C$5:$C$12,INDEX($G$3:$G$18,14),Suizo!$H$5:$H$12,D24))=0),14,99) -> 14 | AJ24: =IF(AND(T24=0,15>B24,(COUNTIFS(Suizo!$C$5:$C$12,D24,Suizo!$H$5:$H$12,INDEX($G$3:$G$18,15))+COUNTIFS(Suizo!$C$5:$C$12,INDEX($G$3:$G$18,15),Suizo!$H$5:$H$12,D24))=0),15,99) -> 15 | AK24: =IF(AND(U24=0,16>B24,(COUNTIFS(Suizo!$C$5:$C$12,D24,Suizo!$H$5:$H$12,INDEX($G$3:$G$18,16))+COUNTIFS(Suizo!$C$5:$C$12,INDEX($G$3:$G$18,16),Suizo!$H$5:$H$12,D24))=0),16,99) -> 16 | AL24: =IF(AND(F24=0,1>B24),1,99) -> 99 | AM24: =IF(AND(G24=0,2>B24),2,99) -> 99 | AN24: =IF(AND(H24=0,3>B24),3,99) -> 99 | AO24: =IF(AND(I24=0,4>B24),4,99) -> 99 | AP24: =IF(AND(J24=0,5>B24),5,99) -> 99 | AQ24: =IF(AND(K24=0,6>B24),6,99) -> 99 | AR24: =IF(AND(L24=0,7>B24),7,99) -> 99 | AS24: =IF(AND(M24=0,8>B24),8,99) -> 8 | AT24: =IF(AND(N24=0,9>B24),9,99) -> 9 | AU24: =IF(AND(O24=0,10>B24),10,99) -> 10 | AV24: =IF(AND(P24=0,11>B24),11,99) -> 11 | AW24: =IF(AND(Q24=0,12>B24),12,99) -> 12 | AX24: =IF(AND(R24=0,13>B24),13,99) -> 13 | AY24: =IF(AND(S24=0,14>B24),14,99) -> 14 | AZ24: =IF(AND(T24=0,15>B24),15,99) -> 15 | BA24: =IF(AND(U24=0,16>B24),16,99) -> 16 | BB24: =IF(MIN(V24:AK24)=99,"REVANCHA","")
A25: 5 | B25: =MATCH(0,F25:U25,0) -> 9 | C25: =IF(MIN(V25:AK25)<99,MIN(V25:AK25),MIN(AL25:BA25)) -> 11 | D25: =INDEX($G$3:$G$18,B25) -> 9 | E25: =INDEX($G$3:$G$18,C25) -> 11 | F25: =IF(OR(F24=1,B24=1,C24=1),1,0) -> 1 | G25: =IF(OR(G24=1,B24=2,C24=2),1,0) -> 1 | H25: =IF(OR(H24=1,B24=3,C24=3),1,0) -> 1 | I25: =IF(OR(I24=1,B24=4,C24=4),1,0) -> 1 | J25: =IF(OR(J24=1,B24=5,C24=5),1,0) -> 1 | K25: =IF(OR(K24=1,B24=6,C24=6),1,0) -> 1 | L25: =IF(OR(L24=1,B24=7,C24=7),1,0) -> 1 | M25: =IF(OR(M24=1,B24=8,C24=8),1,0) -> 1 | N25: =IF(OR(N24=1,B24=9,C24=9),1,0) -> 0 | O25: =IF(OR(O24=1,B24=10,C24=10),1,0) -> 0 | P25: =IF(OR(P24=1,B24=11,C24=11),1,0) -> 0 | Q25: =IF(OR(Q24=1,B24=12,C24=12),1,0) -> 0 | R25: =IF(OR(R24=1,B24=13,C24=13),1,0) -> 0 | S25: =IF(OR(S24=1,B24=14,C24=14),1,0) -> 0 | T25: =IF(OR(T24=1,B24=15,C24=15),1,0) -> 0 | U25: =IF(OR(U24=1,B24=16,C24=16),1,0) -> 0 | V25: =IF(AND(F25=0,1>B25,(COUNTIFS(Suizo!$C$5:$C$12,D25,Suizo!$H$5:$H$12,INDEX($G$3:$G$18,1))+COUNTIFS(Suizo!$C$5:$C$12,INDEX($G$3:$G$18,1),Suizo!$H$5:$H$12,D25))=0),1,99) -> 99 | W25: =IF(AND(G25=0,2>B25,(COUNTIFS(Suizo!$C$5:$C$12,D25,Suizo!$H$5:$H$12,INDEX($G$3:$G$18,2))+COUNTIFS(Suizo!$C$5:$C$12,INDEX($G$3:$G$18,2),Suizo!$H$5:$H$12,D25))=0),2,99) -> 99 | X25: =IF(AND(H25=0,3>B25,(COUNTIFS(Suizo!$C$5:$C$12,D25,Suizo!$H$5:$H$12,INDEX($G$3:$G$18,3))+COUNTIFS(Suizo!$C$5:$C$12,INDEX($G$3:$G$18,3),Suizo!$H$5:$H$12,D25))=0),3,99) -> 99 | Y25: =IF(AND(I25=0,4>B25,(COUNTIFS(Suizo!$C$5:$C$12,D25,Suizo!$H$5:$H$12,INDEX($G$3:$G$18,4))+COUNTIFS(Suizo!$C$5:$C$12,INDEX($G$3:$G$18,4),Suizo!$H$5:$H$12,D25))=0),4,99) -> 99 | Z25: =IF(AND(J25=0,5>B25,(COUNTIFS(Suizo!$C$5:$C$12,D25,Suizo!$H$5:$H$12,INDEX($G$3:$G$18,5))+COUNTIFS(Suizo!$C$5:$C$12,INDEX($G$3:$G$18,5),Suizo!$H$5:$H$12,D25))=0),5,99) -> 99 | AA25: =IF(AND(K25=0,6>B25,(COUNTIFS(Suizo!$C$5:$C$12,D25,Suizo!$H$5:$H$12,INDEX($G$3:$G$18,6))+COUNTIFS(Suizo!$C$5:$C$12,INDEX($G$3:$G$18,6),Suizo!$H$5:$H$12,D25))=0),6,99) -> 99 | AB25: =IF(AND(L25=0,7>B25,(COUNTIFS(Suizo!$C$5:$C$12,D25,Suizo!$H$5:$H$12,INDEX($G$3:$G$18,7))+COUNTIFS(Suizo!$C$5:$C$12,INDEX($G$3:$G$18,7),Suizo!$H$5:$H$12,D25))=0),7,99) -> 99 | AC25: =IF(AND(M25=0,8>B25,(COUNTIFS(Suizo!$C$5:$C$12,D25,Suizo!$H$5:$H$12,INDEX($G$3:$G$18,8))+COUNTIFS(Suizo!$C$5:$C$12,INDEX($G$3:$G$18,8),Suizo!$H$5:$H$12,D25))=0),8,99) -> 99 | AD25: =IF(AND(N25=0,9>B25,(COUNTIFS(Suizo!$C$5:$C$12,D25,Suizo!$H$5:$H$12,INDEX($G$3:$G$18,9))+COUNTIFS(Suizo!$C$5:$C$12,INDEX($G$3:$G$18,9),Suizo!$H$5:$H$12,D25))=0),9,99) -> 99 | AE25: =IF(AND(O25=0,10>B25,(COUNTIFS(Suizo!$C$5:$C$12,D25,Suizo!$H$5:$H$12,INDEX($G$3:$G$18,10))+COUNTIFS(Suizo!$C$5:$C$12,INDEX($G$3:$G$18,10),Suizo!$H$5:$H$12,D25))=0),10,99) -> 99 | AF25: =IF(AND(P25=0,11>B25,(COUNTIFS(Suizo!$C$5:$C$12,D25,Suizo!$H$5:$H$12,INDEX($G$3:$G$18,11))+COUNTIFS(Suizo!$C$5:$C$12,INDEX($G$3:$G$18,11),Suizo!$H$5:$H$12,D25))=0),11,99) -> 11 | AG25: =IF(AND(Q25=0,12>B25,(COUNTIFS(Suizo!$C$5:$C$12,D25,Suizo!$H$5:$H$12,INDEX($G$3:$G$18,12))+COUNTIFS(Suizo!$C$5:$C$12,INDEX($G$3:$G$18,12),Suizo!$H$5:$H$12,D25))=0),12,99) -> 12 | AH25: =IF(AND(R25=0,13>B25,(COUNTIFS(Suizo!$C$5:$C$12,D25,Suizo!$H$5:$H$12,INDEX($G$3:$G$18,13))+COUNTIFS(Suizo!$C$5:$C$12,INDEX($G$3:$G$18,13),Suizo!$H$5:$H$12,D25))=0),13,99) -> 13 | AI25: =IF(AND(S25=0,14>B25,(COUNTIFS(Suizo!$C$5:$C$12,D25,Suizo!$H$5:$H$12,INDEX($G$3:$G$18,14))+COUNTIFS(Suizo!$C$5:$C$12,INDEX($G$3:$G$18,14),Suizo!$H$5:$H$12,D25))=0),14,99) -> 14 | AJ25: =IF(AND(T25=0,15>B25,(COUNTIFS(Suizo!$C$5:$C$12,D25,Suizo!$H$5:$H$12,INDEX($G$3:$G$18,15))+COUNTIFS(Suizo!$C$5:$C$12,INDEX($G$3:$G$18,15),Suizo!$H$5:$H$12,D25))=0),15,99) -> 15 | AK25: =IF(AND(U25=0,16>B25,(COUNTIFS(Suizo!$C$5:$C$12,D25,Suizo!$H$5:$H$12,INDEX($G$3:$G$18,16))+COUNTIFS(Suizo!$C$5:$C$12,INDEX($G$3:$G$18,16),Suizo!$H$5:$H$12,D25))=0),16,99) -> 16 | AL25: =IF(AND(F25=0,1>B25),1,99) -> 99 | AM25: =IF(AND(G25=0,2>B25),2,99) -> 99 | AN25: =IF(AND(H25=0,3>B25),3,99) -> 99 | AO25: =IF(AND(I25=0,4>B25),4,99) -> 99 | AP25: =IF(AND(J25=0,5>B25),5,99) -> 99 | AQ25: =IF(AND(K25=0,6>B25),6,99) -> 99 | AR25: =IF(AND(L25=0,7>B25),7,99) -> 99 | AS25: =IF(AND(M25=0,8>B25),8,99) -> 99 | AT25: =IF(AND(N25=0,9>B25),9,99) -> 99 | AU25: =IF(AND(O25=0,10>B25),10,99) -> 10 | AV25: =IF(AND(P25=0,11>B25),11,99) -> 11 | AW25: =IF(AND(Q25=0,12>B25),12,99) -> 12 | AX25: =IF(AND(R25=0,13>B25),13,99) -> 13 | AY25: =IF(AND(S25=0,14>B25),14,99) -> 14 | AZ25: =IF(AND(T25=0,15>B25),15,99) -> 15 | BA25: =IF(AND(U25=0,16>B25),16,99) -> 16 | BB25: =IF(MIN(V25:AK25)=99,"REVANCHA","")
A26: 6 | B26: =MATCH(0,F26:U26,0) -> 10 | C26: =IF(MIN(V26:AK26)<99,MIN(V26:AK26),MIN(AL26:BA26)) -> 12 | D26: =INDEX($G$3:$G$18,B26) -> 10 | E26: =INDEX($G$3:$G$18,C26) -> 12 | F26: =IF(OR(F25=1,B25=1,C25=1),1,0) -> 1 | G26: =IF(OR(G25=1,B25=2,C25=2),1,0) -> 1 | H26: =IF(OR(H25=1,B25=3,C25=3),1,0) -> 1 | I26: =IF(OR(I25=1,B25=4,C25=4),1,0) -> 1 | J26: =IF(OR(J25=1,B25=5,C25=5),1,0) -> 1 | K26: =IF(OR(K25=1,B25=6,C25=6),1,0) -> 1 | L26: =IF(OR(L25=1,B25=7,C25=7),1,0) -> 1 | M26: =IF(OR(M25=1,B25=8,C25=8),1,0) -> 1 | N26: =IF(OR(N25=1,B25=9,C25=9),1,0) -> 1 | O26: =IF(OR(O25=1,B25=10,C25=10),1,0) -> 0 | P26: =IF(OR(P25=1,B25=11,C25=11),1,0) -> 1 | Q26: =IF(OR(Q25=1,B25=12,C25=12),1,0) -> 0 | R26: =IF(OR(R25=1,B25=13,C25=13),1,0) -> 0 | S26: =IF(OR(S25=1,B25=14,C25=14),1,0) -> 0 | T26: =IF(OR(T25=1,B25=15,C25=15),1,0) -> 0 | U26: =IF(OR(U25=1,B25=16,C25=16),1,0) -> 0 | V26: =IF(AND(F26=0,1>B26,(COUNTIFS(Suizo!$C$5:$C$12,D26,Suizo!$H$5:$H$12,INDEX($G$3:$G$18,1))+COUNTIFS(Suizo!$C$5:$C$12,INDEX($G$3:$G$18,1),Suizo!$H$5:$H$12,D26))=0),1,99) -> 99 | W26: =IF(AND(G26=0,2>B26,(COUNTIFS(Suizo!$C$5:$C$12,D26,Suizo!$H$5:$H$12,INDEX($G$3:$G$18,2))+COUNTIFS(Suizo!$C$5:$C$12,INDEX($G$3:$G$18,2),Suizo!$H$5:$H$12,D26))=0),2,99) -> 99 | X26: =IF(AND(H26=0,3>B26,(COUNTIFS(Suizo!$C$5:$C$12,D26,Suizo!$H$5:$H$12,INDEX($G$3:$G$18,3))+COUNTIFS(Suizo!$C$5:$C$12,INDEX($G$3:$G$18,3),Suizo!$H$5:$H$12,D26))=0),3,99) -> 99 | Y26: =IF(AND(I26=0,4>B26,(COUNTIFS(Suizo!$C$5:$C$12,D26,Suizo!$H$5:$H$12,INDEX($G$3:$G$18,4))+COUNTIFS(Suizo!$C$5:$C$12,INDEX($G$3:$G$18,4),Suizo!$H$5:$H$12,D26))=0),4,99) -> 99 | Z26: =IF(AND(J26=0,5>B26,(COUNTIFS(Suizo!$C$5:$C$12,D26,Suizo!$H$5:$H$12,INDEX($G$3:$G$18,5))+COUNTIFS(Suizo!$C$5:$C$12,INDEX($G$3:$G$18,5),Suizo!$H$5:$H$12,D26))=0),5,99) -> 99 | AA26: =IF(AND(K26=0,6>B26,(COUNTIFS(Suizo!$C$5:$C$12,D26,Suizo!$H$5:$H$12,INDEX($G$3:$G$18,6))+COUNTIFS(Suizo!$C$5:$C$12,INDEX($G$3:$G$18,6),Suizo!$H$5:$H$12,D26))=0),6,99) -> 99 | AB26: =IF(AND(L26=0,7>B26,(COUNTIFS(Suizo!$C$5:$C$12,D26,Suizo!$H$5:$H$12,INDEX($G$3:$G$18,7))+COUNTIFS(Suizo!$C$5:$C$12,INDEX($G$3:$G$18,7),Suizo!$H$5:$H$12,D26))=0),7,99) -> 99 | AC26: =IF(AND(M26=0,8>B26,(COUNTIFS(Suizo!$C$5:$C$12,D26,Suizo!$H$5:$H$12,INDEX($G$3:$G$18,8))+COUNTIFS(Suizo!$C$5:$C$12,INDEX($G$3:$G$18,8),Suizo!$H$5:$H$12,D26))=0),8,99) -> 99 | AD26: =IF(AND(N26=0,9>B26,(COUNTIFS(Suizo!$C$5:$C$12,D26,Suizo!$H$5:$H$12,INDEX($G$3:$G$18,9))+COUNTIFS(Suizo!$C$5:$C$12,INDEX($G$3:$G$18,9),Suizo!$H$5:$H$12,D26))=0),9,99) -> 99 | AE26: =IF(AND(O26=0,10>B26,(COUNTIFS(Suizo!$C$5:$C$12,D26,Suizo!$H$5:$H$12,INDEX($G$3:$G$18,10))+COUNTIFS(Suizo!$C$5:$C$12,INDEX($G$3:$G$18,10),Suizo!$H$5:$H$12,D26))=0),10,99) -> 99 | AF26: =IF(AND(P26=0,11>B26,(COUNTIFS(Suizo!$C$5:$C$12,D26,Suizo!$H$5:$H$12,INDEX($G$3:$G$18,11))+COUNTIFS(Suizo!$C$5:$C$12,INDEX($G$3:$G$18,11),Suizo!$H$5:$H$12,D26))=0),11,99) -> 99 | AG26: =IF(AND(Q26=0,12>B26,(COUNTIFS(Suizo!$C$5:$C$12,D26,Suizo!$H$5:$H$12,INDEX($G$3:$G$18,12))+COUNTIFS(Suizo!$C$5:$C$12,INDEX($G$3:$G$18,12),Suizo!$H$5:$H$12,D26))=0),12,99) -> 12 | AH26: =IF(AND(R26=0,13>B26,(COUNTIFS(Suizo!$C$5:$C$12,D26,Suizo!$H$5:$H$12,INDEX($G$3:$G$18,13))+COUNTIFS(Suizo!$C$5:$C$12,INDEX($G$3:$G$18,13),Suizo!$H$5:$H$12,D26))=0),13,99) -> 13 | AI26: =IF(AND(S26=0,14>B26,(COUNTIFS(Suizo!$C$5:$C$12,D26,Suizo!$H$5:$H$12,INDEX($G$3:$G$18,14))+COUNTIFS(Suizo!$C$5:$C$12,INDEX($G$3:$G$18,14),Suizo!$H$5:$H$12,D26))=0),14,99) -> 14 | AJ26: =IF(AND(T26=0,15>B26,(COUNTIFS(Suizo!$C$5:$C$12,D26,Suizo!$H$5:$H$12,INDEX($G$3:$G$18,15))+COUNTIFS(Suizo!$C$5:$C$12,INDEX($G$3:$G$18,15),Suizo!$H$5:$H$12,D26))=0),15,99) -> 15 | AK26: =IF(AND(U26=0,16>B26,(COUNTIFS(Suizo!$C$5:$C$12,D26,Suizo!$H$5:$H$12,INDEX($G$3:$G$18,16))+COUNTIFS(Suizo!$C$5:$C$12,INDEX($G$3:$G$18,16),Suizo!$H$5:$H$12,D26))=0),16,99) -> 16 | AL26: =IF(AND(F26=0,1>B26),1,99) -> 99 | AM26: =IF(AND(G26=0,2>B26),2,99) -> 99 | AN26: =IF(AND(H26=0,3>B26),3,99) -> 99 | AO26: =IF(AND(I26=0,4>B26),4,99) -> 99 | AP26: =IF(AND(J26=0,5>B26),5,99) -> 99 | AQ26: =IF(AND(K26=0,6>B26),6,99) -> 99 | AR26: =IF(AND(L26=0,7>B26),7,99) -> 99 | AS26: =IF(AND(M26=0,8>B26),8,99) -> 99 | AT26: =IF(AND(N26=0,9>B26),9,99) -> 99 | AU26: =IF(AND(O26=0,10>B26),10,99) -> 99 | AV26: =IF(AND(P26=0,11>B26),11,99) -> 99 | AW26: =IF(AND(Q26=0,12>B26),12,99) -> 12 | AX26: =IF(AND(R26=0,13>B26),13,99) -> 13 | AY26: =IF(AND(S26=0,14>B26),14,99) -> 14 | AZ26: =IF(AND(T26=0,15>B26),15,99) -> 15 | BA26: =IF(AND(U26=0,16>B26),16,99) -> 16 | BB26: =IF(MIN(V26:AK26)=99,"REVANCHA","")
